Workbook

Sheet CALCULO_VR
A1: ENBPar | N1: *fonte: IBGE - Índice de Nomes Geográficos Macapá
A2: CONTRATO ECM-016/2025 - ENERGISA TO 2ª TRANCHE | N2: Rede\Sistema Amostral\DocumentacaoPDF
A3: CONTA CONTRATO | B3: PROJETO | C3: ODI | D3: MUNICÍPIO | E3: QTD | F3: Data_Inicio | G3: Data_Fim | H3: Data_Recebimento | I3: Custo | J3: Grupo | K3: SIGFI | L3: Tipo_zona | M3: Status_ocup | N3: Latitude_Mun | O3: Longitude_Mun | P3: Latitude_UC | Q3: Longitude_UC | R3: KM
A4: 3464081 | B4: MLPA | C4: 402301057 | D4: =_xlfn.XLOOKUP(C4,Planilha3!A:A,Planilha3!C:C) -> PARANÃ | E4: 1 | F4: =_xlfn.XLOOKUP(C4,Planilha3!A:A,Planilha3!E:E) -> 45436.387 | G4: =_xlfn.XLOOKUP(C4,Planilha3!A:A,Planilha3!F:F) -> 45447.387 | H4: =_xlfn.XLOOKUP(C4,Planilha3!A:A,Planilha3!G:G) -> 45916 | I4: =_xlfn.XLOOKUP(K4,Grupo!F:F,Grupo!G:G) -> 46440.22 | J4: =_xlfn.XLOOKUP(D4,Grupo!B:B,Grupo!C:C) -> 10 | K4: =_xlfn.XLOOKUP(A4,[1]COORDENADAS_GEOGRÁFICAS!$D:$D,[1]COORDENADAS_GEOGRÁFICAS!$F:$F) -> 80 | N4: =_xlfn.XLOOKUP(D4,Grupo!B:B,Grupo!D:D) -> -12.620481 | O4: =_xlfn.XLOOKUP(D4,Grupo!B:B,Grupo!E:E) -> -47.884084 | P4: =_xlfn.XLOOKUP(A4,[1]COORDENADAS_GEOGRÁFICAS!$D:$D,[1]COORDENADAS_GEOGRÁFICAS!$G:$G) -> -12.35899 | Q4: =_xlfn.XLOOKUP(A4,[1]COORDENADAS_GEOGRÁFICAS!$D:$D,[1]COORDENADAS_GEOGRÁFICAS!$H:$H) -> -47.95081 | R4: =6371*ACOS(COS(PI()*(90-P4)/180)*COS((90-N4)*PI()/180)+SIN((90-P4)*PI()/180)*SIN((90-N4)*PI()/180)*COS((Q4-O4)*PI()/180)) -> 29.965319
A5: 3459335 | B5: MLPA | C5: 402301073 | D5: =_xlfn.XLOOKUP(C5,Planilha3!A:A,Planilha3!C:C) -> PARANÃ | E5: 1 | F5: =_xlfn.XLOOKUP(C5,Planilha3!A:A,Planilha3!E:E) -> 45445.697 | G5: =_xlfn.XLOOKUP(C5,Planilha3!A:A,Planilha3!F:F) -> 45457.697 | H5: =_xlfn.XLOOKUP(C5,Planilha3!A:A,Planilha3!G:G) -> 45916 | I5: =_xlfn.XLOOKUP(K5,Grupo!F:F,Grupo!G:G) -> 46440.22 | J5: =_xlfn.XLOOKUP(D5,Grupo!B:B,Grupo!C:C) -> 10 | K5: =_xlfn.XLOOKUP(A5,[1]COORDENADAS_GEOGRÁFICAS!$D:$D,[1]COORDENADAS_GEOGRÁFICAS!$F:$F) -> 80 | N5: =_xlfn.XLOOKUP(D5,Grupo!B:B,Grupo!D:D) -> -12.620481 | O5: =_xlfn.XLOOKUP(D5,Grupo!B:B,Grupo!E:E) -> -47.884084 | P5: =_xlfn.XLOOKUP(A5,[1]COORDENADAS_GEOGRÁFICAS!$D:$D,[1]COORDENADAS_GEOGRÁFICAS!$G:$G) -> -12.772738 | Q5: =_xlfn.XLOOKUP(A5,[1]COORDENADAS_GEOGRÁFICAS!$D:$D,[1]COORDENADAS_GEOGRÁFICAS!$H:$H) -> -47.416423 | R5: =6371*ACOS(COS(PI()*(90-P5)/180)*COS((90-N5)*PI()/180)+SIN((90-P5)*PI()/180)*SIN((90-N5)*PI()/180)*COS((Q5-O5)*PI()/180)) -> 53.480408
A6: 3467062 | B6: MLPA | C6: 402301111 | D6: =_xlfn.XLOOKUP(C6,Planilha3!A:A,Planilha3!C:C) -> PARANÃ | E6: 1 | F6: =_xlfn.XLOOKUP(C6,Planilha3!A:A,Planilha3!E:E) -> 45447.663 | G6: =_xlfn.XLOOKUP(C6,Planilha3!A:A,Planilha3!F:F) -> 45460.663 | H6: =_xlfn.XLOOKUP(C6,Planilha3!A:A,Planilha3!G:G) -> 45916 | I6: =_xlfn.XLOOKUP(K6,Grupo!F:F,Grupo!G:G) -> 46440.22 | J6: =_xlfn.XLOOKUP(D6,Grupo!B:B,Grupo!C:C) -> 10 | K6: =_xlfn.XLOOKUP(A6,[1]COORDENADAS_GEOGRÁFICAS!$D:$D,[1]COORDENADAS_GEOGRÁFICAS!$F:$F) -> 80 | N6: =_xlfn.XLOOKUP(D6,Grupo!B:B,Grupo!D:D) -> -12.620481 | O6: =_xlfn.XLOOKUP(D6,Grupo!B:B,Grupo!E:E) -> -47.884084 | P6: =_xlfn.XLOOKUP(A6,[1]COORDENADAS_GEOGRÁFICAS!$D:$D,[1]COORDENADAS_GEOGRÁFICAS!$G:$G) -> -12.781725 | Q6: =_xlfn.XLOOKUP(A6,[1]COORDENADAS_GEOGRÁFICAS!$D:$D,[1]COORDENADAS_GEOGRÁFICAS!$H:$H) -> -47.409683 | R6: =6371*ACOS(COS(PI()*(90-P6)/180)*COS((90-N6)*PI()/180)+SIN((90-P6)*PI()/180)*SIN((90-N6)*PI()/180)*COS((Q6-O6)*PI()/180)) -> 54.494131
A7: 3430975 | B7: MLPA | C7: 402301015 | D7: =_xlfn.XLOOKUP(C7,Planilha3!A:A,Planilha3!C:C) -> PARANÃ | E7: 1 | F7: =_xlfn.XLOOKUP(C7,Planilha3!A:A,Planilha3!E:E) -> 45299.634 | G7: =_xlfn.XLOOKUP(C7,Planilha3!A:A,Planilha3!F:F) -> 45314.634 | H7: =_xlfn.XLOOKUP(C7,Planilha3!A:A,Planilha3!G:G) -> 45916 | I7: =_xlfn.XLOOKUP(K7,Grupo!F:F,Grupo!G:G) -> 46440.22 | J7: =_xlfn.XLOOKUP(D7,Grupo!B:B,Grupo!C:C) -> 10 | K7: =_xlfn.XLOOKUP(A7,[1]COORDENADAS_GEOGRÁFICAS!$D:$D,[1]COORDENADAS_GEOGRÁFICAS!$F:$F) -> 80 | N7: =_xlfn.XLOOKUP(D7,Grupo!B:B,Grupo!D:D) -> -12.620481 | O7: =_xlfn.XLOOKUP(D7,Grupo!B:B,Grupo!E:E) -> -47.884084 | P7: =_xlfn.XLOOKUP(A7,[1]COORDENADAS_GEOGRÁFICAS!$D:$D,[1]COORDENADAS_GEOGRÁFICAS!$G:$G) -> -12.7499 | Q7: =_xlfn.XLOOKUP(A7,[1]COORDENADAS_GEOGRÁFICAS!$D:$D,[1]COORDENADAS_GEOGRÁFICAS!$H:$H) -> -47.4463 | R7: =6371*ACOS(COS(PI()*(90-P7)/180)*COS((90-N7)*PI()/180)+SIN((90-P7)*PI()/180)*SIN((90-N7)*PI()/180)*COS((Q7-O7)*PI()/180)) -> 49.62356
A8: 3434827 | B8: MLPA | C8: 402301013 | D8: =_xlfn.XLOOKUP(C8,Planilha3!A:A,Planilha3!C:C) -> PARANÃ | E8: 1 | F8: =_xlfn.XLOOKUP(C8,Planilha3!A:A,Planilha3!E:E) -> 45298.603 | G8: =_xlfn.XLOOKUP(C8,Planilha3!A:A,Planilha3!F:F) -> 45314.603 | H8: =_xlfn.XLOOKUP(C8,Planilha3!A:A,Planilha3!G:G) -> 45916 | I8: =_xlfn.XLOOKUP(K8,Grupo!F:F,Grupo!G:G) -> 46440.22 | J8: =_xlfn.XLOOKUP(D8,Grupo!B:B,Grupo!C:C) -> 10 | K8: =_xlfn.XLOOKUP(A8,[1]COORDENADAS_GEOGRÁFICAS!$D:$D,[1]COORDENADAS_GEOGRÁFICAS!$F:$F) -> 80 | N8: =_xlfn.XLOOKUP(D8,Grupo!B:B,Grupo!D:D) -> -12.620481 | O8: =_xlfn.XLOOKUP(D8,Grupo!B:B,Grupo!E:E) -> -47.884084 | P8: =_xlfn.XLOOKUP(A8,[1]COORDENADAS_GEOGRÁFICAS!$D:$D,[1]COORDENADAS_GEOGRÁFICAS!$G:$G) -> -12.7589 | Q8: =_xlfn.XLOOKUP(A8,[1]COORDENADAS_GEOGRÁFICAS!$D:$D,[1]COORDENADAS_GEOGRÁFICAS!$H:$H) -> -47.4269 | R8: =6371*ACOS(COS(PI()*(90-P8)/180)*COS((90-N8)*PI()/180)+SIN((90-P8)*PI()/180)*SIN((90-N8)*PI()/180)*COS((Q8-O8)*PI()/180)) -> 51.928189
A9: 3434698 | B9: MLPA | C9: 402301012 | D9: =_xlfn.XLOOKUP(C9,Planilha3!A:A,Planilha3!C:C) -> PARANÃ | E9: 1 | F9: =_xlfn.XLOOKUP(C9,Planilha3!A:A,Planilha3!E:E) -> 45303.598 | G9: =_xlfn.XLOOKUP(C9,Planilha3!A:A,Planilha3!F:F) -> 45314.598 | H9: =_xlfn.XLOOKUP(C9,Planilha3!A:A,Planilha3!G:G) -> 45916 | I9: =_xlfn.XLOOKUP(K9,Grupo!F:F,Grupo!G:G) -> 46440.22 | J9: =_xlfn.XLOOKUP(D9,Grupo!B:B,Grupo!C:C) -> 10 | K9: =_xlfn.XLOOKUP(A9,[1]COORDENADAS_GEOGRÁFICAS!$D:$D,[1]COORDENADAS_GEOGRÁFICAS!$F:$F) -> 80 | N9: =_xlfn.XLOOKUP(D9,Grupo!B:B,Grupo!D:D) -> -12.620481 | O9: =_xlfn.XLOOKUP(D9,Grupo!B:B,Grupo!E:E) -> -47.884084 | P9: =_xlfn.XLOOKUP(A9,[1]COORDENADAS_GEOGRÁFICAS!$D:$D,[1]COORDENADAS_GEOGRÁFICAS!$G:$G) -> -12.7686 | Q9: =_xlfn.XLOOKUP(A9,[1]COORDENADAS_GEOGRÁFICAS!$D:$D,[1]COORDENADAS_GEOGRÁFICAS!$H:$H) -> -47.3985 | R9: =6371*ACOS(COS(PI()*(90-P9)/180)*COS((90-N9)*PI()/180)+SIN((90-P9)*PI()/180)*SIN((90-N9)*PI()/180)*COS((Q9-O9)*PI()/180)) -> 55.189406
A10: 3466701 | B10: MLPA | C10: 402301072 | D10: =_xlfn.XLOOKUP(C10,Planilha3!A:A,Planilha3!C:C) -> PARANÃ | E10: 1 | F10: =_xlfn.XLOOKUP(C10,Planilha3!A:A,Planilha3!E:E) -> 45445.663 | G10: =_xlfn.XLOOKUP(C10,Planilha3!A:A,Planilha3!F:F) -> 45457.663 | H10: =_xlfn.XLOOKUP(C10,Planilha3!A:A,Planilha3!G:G) -> 45916 | I10: =_xlfn.XLOOKUP(K10,Grupo!F:F,Grupo!G:G) -> 46440.22 | J10: =_xlfn.XLOOKUP(D10,Grupo!B:B,Grupo!C:C) -> 10 | K10: =_xlfn.XLOOKUP(A10,[1]COORDENADAS_GEOGRÁFICAS!$D:$D,[1]COORDENADAS_GEOGRÁFICAS!$F:$F) -> 80 | N10: =_xlfn.XLOOKUP(D10,Grupo!B:B,Grupo!D:D) -> -12.620481 | O10: =_xlfn.XLOOKUP(D10,Grupo!B:B,Grupo!E:E) -> -47.884084 | P10: =_xlfn.XLOOKUP(A10,[1]COORDENADAS_GEOGRÁFICAS!$D:$D,[1]COORDENADAS_GEOGRÁFICAS!$G:$G) -> -12.776825 | Q10: =_xlfn.XLOOKUP(A10,[1]COORDENADAS_GEOGRÁFICAS!$D:$D,[1]COORDENADAS_GEOGRÁFICAS!$H:$H) -> -47.413893 | R10: =6371*ACOS(COS(PI()*(90-P10)/180)*COS((90-N10)*PI()/180)+SIN((90-P10)*PI()/180)*SIN((90-N10)*PI()/180)*COS((Q10-O10)*PI()/180)) -> 53.885313
A11: 3464244 | B11: MLPA | C11: 402301056 | D11: =_xlfn.XLOOKUP(C11,Planilha3!A:A,Planilha3!C:C) -> PARANÃ | E11: 1 | F11: =_xlfn.XLOOKUP(C11,Planilha3!A:A,Planilha3!E:E) -> 45443.454 | G11: =_xlfn.XLOOKUP(C11,Planilha3!A:A,Planilha3!F:F) -> 45456.454 | H11: =_xlfn.XLOOKUP(C11,Planilha3!A:A,Planilha3!G:G) -> 45916 | I11: =_xlfn.XLOOKUP(K11,Grupo!F:F,Grupo!G:G) -> 46440.22 | J11: =_xlfn.XLOOKUP(D11,Grupo!B:B,Grupo!C:C) -> 10 | K11: =_xlfn.XLOOKUP(A11,[1]COORDENADAS_GEOGRÁFICAS!$D:$D,[1]COORDENADAS_GEOGRÁFICAS!$F:$F) -> 80 | N11: =_xlfn.XLOOKUP(D11,Grupo!B:B,Grupo!D:D) -> -12.620481 | O11: =_xlfn.XLOOKUP(D11,Grupo!B:B,Grupo!E:E) -> -47.884084 | P11: =_xlfn.XLOOKUP(A11,[1]COORDENADAS_GEOGRÁFICAS!$D:$D,[1]COORDENADAS_GEOGRÁFICAS!$G:$G) -> -12.381087 | Q11: =_xlfn.XLOOKUP(A11,[1]COORDENADAS_GEOGRÁFICAS!$D:$D,[1]COORDENADAS_GEOGRÁFICAS!$H:$H) -> -48.215148 | R11: =6371*ACOS(COS(PI()*(90-P11)/180)*COS((90-N11)*PI()/180)+SIN((90-P11)*PI()/180)*SIN((90-N11)*PI()/180)*COS((Q11-O11)*PI()/180)) -> 44.724412
A12: 3465687 | B12: MLPA | C12: 402301070 | D12: =_xlfn.XLOOKUP(C12,Planilha3!A:A,Planilha3!C:C) -> PARANÃ | E12: 1 | F12: =_xlfn.XLOOKUP(C12,Planilha3!A:A,Planilha3!E:E) -> 45442.638 | G12: =_xlfn.XLOOKUP(C12,Planilha3!A:A,Planilha3!F:F) -> 45457.638 | H12: =_xlfn.XLOOKUP(C12,Planilha3!A:A,Planilha3!G:G) -> 45916 | I12: =_xlfn.XLOOKUP(K12,Grupo!F:F,Grupo!G:G) -> 46440.22 | J12: =_xlfn.XLOOKUP(D12,Grupo!B:B,Grupo!C:C) -> 10 | K12: =_xlfn.XLOOKUP(A12,[1]COORDENADAS_GEOGRÁFICAS!$D:$D,[1]COORDENADAS_GEOGRÁFICAS!$F:$F) -> 80 | N12: =_xlfn.XLOOKUP(D12,Grupo!B:B,Grupo!D:D) -> -12.620481 | O12: =_xlfn.XLOOKUP(D12,Grupo!B:B,Grupo!E:E) -> -47.884084 | P12: =_xlfn.XLOOKUP(A12,[1]COORDENADAS_GEOGRÁFICAS!$D:$D,[1]COORDENADAS_GEOGRÁFICAS!$G:$G) -> -12.330187 | Q12: =_xlfn.XLOOKUP(A12,[1]COORDENADAS_GEOGRÁFICAS!$D:$D,[1]COORDENADAS_GEOGRÁFICAS!$H:$H) -> -48.187702 | R12: =6371*ACOS(COS(PI()*(90-P12)/180)*COS((90-N12)*PI()/180)+SIN((90-P12)*PI()/180)*SIN((90-N12)*PI()/180)*COS((Q12-O12)*PI()/180)) -> 46.136249
A13: 3435800 | B13: MLPA | C13: 402301017 | D13: =_xlfn.XLOOKUP(C13,Planilha3!A:A,Planilha3!C:C) -> PARANÃ | E13: 1 | F13: =_xlfn.XLOOKUP(C13,Planilha3!A:A,Planilha3!E:E) -> 45305.616 | G13: =_xlfn.XLOOKUP(C13,Planilha3!A:A,Planilha3!F:F) -> 45316.616 | H13: =_xlfn.XLOOKUP(C13,Planilha3!A:A,Planilha3!G:G) -> 45916 | I13: =_xlfn.XLOOKUP(K13,Grupo!F:F,Grupo!G:G) -> 46440.22 | J13: =_xlfn.XLOOKUP(D13,Grupo!B:B,Grupo!C:C) -> 10 | K13: =_xlfn.XLOOKUP(A13,[1]COORDENADAS_GEOGRÁFICAS!$D:$D,[1]COORDENADAS_GEOGRÁFICAS!$F:$F) -> 80 | N13: =_xlfn.XLOOKUP(D13,Grupo!B:B,Grupo!D:D) -> -12.620481 | O13: =_xlfn.XLOOKUP(D13,Grupo!B:B,Grupo!E:E) -> -47.884084 | P13: =_xlfn.XLOOKUP(A13,[1]COORDENADAS_GEOGRÁFICAS!$D:$D,[1]COORDENADAS_GEOGRÁFICAS!$G:$G) -> -12.399542 | Q13: =_xlfn.XLOOKUP(A13,[1]COORDENADAS_GEOGRÁFICAS!$D:$D,[1]COORDENADAS_GEOGRÁFICAS!$H:$H) -> -47.897138 | R13: =6371*ACOS(COS(PI()*(90-P13)/180)*COS((90-N13)*PI()/180)+SIN((90-P13)*PI()/180)*SIN((90-N13)*PI()/180)*COS((Q13-O13)*PI()/180)) -> 24.608187
A14: 3463633 | B14: MLPA | C14: 402301069 | D14: =_xlfn.XLOOKUP(C14,Planilha3!A:A,Planilha3!C:C) -> PARANÃ | E14: 1 | F14: =_xlfn.XLOOKUP(C14,Planilha3!A:A,Planilha3!E:E) -> 45436.681 | G14: =_xlfn.XLOOKUP(C14,Planilha3!A:A,Planilha3!F:F) -> 45448.681 | H14: =_xlfn.XLOOKUP(C14,Planilha3!A:A,Planilha3!G:G) -> 45916 | I14: =_xlfn.XLOOKUP(K14,Grupo!F:F,Grupo!G:G) -> 46440.22 | J14: =_xlfn.XLOOKUP(D14,Grupo!B:B,Grupo!C:C) -> 10 | K14: =_xlfn.XLOOKUP(A14,[1]COORDENADAS_GEOGRÁFICAS!$D:$D,[1]COORDENADAS_GEOGRÁFICAS!$F:$F) -> 80 | N14: =_xlfn.XLOOKUP(D14,Grupo!B:B,Grupo!D:D) -> -12.620481 | O14: =_xlfn.XLOOKUP(D14,Grupo!B:B,Grupo!E:E) -> -47.884084 | P14: =_xlfn.XLOOKUP(A14,[1]COORDENADAS_GEOGRÁFICAS!$D:$D,[1]COORDENADAS_GEOGRÁFICAS!$G:$G) -> -12.3945 | Q14: =_xlfn.XLOOKUP(A14,[1]COORDENADAS_GEOGRÁFICAS!$D:$D,[1]COORDENADAS_GEOGRÁFICAS!$H:$H) -> -47.9309 | R14: =6371*ACOS(COS(PI()*(90-P14)/180)*COS((90-N14)*PI()/180)+SIN((90-P14)*PI()/180)*SIN((90-N14)*PI()/180)*COS((Q14-O14)*PI()/180)) -> 25.636785
A15: 3439684 | B15: MLPA | C15: 402301016 | D15: =_xlfn.XLOOKUP(C15,Planilha3!A:A,Planilha3!C:C) -> PARANÃ | E15: 1 | F15: =_xlfn.XLOOKUP(C15,Planilha3!A:A,Planilha3!E:E) -> 45303.609 | G15: =_xlfn.XLOOKUP(C15,Planilha3!A:A,Planilha3!F:F) -> 45316.609 | H15: =_xlfn.XLOOKUP(C15,Planilha3!A:A,Planilha3!G:G) -> 45916 | I15: =_xlfn.XLOOKUP(K15,Grupo!F:F,Grupo!G:G) -> 46440.22 | J15: =_xlfn.XLOOKUP(D15,Grupo!B:B,Grupo!C:C) -> 10 | K15: =_xlfn.XLOOKUP(A15,[1]COORDENADAS_GEOGRÁFICAS!$D:$D,[1]COORDENADAS_GEOGRÁFICAS!$F:$F) -> 80 | N15: =_xlfn.XLOOKUP(D15,Grupo!B:B,Grupo!D:D) -> -12.620481 | O15: =_xlfn.XLOOKUP(D15,Grupo!B:B,Grupo!E:E) -> -47.884084 | P15: =_xlfn.XLOOKUP(A15,[1]COORDENADAS_GEOGRÁFICAS!$D:$D,[1]COORDENADAS_GEOGRÁFICAS!$G:$G) -> -12.335967 | Q15: =_xlfn.XLOOKUP(A15,[1]COORDENADAS_GEOGRÁFICAS!$D:$D,[1]COORDENADAS_GEOGRÁFICAS!$H:$H) -> -48.202075 | R15: =6371*ACOS(COS(PI()*(90-P15)/180)*COS((90-N15)*PI()/180)+SIN((90-P15)*PI()/180)*SIN((90-N15)*PI()/180)*COS((Q15-O15)*PI()/180)) -> 46.826919
... A117: 3466828 | B117: MLPA | C117: 402301261 | D117: =_xlfn.XLOOKUP(C117,Planilha3!A:A,Planilha3!C:C) -> PARANÃ | E117: 1 | F117: =_xlfn.XLOOKUP(C117,Planilha3!A:A,Planilha3!E:E) -> 45453 | G117: =_xlfn.XLOOKUP(C117,Planilha3!A:A,Planilha3!F:F) -> 45464 | H117: =_xlfn.XLOOKUP(C117,Planilha3!A:A,Planilha3!G:G) -> 45922 | I117: =_xlfn.XLOOKUP(K117,Grupo!F:F,Grupo!G:G) -> 46440.22 | J117: =_xlfn.XLOOKUP(D117,Grupo!B:B,Grupo!C:C) -> 10 | K117: =_xlfn.XLOOKUP(A117,[1]COORDENADAS_GEOGRÁFICAS!$D:$D,[1]COORDENADAS_GEOGRÁFICAS!$F:$F) -> 80 | N117: =_xlfn.XLOOKUP(D117,Grupo!B:B,Grupo!D:D) -> -12.620481 | O117: =_xlfn.XLOOKUP(D117,Grupo!B:B,Grupo!E:E) -> -47.884084 | P117: =_xlfn.XLOOKUP(A117,[1]COORDENADAS_GEOGRÁFICAS!$D:$D,[1]COORDENADAS_GEOGRÁFICAS!$G:$G) -> -13.148413 | Q117: =_xlfn.XLOOKUP(A117,[1]COORDENADAS_GEOGRÁFICAS!$D:$D,[1]COORDENADAS_GEOGRÁFICAS!$H:$H) -> -47.651178 | R117: =6371*ACOS(COS(PI()*(90-P117)/180)*COS((90-N117)*PI()/180)+SIN((90-P117)*PI()/180)*SIN((90-N117)*PI()/180)*COS((Q117-O117)*PI()/180)) -> 63.901697
A118: 3463158 | B118: MLPA | C118: 402301267 | D118: =_xlfn.XLOOKUP(C118,Planilha3!A:A,Planilha3!C:C) -> PARANÃ | E118: 1 | F118: =_xlfn.XLOOKUP(C118,Planilha3!A:A,Planilha3!E:E) -> 45453 | G118: =_xlfn.XLOOKUP(C118,Planilha3!A:A,Planilha3!F:F) -> 45465 | H118: =_xlfn.XLOOKUP(C118,Planilha3!A:A,Planilha3!G:G) -> 45922 | I118: =_xlfn.XLOOKUP(K118,Grupo!F:F,Grupo!G:G) -> 46440.22 | J118: =_xlfn.XLOOKUP(D118,Grupo!B:B,Grupo!C:C) -> 10 | K118: =_xlfn.XLOOKUP(A118,[1]COORDENADAS_GEOGRÁFICAS!$D:$D,[1]COORDENADAS_GEOGRÁFICAS!$F:$F) -> 80 | N118: -12.620481 | O118: -47.884084 | P118: -13.233723 | Q118: -47.66909 | R118: =6371*ACOS(COS(PI()*(90-P118)/180)*COS((90-N118)*PI()/180)+SIN((90-P118)*PI()/180)*SIN((90-N118)*PI()/180)*COS((Q118-O118)*PI()/180)) -> 72.060292
A119: 3466920 | B119: MLPA | C119: 402301269 | D119: =_xlfn.XLOOKUP(C119,Planilha3!A:A,Planilha3!C:C) -> PARANÃ | E119: 1 | F119: =_xlfn.XLOOKUP(C119,Planilha3!A:A,Planilha3!E:E) -> 45452 | G119: =_xlfn.XLOOKUP(C119,Planilha3!A:A,Planilha3!F:F) -> 45465 | H119: =_xlfn.XLOOKUP(C119,Planilha3!A:A,Planilha3!G:G) -> 45922 | I119: =_xlfn.XLOOKUP(K119,Grupo!F:F,Grupo!G:G) -> 46440.22 | J119: =_xlfn.XLOOKUP(D119,Grupo!B:B,Grupo!C:C) -> 10 | K119: =_xlfn.XLOOKUP(A119,[1]COORDENADAS_GEOGRÁFICAS!$D:$D,[1]COORDENADAS_GEOGRÁFICAS!$F:$F) -> 80 | N119: =_xlfn.XLOOKUP(D119,Grupo!B:B,Grupo!D:D) -> -12.620481 | O119: =_xlfn.XLOOKUP(D119,Grupo!B:B,Grupo!E:E) -> -47.884084 | P119: =_xlfn.XLOOKUP(A119,[1]COORDENADAS_GEOGRÁFICAS!$D:$D,[1]COORDENADAS_GEOGRÁFICAS!$G:$G) -> -13.216033 | Q119: =_xlfn.XLOOKUP(A119,[1]COORDENADAS_GEOGRÁFICAS!$D:$D,[1]COORDENADAS_GEOGRÁFICAS!$H:$H) -> -47.670985 | R119: =6371*ACOS(COS(PI()*(90-P119)/180)*COS((90-N119)*PI()/180)+SIN((90-P119)*PI()/180)*SIN((90-N119)*PI()/180)*COS((Q119-O119)*PI()/180)) -> 70.134176
A120: 3463198 | B120: MLPA | C120: 402301271 | D120: =_xlfn.XLOOKUP(C120,Planilha3!A:A,Planilha3!C:C) -> PARANÃ | E120: 1 | F120: =_xlfn.XLOOKUP(C120,Planilha3!A:A,Planilha3!E:E) -> 45450 | G120: =_xlfn.XLOOKUP(C120,Planilha3!A:A,Planilha3!F:F) -> 45465 | H120: =_xlfn.XLOOKUP(C120,Planilha3!A:A,Planilha3!G:G) -> 45922 | I120: =_xlfn.XLOOKUP(K120,Grupo!F:F,Grupo!G:G) -> 46440.22 | J120: =_xlfn.XLOOKUP(D120,Grupo!B:B,Grupo!C:C) -> 10 | K120: =_xlfn.XLOOKUP(A120,[1]COORDENADAS_GEOGRÁFICAS!$D:$D,[1]COORDENADAS_GEOGRÁFICAS!$F:$F) -> 80 | N120: =_xlfn.XLOOKUP(D120,Grupo!B:B,Grupo!D:D) -> -12.620481 | O120: =_xlfn.XLOOKUP(D120,Grupo!B:B,Grupo!E:E) -> -47.884084 | P120: =_xlfn.XLOOKUP(A120,[1]COORDENADAS_GEOGRÁFICAS!$D:$D,[1]COORDENADAS_GEOGRÁFICAS!$G:$G) -> -13.293277 | Q120: =_xlfn.XLOOKUP(A120,[1]COORDENADAS_GEOGRÁFICAS!$D:$D,[1]COORDENADAS_GEOGRÁFICAS!$H:$H) -> -47.729392 | R120: =6371*ACOS(COS(PI()*(90-P120)/180)*COS((90-N120)*PI()/180)+SIN((90-P120)*PI()/180)*SIN((90-N120)*PI()/180)*COS((Q120-O120)*PI()/180)) -> 76.666463
A121: 3467106 | B121: MLPA | C121: 402301270 | D121: =_xlfn.XLOOKUP(C121,Planilha3!A:A,Planilha3!C:C) -> PARANÃ | E121: 1 | F121: =_xlfn.XLOOKUP(C121,Planilha3!A:A,Planilha3!E:E) -> 45454 | G121: =_xlfn.XLOOKUP(C121,Planilha3!A:A,Planilha3!F:F) -> 45465 | H121: =_xlfn.XLOOKUP(C121,Planilha3!A:A,Planilha3!G:G) -> 45922 | I121: =_xlfn.XLOOKUP(K121,Grupo!F:F,Grupo!G:G) -> 46440.22 | J121: =_xlfn.XLOOKUP(D121,Grupo!B:B,Grupo!C:C) -> 10 | K121: =_xlfn.XLOOKUP(A121,[1]COORDENADAS_GEOGRÁFICAS!$D:$D,[1]COORDENADAS_GEOGRÁFICAS!$F:$F) -> 80 | N121: =_xlfn.XLOOKUP(D121,Grupo!B:B,Grupo!D:D) -> -12.620481 | O121: =_xlfn.XLOOKUP(D121,Grupo!B:B,Grupo!E:E) -> -47.884084 | P121: =_xlfn.XLOOKUP(A121,[1]COORDENADAS_GEOGRÁFICAS!$D:$D,[1]COORDENADAS_GEOGRÁFICAS!$G:$G) -> -13.278975 | Q121: =_xlfn.XLOOKUP(A121,[1]COORDENADAS_GEOGRÁFICAS!$D:$D,[1]COORDENADAS_GEOGRÁFICAS!$H:$H) -> -47.710357 | R121: =6371*ACOS(COS(PI()*(90-P121)/180)*COS((90-N121)*PI()/180)+SIN((90-P121)*PI()/180)*SIN((90-N121)*PI()/180)*COS((Q121-O121)*PI()/180)) -> 75.602628
A122: 3464197 | B122: MLPA | C122: 402301243 | D122: =_xlfn.XLOOKUP(C122,Planilha3!A:A,Planilha3!C:C) -> PARANÃ | E122: 1 | F122: =_xlfn.XLOOKUP(C122,Planilha3!A:A,Planilha3!E:E) -> 45441 | G122: =_xlfn.XLOOKUP(C122,Planilha3!A:A,Planilha3!F:F) -> 45453 | H122: =_xlfn.XLOOKUP(C122,Planilha3!A:A,Planilha3!G:G) -> 45922 | I122: =_xlfn.XLOOKUP(K122,Grupo!F:F,Grupo!G:G) -> 46440.22 | J122: =_xlfn.XLOOKUP(D122,Grupo!B:B,Grupo!C:C) -> 10 | K122: =_xlfn.XLOOKUP(A122,[1]COORDENADAS_GEOGRÁFICAS!$D:$D,[1]COORDENADAS_GEOGRÁFICAS!$F:$F) -> 80 | N122: =_xlfn.XLOOKUP(D122,Grupo!B:B,Grupo!D:D) -> -12.620481 | O122: =_xlfn.XLOOKUP(D122,Grupo!B:B,Grupo!E:E) -> -47.884084 | P122: =_xlfn.XLOOKUP(A122,[1]COORDENADAS_GEOGRÁFICAS!$D:$D,[1]COORDENADAS_GEOGRÁFICAS!$G:$G) -> -12.99181 | Q122: =_xlfn.XLOOKUP(A122,[1]COORDENADAS_GEOGRÁFICAS!$D:$D,[1]COORDENADAS_GEOGRÁFICAS!$H:$H) -> -47.754275 | R122: =6371*ACOS(COS(PI()*(90-P122)/180)*COS((90-N122)*PI()/180)+SIN((90-P122)*PI()/180)*SIN((90-N122)*PI()/180)*COS((Q122-O122)*PI()/180)) -> 43.622897
A123: 3467083 | B123: MLPA | C123: 402301236 | D123: =_xlfn.XLOOKUP(C123,Planilha3!A:A,Planilha3!C:C) -> PARANÃ | E123: 1 | F123: =_xlfn.XLOOKUP(C123,Planilha3!A:A,Planilha3!E:E) -> 45450 | G123: =_xlfn.XLOOKUP(C123,Planilha3!A:A,Planilha3!F:F) -> 45463 | H123: =_xlfn.XLOOKUP(C123,Planilha3!A:A,Planilha3!G:G) -> 45922 | I123: =_xlfn.XLOOKUP(K123,Grupo!F:F,Grupo!G:G) -> 46440.22 | J123: =_xlfn.XLOOKUP(D123,Grupo!B:B,Grupo!C:C) -> 10 | K123: =_xlfn.XLOOKUP(A123,[1]COORDENADAS_GEOGRÁFICAS!$D:$D,[1]COORDENADAS_GEOGRÁFICAS!$F:$F) -> 80 | N123: =_xlfn.XLOOKUP(D123,Grupo!B:B,Grupo!D:D) -> -12.620481 | O123: =_xlfn.XLOOKUP(D123,Grupo!B:B,Grupo!E:E) -> -47.884084 | P123: =_xlfn.XLOOKUP(A123,[1]COORDENADAS_GEOGRÁFICAS!$D:$D,[1]COORDENADAS_GEOGRÁFICAS!$G:$G) -> -12.958562 | Q123: =_xlfn.XLOOKUP(A123,[1]COORDENADAS_GEOGRÁFICAS!$D:$D,[1]COORDENADAS_GEOGRÁFICAS!$H:$H) -> -47.623715 | R123: =6371*ACOS(COS(PI()*(90-P123)/180)*COS((90-N123)*PI()/180)+SIN((90-P123)*PI()/180)*SIN((90-N123)*PI()/180)*COS((Q123-O123)*PI()/180)) -> 47.014283
A124: 3463232 | B124: MLPA | C124: 402301235 | D124: =_xlfn.XLOOKUP(C124,Planilha3!A:A,Planilha3!C:C) -> PARANÃ | E124: 1 | F124: =_xlfn.XLOOKUP(C124,Planilha3!A:A,Planilha3!E:E) -> 45447 | G124: =_xlfn.XLOOKUP(C124,Planilha3!A:A,Planilha3!F:F) -> 45462 | H124: =_xlfn.XLOOKUP(C124,Planilha3!A:A,Planilha3!G:G) -> 45922 | I124: =_xlfn.XLOOKUP(K124,Grupo!F:F,Grupo!G:G) -> 46440.22 | J124: =_xlfn.XLOOKUP(D124,Grupo!B:B,Grupo!C:C) -> 10 | K124: =_xlfn.XLOOKUP(A124,[1]COORDENADAS_GEOGRÁFICAS!$D:$D,[1]COORDENADAS_GEOGRÁFICAS!$F:$F) -> 80 | N124: =_xlfn.XLOOKUP(D124,Grupo!B:B,Grupo!D:D) -> -12.620481 | O124: =_xlfn.XLOOKUP(D124,Grupo!B:B,Grupo!E:E) -> -47.884084 | P124: =_xlfn.XLOOKUP(A124,[1]COORDENADAS_GEOGRÁFICAS!$D:$D,[1]COORDENADAS_GEOGRÁFICAS!$G:$G) -> -12.362678 | Q124: =_xlfn.XLOOKUP(A124,[1]COORDENADAS_GEOGRÁFICAS!$D:$D,[1]COORDENADAS_GEOGRÁFICAS!$H:$H) -> -47.869373 | R124: =6371*ACOS(COS(PI()*(90-P124)/180)*COS((90-N124)*PI()/180)+SIN((90-P124)*PI()/180)*SIN((90-N124)*PI()/180)*COS((Q124-O124)*PI()/180)) -> 28.710892
A125: 3462372 | B125: MLPA | C125: 402301232 | D125: =_xlfn.XLOOKUP(C125,Planilha3!A:A,Planilha3!C:C) -> PARANÃ | E125: 1 | F125: =_xlfn.XLOOKUP(C125,Planilha3!A:A,Planilha3!E:E) -> 45445 | G125: =_xlfn.XLOOKUP(C125,Planilha3!A:A,Planilha3!F:F) -> 45461 | H125: =_xlfn.XLOOKUP(C125,Planilha3!A:A,Planilha3!G:G) -> 45922 | I125: =_xlfn.XLOOKUP(K125,Grupo!F:F,Grupo!G:G) -> 46440.22 | J125: =_xlfn.XLOOKUP(D125,Grupo!B:B,Grupo!C:C) -> 10 | K125: =_xlfn.XLOOKUP(A125,[1]COORDENADAS_GEOGRÁFICAS!$D:$D,[1]COORDENADAS_GEOGRÁFICAS!$F:$F) -> 80 | N125: =_xlfn.XLOOKUP(D125,Grupo!B:B,Grupo!D:D) -> -12.620481 | O125: =_xlfn.XLOOKUP(D125,Grupo!B:B,Grupo!E:E) -> -47.884084 | P125: =_xlfn.XLOOKUP(A125,[1]COORDENADAS_GEOGRÁFICAS!$D:$D,[1]COORDENADAS_GEOGRÁFICAS!$G:$G) -> -12.870557 | Q125: =_xlfn.XLOOKUP(A125,[1]COORDENADAS_GEOGRÁFICAS!$D:$D,[1]COORDENADAS_GEOGRÁFICAS!$H:$H) -> -47.54364 | R125: =6371*ACOS(COS(PI()*(90-P125)/180)*COS((90-N125)*PI()/180)+SIN((90-P125)*PI()/180)*SIN((90-N125)*PI()/180)*COS((Q125-O125)*PI()/180)) -> 46.222609
A126: 3466805 | B126: MLPA | C126: 402301257 | D126: =_xlfn.XLOOKUP(C126,Planilha3!A:A,Planilha3!C:C) -> PARANÃ | E126: 1 | F126: =_xlfn.XLOOKUP(C126,Planilha3!A:A,Planilha3!E:E) -> 45453 | G126: =_xlfn.XLOOKUP(C126,Planilha3!A:A,Planilha3!F:F) -> 45464 | H126: =_xlfn.XLOOKUP(C126,Planilha3!A:A,Planilha3!G:G) -> 45922 | I126: =_xlfn.XLOOKUP(K126,Grupo!F:F,Grupo!G:G) -> 46440.22 | J126: =_xlfn.XLOOKUP(D126,Grupo!B:B,Grupo!C:C) -> 10 | K126: =_xlfn.XLOOKUP(A126,[1]COORDENADAS_GEOGRÁFICAS!$D:$D,[1]COORDENADAS_GEOGRÁFICAS!$F:$F) -> 80 | N126: =_xlfn.XLOOKUP(D126,Grupo!B:B,Grupo!D:D) -> -12.620481 | O126: =_xlfn.XLOOKUP(D126,Grupo!B:B,Grupo!E:E) -> -47.884084 | P126: =_xlfn.XLOOKUP(A126,[1]COORDENADAS_GEOGRÁFICAS!$D:$D,[1]COORDENADAS_GEOGRÁFICAS!$G:$G) -> -13.121487 | Q126: =_xlfn.XLOOKUP(A126,[1]COORDENADAS_GEOGRÁFICAS!$D:$D,[1]COORDENADAS_GEOGRÁFICAS!$H:$H) -> -47.715932 | R126: =6371*ACOS(COS(PI()*(90-P126)/180)*COS((90-N126)*PI()/180)+SIN((90-P126)*PI()/180)*SIN((90-N126)*PI()/180)*COS((Q126-O126)*PI()/180)) -> 58.615476
A127: 3463161 | B127: MLPA | C127: 402301268 | D127: =_xlfn.XLOOKUP(C127,Planilha3!A:A,Planilha3!C:C) -> PARANÃ | E127: 1 | F127: =_xlfn.XLOOKUP(C127,Planilha3!A:A,Planilha3!E:E) -> 45453 | G127: =_xlfn.XLOOKUP(C127,Planilha3!A:A,Planilha3!F:F) -> 45465 | H127: =_xlfn.XLOOKUP(C127,Planilha3!A:A,Planilha3!G:G) -> 45922 | I127: =_xlfn.XLOOKUP(K127,Grupo!F:F,Grupo!G:G) -> 46440.22 | J127: =_xlfn.XLOOKUP(D127,Grupo!B:B,Grupo!C:C) -> 10 | K127: =_xlfn.XLOOKUP(A127,[1]COORDENADAS_GEOGRÁFICAS!$D:$D,[1]COORDENADAS_GEOGRÁFICAS!$F:$F) -> 80 | N127: =_xlfn.XLOOKUP(D127,Grupo!B:B,Grupo!D:D) -> -12.620481 | O127: =_xlfn.XLOOKUP(D127,Grupo!B:B,Grupo!E:E) -> -47.884084 | P127: =_xlfn.XLOOKUP(A127,[1]COORDENADAS_GEOGRÁFICAS!$D:$D,[1]COORDENADAS_GEOGRÁFICAS!$G:$G) -> -13.244778 | Q127: =_xlfn.XLOOKUP(A127,[1]COORDENADAS_GEOGRÁFICAS!$D:$D,[1]COORDENADAS_GEOGRÁFICAS!$H:$H) -> -47.649161 | R127: =6371*ACOS(COS(PI()*(90-P127)/180)*COS((90-N127)*PI()/180)+SIN((90-P127)*PI()/180)*SIN((90-N127)*PI()/180)*COS((Q127-O127)*PI()/180)) -> 73.940018
A128: 3463573 | B128: MLPA | C128: 402301258 | D128: =_xlfn.XLOOKUP(C128,Planilha3!A:A,Planilha3!C:C) -> PARANÃ | E128: 1 | F128: =_xlfn.XLOOKUP(C128,Planilha3!A:A,Planilha3!E:E) -> 45451 | G128: =_xlfn.XLOOKUP(C128,Planilha3!A:A,Planilha3!F:F) -> 45464 | H128: =_xlfn.XLOOKUP(C128,Planilha3!A:A,Planilha3!G:G) -> 45922 | I128: =_xlfn.XLOOKUP(K128,Grupo!F:F,Grupo!G:G) -> 46440.22 | J128: =_xlfn.XLOOKUP(D128,Grupo!B:B,Grupo!C:C) -> 10 | K128: =_xlfn.XLOOKUP(A128,[1]COORDENADAS_GEOGRÁFICAS!$D:$D,[1]COORDENADAS_GEOGRÁFICAS!$F:$F) -> 80 | N128: =_xlfn.XLOOKUP(D128,Grupo!B:B,Grupo!D:D) -> -12.620481 | O128: =_xlfn.XLOOKUP(D128,Grupo!B:B,Grupo!E:E) -> -47.884084 | P128: =_xlfn.XLOOKUP(A128,[1]COORDENADAS_GEOGRÁFICAS!$D:$D,[1]COORDENADAS_GEOGRÁFICAS!$G:$G) -> -13.163478 | Q128: =_xlfn.XLOOKUP(A128,[1]COORDENADAS_GEOGRÁFICAS!$D:$D,[1]COORDENADAS_GEOGRÁFICAS!$H:$H) -> -47.667717 | R128: =6371*ACOS(COS(PI()*(90-P128)/180)*COS((90-N128)*PI()/180)+SIN((90-P128)*PI()/180)*SIN((90-N128)*PI()/180)*COS((Q128-O128)*PI()/180)) -> 64.773213
A129: 3466790 | B129: MLPA | C129: 402301250 | D129: =_xlfn.XLOOKUP(C129,Planilha3!A:A,Planilha3!C:C) -> PARANÃ | E129: 1 | F129: =_xlfn.XLOOKUP(C129,Planilha3!A:A,Planilha3!E:E) -> 45448 | G129: =_xlfn.XLOOKUP(C129,Planilha3!A:A,Planilha3!F:F) -> 45463 | H129: =_xlfn.XLOOKUP(C129,Planilha3!A:A,Planilha3!G:G) -> 45922 | I129: =_xlfn.XLOOKUP(K129,Grupo!F:F,Grupo!G:G) -> 46440.22 | J129: =_xlfn.XLOOKUP(D129,Grupo!B:B,Grupo!C:C) -> 10 | K129: =_xlfn.XLOOKUP(A129,[1]COORDENADAS_GEOGRÁFICAS!$D:$D,[1]COORDENADAS_GEOGRÁFICAS!$F:$F) -> 80 | N129: =_xlfn.XLOOKUP(D129,Grupo!B:B,Grupo!D:D) -> -12.620481 | O129: =_xlfn.XLOOKUP(D129,Grupo!B:B,Grupo!E:E) -> -47.884084 | P129: =_xlfn.XLOOKUP(A129,[1]COORDENADAS_GEOGRÁFICAS!$D:$D,[1]COORDENADAS_GEOGRÁFICAS!$G:$G) -> -12.753415 | Q129: =_xlfn.XLOOKUP(A129,[1]COORDENADAS_GEOGRÁFICAS!$D:$D,[1]COORDENADAS_GEOGRÁFICAS!$H:$H) -> -47.426275 | R129: =6371*ACOS(COS(PI()*(90-P129)/180)*COS((90-N129)*PI()/180)+SIN((90-P129)*PI()/180)*SIN((90-N129)*PI()/180)*COS((Q129-O129)*PI()/180)) -> 51.816185
A130: 3466916 | B130: MLPA | C130: 402301266 | D130: =_xlfn.XLOOKUP(C130,Planilha3!A:A,Planilha3!C:C) -> PARANÃ | E130: 1 | F130: =_xlfn.XLOOKUP(C130,Planilha3!A:A,Planilha3!E:E) -> 45453 | G130: =_xlfn.XLOOKUP(C130,Planilha3!A:A,Planilha3!F:F) -> 45464 | H130: =_xlfn.XLOOKUP(C130,Planilha3!A:A,Planilha3!G:G) -> 45922 | I130: =_xlfn.XLOOKUP(K130,Grupo!F:F,Grupo!G:G) -> 46440.22 | J130: =_xlfn.XLOOKUP(D130,Grupo!B:B,Grupo!C:C) -> 10 | K130: =_xlfn.XLOOKUP(A130,[1]COORDENADAS_GEOGRÁFICAS!$D:$D,[1]COORDENADAS_GEOGRÁFICAS!$F:$F) -> 80 | N130: =_xlfn.XLOOKUP(D130,Grupo!B:B,Grupo!D:D) -> -12.620481 | O130: =_xlfn.XLOOKUP(D130,Grupo!B:B,Grupo!E:E) -> -47.884084 | P130: =_xlfn.XLOOKUP(A130,[1]COORDENADAS_GEOGRÁFICAS!$D:$D,[1]COORDENADAS_GEOGRÁFICAS!$G:$G) -> -13.247202 | Q130: =_xlfn.XLOOKUP(A130,[1]COORDENADAS_GEOGRÁFICAS!$D:$D,[1]COORDENADAS_GEOGRÁFICAS!$H:$H) -> -47.675962 | R130: =6371*ACOS(COS(PI()*(90-P130)/180)*COS((90-N130)*PI()/180)+SIN((90-P130)*PI()/180)*SIN((90-N130)*PI()/180)*COS((Q130-O130)*PI()/180)) -> 73.24723
... A182: 3463187 | B182: MLPA | C182: 402400064 | D182: =_xlfn.XLOOKUP(C182,Planilha3!A:A,Planilha3!C:C) -> PARANÃ | E182: 1 | F182: =_xlfn.XLOOKUP(C182,Planilha3!A:A,Planilha3!E:E) -> 45454.358 | G182: =_xlfn.XLOOKUP(C182,Planilha3!A:A,Planilha3!F:F) -> 45467.358 | H182: =_xlfn.XLOOKUP(C182,Planilha3!A:A,Planilha3!G:G) -> 45922 | I182: =_xlfn.XLOOKUP(K182,Grupo!F:F,Grupo!G:G) -> 46440.22 | J182: =_xlfn.XLOOKUP(D182,Grupo!B:B,Grupo!C:C) -> 10 | K182: =_xlfn.XLOOKUP(A182,[1]COORDENADAS_GEOGRÁFICAS!$D:$D,[1]COORDENADAS_GEOGRÁFICAS!$F:$F) -> 80 | N182: =_xlfn.XLOOKUP(D182,Grupo!B:B,Grupo!D:D) -> -12.620481 | O182: =_xlfn.XLOOKUP(D182,Grupo!B:B,Grupo!E:E) -> -47.884084 | P182: =_xlfn.XLOOKUP(A182,[1]COORDENADAS_GEOGRÁFICAS!$D:$D,[1]COORDENADAS_GEOGRÁFICAS!$G:$G) -> -13.295778 | Q182: =_xlfn.XLOOKUP(A182,[1]COORDENADAS_GEOGRÁFICAS!$D:$D,[1]COORDENADAS_GEOGRÁFICAS!$H:$H) -> -47.68164 | R182: =6371*ACOS(COS(PI()*(90-P182)/180)*COS((90-N182)*PI()/180)+SIN((90-P182)*PI()/180)*SIN((90-N182)*PI()/180)*COS((Q182-O182)*PI()/180)) -> 78.22842
A183: 3467117 | B183: MLPA | C183: 402400061 | D183: =_xlfn.XLOOKUP(C183,Planilha3!A:A,Planilha3!C:C) -> PARANÃ | E183: 1 | F183: =_xlfn.XLOOKUP(C183,Planilha3!A:A,Planilha3!E:E) -> 45450.677 | G183: =_xlfn.XLOOKUP(C183,Planilha3!A:A,Planilha3!F:F) -> 45465.677 | H183: =_xlfn.XLOOKUP(C183,Planilha3!A:A,Planilha3!G:G) -> 45922 | I183: =_xlfn.XLOOKUP(K183,Grupo!F:F,Grupo!G:G) -> 46440.22 | J183: =_xlfn.XLOOKUP(D183,Grupo!B:B,Grupo!C:C) -> 10 | K183: =_xlfn.XLOOKUP(A183,[1]COORDENADAS_GEOGRÁFICAS!$D:$D,[1]COORDENADAS_GEOGRÁFICAS!$F:$F) -> 80 | N183: -12.620481 | O183: -47.884084 | P183: -13.08901 | Q183: -47.674202 | R183: =6371*ACOS(COS(PI()*(90-P183)/180)*COS((90-N183)*PI()/180)+SIN((90-P183)*PI()/180)*SIN((90-N183)*PI()/180)*COS((Q183-O183)*PI()/180)) -> 56.849721
A184: 3467212 | B184: MLPA | C184: 402400087 | D184: =_xlfn.XLOOKUP(C184,Planilha3!A:A,Planilha3!C:C) -> PARANÃ | E184: 1 | F184: =_xlfn.XLOOKUP(C184,Planilha3!A:A,Planilha3!E:E) -> 45457.438 | G184: =_xlfn.XLOOKUP(C184,Planilha3!A:A,Planilha3!F:F) -> 45468.438 | H184: =_xlfn.XLOOKUP(C184,Planilha3!A:A,Planilha3!G:G) -> 45922 | I184: =_xlfn.XLOOKUP(K184,Grupo!F:F,Grupo!G:G) -> 46440.22 | J184: =_xlfn.XLOOKUP(D184,Grupo!B:B,Grupo!C:C) -> 10 | K184: =_xlfn.XLOOKUP(A184,[1]COORDENADAS_GEOGRÁFICAS!$D:$D,[1]COORDENADAS_GEOGRÁFICAS!$F:$F) -> 80 | N184: =_xlfn.XLOOKUP(D184,Grupo!B:B,Grupo!D:D) -> -12.620481 | O184: =_xlfn.XLOOKUP(D184,Grupo!B:B,Grupo!E:E) -> -47.884084 | P184: =_xlfn.XLOOKUP(A184,[1]COORDENADAS_GEOGRÁFICAS!$D:$D,[1]COORDENADAS_GEOGRÁFICAS!$G:$G) -> -13.250114 | Q184: =_xlfn.XLOOKUP(A184,[1]COORDENADAS_GEOGRÁFICAS!$D:$D,[1]COORDENADAS_GEOGRÁFICAS!$H:$H) -> -47.674072 | R184: =6371*ACOS(COS(PI()*(90-P184)/180)*COS((90-N184)*PI()/180)+SIN((90-P184)*PI()/180)*SIN((90-N184)*PI()/180)*COS((Q184-O184)*PI()/180)) -> 73.618388
A185: 3463163 | B185: MLPA | C185: 402400065 | D185: =_xlfn.XLOOKUP(C185,Planilha3!A:A,Planilha3!C:C) -> PARANÃ | E185: 1 | F185: =_xlfn.XLOOKUP(C185,Planilha3!A:A,Planilha3!E:E) -> 45455.371 | G185: =_xlfn.XLOOKUP(C185,Planilha3!A:A,Planilha3!F:F) -> 45467.371 | H185: =_xlfn.XLOOKUP(C185,Planilha3!A:A,Planilha3!G:G) -> 45922 | I185: =_xlfn.XLOOKUP(K185,Grupo!F:F,Grupo!G:G) -> 46440.22 | J185: =_xlfn.XLOOKUP(D185,Grupo!B:B,Grupo!C:C) -> 10 | K185: =_xlfn.XLOOKUP(A185,[1]COORDENADAS_GEOGRÁFICAS!$D:$D,[1]COORDENADAS_GEOGRÁFICAS!$F:$F) -> 80 | N185: =_xlfn.XLOOKUP(D185,Grupo!B:B,Grupo!D:D) -> -12.620481 | O185: =_xlfn.XLOOKUP(D185,Grupo!B:B,Grupo!E:E) -> -47.884084 | P185: =_xlfn.XLOOKUP(A185,[1]COORDENADAS_GEOGRÁFICAS!$D:$D,[1]COORDENADAS_GEOGRÁFICAS!$G:$G) -> -13.288798 | Q185: =_xlfn.XLOOKUP(A185,[1]COORDENADAS_GEOGRÁFICAS!$D:$D,[1]COORDENADAS_GEOGRÁFICAS!$H:$H) -> -47.656587 | R185: =6371*ACOS(COS(PI()*(90-P185)/180)*COS((90-N185)*PI()/180)+SIN((90-P185)*PI()/180)*SIN((90-N185)*PI()/180)*COS((Q185-O185)*PI()/180)) -> 78.295763
A186: 3466879 | B186: MLPA | C186: 402400090 | D186: =_xlfn.XLOOKUP(C186,Planilha3!A:A,Planilha3!C:C) -> PARANÃ | E186: 1 | F186: =_xlfn.XLOOKUP(C186,Planilha3!A:A,Planilha3!E:E) -> 45455.466 | G186: =_xlfn.XLOOKUP(C186,Planilha3!A:A,Planilha3!F:F) -> 45468.466 | H186: =_xlfn.XLOOKUP(C186,Planilha3!A:A,Planilha3!G:G) -> 45922 | I186: =_xlfn.XLOOKUP(K186,Grupo!F:F,Grupo!G:G) -> 46440.22 | J186: =_xlfn.XLOOKUP(D186,Grupo!B:B,Grupo!C:C) -> 10 | K186: =_xlfn.XLOOKUP(A186,[1]COORDENADAS_GEOGRÁFICAS!$D:$D,[1]COORDENADAS_GEOGRÁFICAS!$F:$F) -> 80 | N186: =_xlfn.XLOOKUP(D186,Grupo!B:B,Grupo!D:D) -> -12.620481 | O186: =_xlfn.XLOOKUP(D186,Grupo!B:B,Grupo!E:E) -> -47.884084 | P186: =_xlfn.XLOOKUP(A186,[1]COORDENADAS_GEOGRÁFICAS!$D:$D,[1]COORDENADAS_GEOGRÁFICAS!$G:$G) -> -13.303593 | Q186: =_xlfn.XLOOKUP(A186,[1]COORDENADAS_GEOGRÁFICAS!$D:$D,[1]COORDENADAS_GEOGRÁFICAS!$H:$H) -> -47.663683 | R186: =6371*ACOS(COS(PI()*(90-P186)/180)*COS((90-N186)*PI()/180)+SIN((90-P186)*PI()/180)*SIN((90-N186)*PI()/180)*COS((Q186-O186)*PI()/180)) -> 79.624664
A187: 3466930 | B187: MLPA | C187: 402400088 | D187: =_xlfn.XLOOKUP(C187,Planilha3!A:A,Planilha3!C:C) -> PARANÃ | E187: 1 | F187: =_xlfn.XLOOKUP(C187,Planilha3!A:A,Planilha3!E:E) -> 45453.447 | G187: =_xlfn.XLOOKUP(C187,Planilha3!A:A,Planilha3!F:F) -> 45468.447 | H187: =_xlfn.XLOOKUP(C187,Planilha3!A:A,Planilha3!G:G) -> 45922 | I187: =_xlfn.XLOOKUP(K187,Grupo!F:F,Grupo!G:G) -> 46440.22 | J187: =_xlfn.XLOOKUP(D187,Grupo!B:B,Grupo!C:C) -> 10 | K187: =_xlfn.XLOOKUP(A187,[1]COORDENADAS_GEOGRÁFICAS!$D:$D,[1]COORDENADAS_GEOGRÁFICAS!$F:$F) -> 80 | N187: =_xlfn.XLOOKUP(D187,Grupo!B:B,Grupo!D:D) -> -12.620481 | O187: =_xlfn.XLOOKUP(D187,Grupo!B:B,Grupo!E:E) -> -47.884084 | P187: =_xlfn.XLOOKUP(A187,[1]COORDENADAS_GEOGRÁFICAS!$D:$D,[1]COORDENADAS_GEOGRÁFICAS!$G:$G) -> -13.296087 | Q187: =_xlfn.XLOOKUP(A187,[1]COORDENADAS_GEOGRÁFICAS!$D:$D,[1]COORDENADAS_GEOGRÁFICAS!$H:$H) -> -47.685901 | R187: =6371*ACOS(COS(PI()*(90-P187)/180)*COS((90-N187)*PI()/180)+SIN((90-P187)*PI()/180)*SIN((90-N187)*PI()/180)*COS((Q187-O187)*PI()/180)) -> 78.133227
A188: 3467213 | B188: MLPA | C188: 402400089 | D188: =_xlfn.XLOOKUP(C188,Planilha3!A:A,Planilha3!C:C) -> PARANÃ | E188: 1 | F188: =_xlfn.XLOOKUP(C188,Planilha3!A:A,Planilha3!E:E) -> 45452.452 | G188: =_xlfn.XLOOKUP(C188,Planilha3!A:A,Planilha3!F:F) -> 45468.452 | H188: =_xlfn.XLOOKUP(C188,Planilha3!A:A,Planilha3!G:G) -> 45922 | I188: =_xlfn.XLOOKUP(K188,Grupo!F:F,Grupo!G:G) -> 46440.22 | J188: =_xlfn.XLOOKUP(D188,Grupo!B:B,Grupo!C:C) -> 10 | K188: =_xlfn.XLOOKUP(A188,[1]COORDENADAS_GEOGRÁFICAS!$D:$D,[1]COORDENADAS_GEOGRÁFICAS!$F:$F) -> 80 | N188: =_xlfn.XLOOKUP(D188,Grupo!B:B,Grupo!D:D) -> -12.620481 | O188: =_xlfn.XLOOKUP(D188,Grupo!B:B,Grupo!E:E) -> -47.884084 | P188: =_xlfn.XLOOKUP(A188,[1]COORDENADAS_GEOGRÁFICAS!$D:$D,[1]COORDENADAS_GEOGRÁFICAS!$G:$G) -> -13.320015 | Q188: =_xlfn.XLOOKUP(A188,[1]COORDENADAS_GEOGRÁFICAS!$D:$D,[1]COORDENADAS_GEOGRÁFICAS!$H:$H) -> -47.677818 | R188: =6371*ACOS(COS(PI()*(90-P188)/180)*COS((90-N188)*PI()/180)+SIN((90-P188)*PI()/180)*SIN((90-N188)*PI()/180)*COS((Q188-O188)*PI()/180)) -> 80.931946
A189: 3466770 | B189: MLPA | C189: 402400086 | D189: =_xlfn.XLOOKUP(C189,Planilha3!A:A,Planilha3!C:C) -> PARANÃ | E189: 1 | F189: =_xlfn.XLOOKUP(C189,Planilha3!A:A,Planilha3!E:E) -> 45457.415 | G189: =_xlfn.XLOOKUP(C189,Planilha3!A:A,Planilha3!F:F) -> 45468.415 | H189: =_xlfn.XLOOKUP(C189,Planilha3!A:A,Planilha3!G:G) -> 45922 | I189: =_xlfn.XLOOKUP(K189,Grupo!F:F,Grupo!G:G) -> 46440.22 | J189: =_xlfn.XLOOKUP(D189,Grupo!B:B,Grupo!C:C) -> 10 | K189: =_xlfn.XLOOKUP(A189,[1]COORDENADAS_GEOGRÁFICAS!$D:$D,[1]COORDENADAS_GEOGRÁFICAS!$F:$F) -> 80 | N189: =_xlfn.XLOOKUP(D189,Grupo!B:B,Grupo!D:D) -> -12.620481 | O189: =_xlfn.XLOOKUP(D189,Grupo!B:B,Grupo!E:E) -> -47.884084 | P189: =_xlfn.XLOOKUP(A189,[1]COORDENADAS_GEOGRÁFICAS!$D:$D,[1]COORDENADAS_GEOGRÁFICAS!$G:$G) -> -13.146948 | Q189: =_xlfn.XLOOKUP(A189,[1]COORDENADAS_GEOGRÁFICAS!$D:$D,[1]COORDENADAS_GEOGRÁFICAS!$H:$H) -> -47.775047 | R189: =6371*ACOS(COS(PI()*(90-P189)/180)*COS((90-N189)*PI()/180)+SIN((90-P189)*PI()/180)*SIN((90-N189)*PI()/180)*COS((Q189-O189)*PI()/180)) -> 59.721595
A190: 3466873 | B190: MLPA | C190: 402400073 | D190: =_xlfn.XLOOKUP(C190,Planilha3!A:A,Planilha3!C:C) -> PARANÃ | E190: 1 | F190: =_xlfn.XLOOKUP(C190,Planilha3!A:A,Planilha3!E:E) -> 45456.635 | G190: =_xlfn.XLOOKUP(C190,Planilha3!A:A,Planilha3!F:F) -> 45468.635 | H190: =_xlfn.XLOOKUP(C190,Planilha3!A:A,Planilha3!G:G) -> 45922 | I190: =_xlfn.XLOOKUP(K190,Grupo!F:F,Grupo!G:G) -> 46440.22 | J190: =_xlfn.XLOOKUP(D190,Grupo!B:B,Grupo!C:C) -> 10 | K190: =_xlfn.XLOOKUP(A190,[1]COORDENADAS_GEOGRÁFICAS!$D:$D,[1]COORDENADAS_GEOGRÁFICAS!$F:$F) -> 80 | N190: =_xlfn.XLOOKUP(D190,Grupo!B:B,Grupo!D:D) -> -12.620481 | O190: =_xlfn.XLOOKUP(D190,Grupo!B:B,Grupo!E:E) -> -47.884084 | P190: =_xlfn.XLOOKUP(A190,[1]COORDENADAS_GEOGRÁFICAS!$D:$D,[1]COORDENADAS_GEOGRÁFICAS!$G:$G) -> -13.151652 | Q190: =_xlfn.XLOOKUP(A190,[1]COORDENADAS_GEOGRÁFICAS!$D:$D,[1]COORDENADAS_GEOGRÁFICAS!$H:$H) -> -47.741591 | R190: =6371*ACOS(COS(PI()*(90-P190)/180)*COS((90-N190)*PI()/180)+SIN((90-P190)*PI()/180)*SIN((90-N190)*PI()/180)*COS((Q190-O190)*PI()/180)) -> 61.04959
A191: 3466950 | B191: MLPA | C191: 402400079 | D191: =_xlfn.XLOOKUP(C191,Planilha3!A:A,Planilha3!C:C) -> PARANÃ | E191: 1 | F191: =_xlfn.XLOOKUP(C191,Planilha3!A:A,Planilha3!E:E) -> 45455.724 | G191: =_xlfn.XLOOKUP(C191,Planilha3!A:A,Planilha3!F:F) -> 45468.724 | H191: =_xlfn.XLOOKUP(C191,Planilha3!A:A,Planilha3!G:G) -> 45922 | I191: =_xlfn.XLOOKUP(K191,Grupo!F:F,Grupo!G:G) -> 46440.22 | J191: =_xlfn.XLOOKUP(D191,Grupo!B:B,Grupo!C:C) -> 10 | K191: =_xlfn.XLOOKUP(A191,[1]COORDENADAS_GEOGRÁFICAS!$D:$D,[1]COORDENADAS_GEOGRÁFICAS!$F:$F) -> 80 | N191: =_xlfn.XLOOKUP(D191,Grupo!B:B,Grupo!D:D) -> -12.620481 | O191: =_xlfn.XLOOKUP(D191,Grupo!B:B,Grupo!E:E) -> -47.884084 | P191: =_xlfn.XLOOKUP(A191,[1]COORDENADAS_GEOGRÁFICAS!$D:$D,[1]COORDENADAS_GEOGRÁFICAS!$G:$G) -> -13.149968 | Q191: =_xlfn.XLOOKUP(A191,[1]COORDENADAS_GEOGRÁFICAS!$D:$D,[1]COORDENADAS_GEOGRÁFICAS!$H:$H) -> -47.736065 | R191: =6371*ACOS(COS(PI()*(90-P191)/180)*COS((90-N191)*PI()/180)+SIN((90-P191)*PI()/180)*SIN((90-N191)*PI()/180)*COS((Q191-O191)*PI()/180)) -> 61.023205
A192: 3466158 | B192: MLPA | C192: 402400080 | D192: =_xlfn.XLOOKUP(C192,Planilha3!A:A,Planilha3!C:C) -> PARANÃ | E192: 1 | F192: =_xlfn.XLOOKUP(C192,Planilha3!A:A,Planilha3!E:E) -> 45453.73 | G192: =_xlfn.XLOOKUP(C192,Planilha3!A:A,Planilha3!F:F) -> 45468.73 | H192: =_xlfn.XLOOKUP(C192,Planilha3!A:A,Planilha3!G:G) -> 45922 | I192: =_xlfn.XLOOKUP(K192,Grupo!F:F,Grupo!G:G) -> 46440.22 | J192: =_xlfn.XLOOKUP(D192,Grupo!B:B,Grupo!C:C) -> 10 | K192: =_xlfn.XLOOKUP(A192,[1]COORDENADAS_GEOGRÁFICAS!$D:$D,[1]COORDENADAS_GEOGRÁFICAS!$F:$F) -> 80 | N192: =_xlfn.XLOOKUP(D192,Grupo!B:B,Grupo!D:D) -> -12.620481 | O192: =_xlfn.XLOOKUP(D192,Grupo!B:B,Grupo!E:E) -> -47.884084 | P192: =_xlfn.XLOOKUP(A192,[1]COORDENADAS_GEOGRÁFICAS!$D:$D,[1]COORDENADAS_GEOGRÁFICAS!$G:$G) -> -13.194426 | Q192: =_xlfn.XLOOKUP(A192,[1]COORDENADAS_GEOGRÁFICAS!$D:$D,[1]COORDENADAS_GEOGRÁFICAS!$H:$H) -> -47.666097 | R192: =6371*ACOS(COS(PI()*(90-P192)/180)*COS((90-N192)*PI()/180)+SIN((90-P192)*PI()/180)*SIN((90-N192)*PI()/180)*COS((Q192-O192)*PI()/180)) -> 68.052662
...

Sheet Lote1
A1: ENBPar
A2: RORAIMA ENERGIA 1ª Tranche
A3: UC | B3: Projeto | C3: Município | D3: Data Inicio | E3: Data Fim | F3: Custo(R$) | G3: Cons. | H3: Kit | I3: Regional | J3: Grupo | K3: Poste | L3: Rede AT km | M3: Rede BT km | N3: Medidor | O3: Trafo | P3: Equip. | Q3: VR
A4: =CALCULO_VR!A4 -> 3464081 | B4: =CALCULO_VR!B4 -> MLPA | C4: PARANA | D4: =CALCULO_VR!F4 -> 45436.387 | E4: =CALCULO_VR!G4 -> 45447.387 | F4: =CALCULO_VR!I4 -> 46440.22 | G4: =CALCULO_VR!E4 -> 1 | H4: =G4 -> 1 | I4: TO 2a | J4: =CALCULO_VR!J4 -> 10 | Q4: =CALCULO_VR!R4 -> 29.965319
A5: =CALCULO_VR!A5 -> 3459335 | B5: =CALCULO_VR!B5 -> MLPA | C5: PARANA | D5: =CALCULO_VR!F5 -> 45445.697 | E5: =CALCULO_VR!G5 -> 45457.697 | F5: =CALCULO_VR!I5 -> 46440.22 | G5: =CALCULO_VR!E5 -> 1 | H5: =G5 -> 1 | I5: TO 2a | J5: =CALCULO_VR!J5 -> 10 | Q5: =CALCULO_VR!R5 -> 53.480408
A6: =CALCULO_VR!A6 -> 3467062 | B6: =CALCULO_VR!B6 -> MLPA | C6: PARANA | D6: =CALCULO_VR!F6 -> 45447.663 | E6: =CALCULO_VR!G6 -> 45460.663 | F6: =CALCULO_VR!I6 -> 46440.22 | G6: =CALCULO_VR!E6 -> 1 | H6: =G6 -> 1 | I6: TO 2a | J6: =CALCULO_VR!J6 -> 10 | Q6: =CALCULO_VR!R6 -> 54.494131
A7: =CALCULO_VR!A7 -> 3430975 | B7: =CALCULO_VR!B7 -> MLPA | C7: PARANA | D7: =CALCULO_VR!F7 -> 45299.634 | E7: =CALCULO_VR!G7 -> 45314.634 | F7: =CALCULO_VR!I7 -> 46440.22 | G7: =CALCULO_VR!E7 -> 1 | H7: =G7 -> 1 | I7: TO 2a | J7: =CALCULO_VR!J7 -> 10 | Q7: =CALCULO_VR!R7 -> 49.62356
A8: =CALCULO_VR!A8 -> 3434827 | B8: =CALCULO_VR!B8 -> MLPA | C8: PARANA | D8: =CALCULO_VR!F8 -> 45298.603 | E8: =CALCULO_VR!G8 -> 45314.603 | F8: =CALCULO_VR!I8 -> 46440.22 | G8: =CALCULO_VR!E8 -> 1 | H8: =G8 -> 1 | I8: TO 2a | J8: =CALCULO_VR!J8 -> 10 | Q8: =CALCULO_VR!R8 -> 51.928189
A9: =CALCULO_VR!A9 -> 3434698 | B9: =CALCULO_VR!B9 -> MLPA | C9: PARANA | D9: =CALCULO_VR!F9 -> 45303.598 | E9: =CALCULO_VR!G9 -> 45314.598 | F9: =CALCULO_VR!I9 -> 46440.22 | G9: =CALCULO_VR!E9 -> 1 | H9: =G9 -> 1 | I9: TO 2a | J9: =CALCULO_VR!J9 -> 10 | Q9: =CALCULO_VR!R9 -> 55.189406
A10: =CALCULO_VR!A10 -> 3466701 | B10: =CALCULO_VR!B10 -> MLPA | C10: PARANA | D10: =CALCULO_VR!F10 -> 45445.663 | E10: =CALCULO_VR!G10 -> 45457.663 | F10: =CALCULO_VR!I10 -> 46440.22 | G10: =CALCULO_VR!E10 -> 1 | H10: =G10 -> 1 | I10: TO 2a | J10: =CALCULO_VR!J10 -> 10 | Q10: =CALCULO_VR!R10 -> 53.885313
A11: =CALCULO_VR!A11 -> 3464244 | B11: =CALCULO_VR!B11 -> MLPA | C11: PARANA | D11: =CALCULO_VR!F11 -> 45443.454 | E11: =CALCULO_VR!G11 -> 45456.454 | F11: =CALCULO_VR!I11 -> 46440.22 | G11: =CALCULO_VR!E11 -> 1 | H11: =G11 -> 1 | I11: TO 2a | J11: =CALCULO_VR!J11 -> 10 | Q11: =CALCULO_VR!R11 -> 44.724412
A12: =CALCULO_VR!A12 -> 3465687 | B12: =CALCULO_VR!B12 -> MLPA | C12: PARANA | D12: =CALCULO_VR!F12 -> 45442.638 | E12: =CALCULO_VR!G12 -> 45457.638 | F12: =CALCULO_VR!I12 -> 46440.22 | G12: =CALCULO_VR!E12 -> 1 | H12: =G12 -> 1 | I12: TO 2a | J12: =CALCULO_VR!J12 -> 10 | Q12: =CALCULO_VR!R12 -> 46.136249
A13: =CALCULO_VR!A13 -> 3435800 | B13: =CALCULO_VR!B13 -> MLPA | C13: PARANA | D13: =CALCULO_VR!F13 -> 45305.616 | E13: =CALCULO_VR!G13 -> 45316.616 | F13: =CALCULO_VR!I13 -> 46440.22 | G13: =CALCULO_VR!E13 -> 1 | H13: =G13 -> 1 | I13: TO 2a | J13: =CALCULO_VR!J13 -> 10 | Q13: =CALCULO_VR!R13 -> 24.608187
A14: =CALCULO_VR!A14 -> 3463633 | B14: =CALCULO_VR!B14 -> MLPA | C14: PARANA | D14: =CALCULO_VR!F14 -> 45436.681 | E14: =CALCULO_VR!G14 -> 45448.681 | F14: =CALCULO_VR!I14 -> 46440.22 | G14: =CALCULO_VR!E14 -> 1 | H14: =G14 -> 1 | I14: TO 2a | J14: =CALCULO_VR!J14 -> 10 | Q14: =CALCULO_VR!R14 -> 25.636785
A15: =CALCULO_VR!A15 -> 3439684 | B15: =CALCULO_VR!B15 -> MLPA | C15: PARANA | D15: =CALCULO_VR!F15 -> 45303.609 | E15: =CALCULO_VR!G15 -> 45316.609 | F15: =CALCULO_VR!I15 -> 46440.22 | G15: =CALCULO_VR!E15 -> 1 | H15: =G15 -> 1 | I15: TO 2a | J15: =CALCULO_VR!J15 -> 10 | Q15: =CALCULO_VR!R15 -> 46.826919
... A453: =CALCULO_VR!A453 -> 3441258 | B453: =CALCULO_VR!B453 -> MLPA | C453: PARANA | D453: =CALCULO_VR!F453 -> 45383 | E453: =CALCULO_VR!G453 -> 45398 | F453: =CALCULO_VR!I453 -> 46440.22 | G453: =CALCULO_VR!E453 -> 1 | H453: =G453 -> 1 | I453: TO 2a | J453: =CALCULO_VR!J453 -> 10 | Q453: =CALCULO_VR!R453 -> 25.418536
A454: 3508155 | B454: MLPA | C454: Paranã | D454: 45532 | E454: 45545 | F454: 42589.11 | G454: 1 | H454: 1 | I454: TO 3a | J454: 10 | Q454: 31.770305
A455: 3509559 | B455: MLPA | C455: Paranã | D455: 45532 | E455: 45547 | F455: 42589.11 | G455: 1 | H455: 1 | I455: TO 3a | J455: 10 | Q455: 31.612365
A456: 3485572 | B456: MLPA | C456: Paranã | D456: 45514 | E456: 45530 | F456: 42589.11 | G456: 1 | H456: 1 | I456: TO 3a | J456: 10 | Q456: 35.238325
A457: 3508196 | B457: MLPA | C457: Paranã | D457: 45536 | E457: 45547 | F457: 42589.11 | G457: 1 | H457: 1 | I457: TO 3a | J457: 10 | Q457: 32.937436
A458: 3508194 | B458: MLPA | C458: Paranã | D458: 45533 | E458: 45547 | F458: 42589.11 | G458: 1 | H458: 1 | I458: TO 3a | J458: 10 | Q458: 32.181668
A459: 3508165 | B459: MLPA | C459: Paranã | D459: 45534 | E459: 45547 | F459: 42589.11 | G459: 1 | H459: 1 | I459: TO 3a | J459: 10 | Q459: 36.239644
A460: 3508162 | B460: MLPA | C460: Paranã | D460: 45532 | E460: 45547 | F460: 42589.11 | G460: 1 | H460: 1 | I460: TO 3a | J460: 10 | Q460: 33.554735
A461: 3507782 | B461: MLPA | C461: Paranã | D461: 45531 | E461: 45547 | F461: 42589.11 | G461: 1 | H461: 1 | I461: TO 3a | J461: 10 | Q461: 35.005131
A462: 3507784 | B462: MLPA | C462: Paranã | D462: 45536 | E462: 45547 | F462: 42589.11 | G462: 1 | H462: 1 | I462: TO 3a | J462: 10 | Q462: 38.828917
A463: 3507785 | B463: MLPA | C463: Paranã | D463: 45533 | E463: 45547 | F463: 42589.11 | G463: 1 | H463: 1 | I463: TO 3a | J463: 10 | Q463: 39.36203
A464: 3507827 | B464: MLPA | C464: Paranã | D464: 45534 | E464: 45547 | F464: 42589.11 | G464: 1 | H464: 1 | I464: TO 3a | J464: 10 | Q464: 34.408517
A465: 3507830 | B465: MLPA | C465: Paranã | D465: 45532 | E465: 45547 | F465: 42589.11 | G465: 1 | H465: 1 | I465: TO 3a | J465: 10 | Q465: 35.65176
... A903: 3512763 | B903: MLPA | C903: Rio Sono | D903: 45592.621 | E903: 45607.621 | F903: 42589.11 | G903: 1 | H903: 1 | I903: TO 3a | J903: 13 | Q903: 63.268979

Sheet Planilha3
A1: ODI | B1: Projeto | C1: Municipio | D1: Localidade | E1: Data_Inicio | F1: Data_Fim | G1: Data_Recebimento | H1: Custo_ODI | I1: Tipo_Sist | J1: Quant_Cons | K1: Quant_Kits | L1: Quant_SIGFI | M1: Quant_MIGDI | N1: Quant_Poste | O1: Quant_Rede | P1: Quant_Padrao | Q1: Lote | R1: PAOC | S1: Quant_Paineis | T1: Potencia_Total | U1: Disp_45 | V1: Disp_80 | W1: Disp_160 | X1: Disp_D | Y1: Disp_E
A2: 402301057 | B2: MLPA | C2: PARANÃ | D2: FAZENDA VITORIA | E2: 45436.387 | F2: 45447.387 | G2: 45916 | H2: 45200.38 | I2: SIGFI | J2: 1 | K2: 1 | L2: 1 | M2: 0 | N2: 0 | O2: 0 | P2: 0 | Q2: 0 | R2: 1 | S2: 2 | T2: 0.9 | U2: 0 | V2: 1 | W2: 0 | X2: 0 | Y2: 0
A3: 402301073 | B3: MLPA | C3: PARANÃ | D3: FAZENDA BOA VISTA | E3: 45445.697 | F3: 45457.697 | G3: 45916 | H3: 45200.37 | I3: SIGFI | J3: 1 | K3: 1 | L3: 1 | M3: 0 | N3: 0 | O3: 0 | P3: 0 | Q3: 0 | R3: 1 | S3: 2 | T3: 0.9 | U3: 0 | V3: 1 | W3: 0 | X3: 0 | Y3: 0
A4: 402301111 | B4: MLPA | C4: PARANÃ | D4: FAZENDA BOA VISTA | E4: 45447.663 | F4: 45460.663 | G4: 45916 | H4: 45200.38 | I4: SIGFI | J4: 1 | K4: 1 | L4: 1 | M4: 0 | N4: 0 | O4: 0 | P4: 0 | Q4: 0 | R4: 1 | S4: 2 | T4: 0.9 | U4: 0 | V4: 1 | W4: 0 | X4: 0 | Y4: 0
A5: 402301015 | B5: MLPA | C5: PARANÃ | D5: FAZENDA SAO FRANCISCO | E5: 45299.634 | F5: 45314.634 | G5: 45916 | H5: 44601.1 | I5: SIGFI | J5: 1 | K5: 1 | L5: 1 | M5: 0 | N5: 0 | O5: 0 | P5: 0 | Q5: 0 | R5: 1 | S5: 2 | T5: 0.9 | U5: 0 | V5: 1 | W5: 0 | X5: 0 | Y5: 0
A6: 402301013 | B6: MLPA | C6: PARANÃ | D6: FAZENDA SANTA RITA | E6: 45298.603 | F6: 45314.603 | G6: 45916 | H6: 45005.57 | I6: SIGFI | J6: 1 | K6: 1 | L6: 1 | M6: 0 | N6: 0 | O6: 0 | P6: 0 | Q6: 0 | R6: 1 | S6: 2 | T6: 0.9 | U6: 0 | V6: 1 | W6: 0 | X6: 0 | Y6: 0
A7: 402301012 | B7: MLPA | C7: PARANÃ | D7: FAZENDA JERUSALÉM | E7: 45303.598 | F7: 45314.598 | G7: 45916 | H7: 45005.56 | I7: SIGFI | J7: 1 | K7: 1 | L7: 1 | M7: 0 | N7: 0 | O7: 0 | P7: 0 | Q7: 0 | R7: 1 | S7: 2 | T7: 0.9 | U7: 0 | V7: 1 | W7: 0 | X7: 0 | Y7: 0
A8: 402301072 | B8: MLPA | C8: PARANÃ | D8: FAZENDA BOA VISTA | E8: 45445.663 | F8: 45457.663 | G8: 45916 | H8: 45200.38 | I8: SIGFI | J8: 1 | K8: 1 | L8: 1 | M8: 0 | N8: 0 | O8: 0 | P8: 0 | Q8: 0 | R8: 1 | S8: 2 | T8: 0.9 | U8: 0 | V8: 1 | W8: 0 | X8: 0 | Y8: 0
A9: 402301056 | B9: MLPA | C9: PARANÃ | D9: SITIO SOM DO BERRANTE | E9: 45443.454 | F9: 45456.454 | G9: 45916 | H9: 45200.37 | I9: SIGFI | J9: 1 | K9: 1 | L9: 1 | M9: 0 | N9: 0 | O9: 0 | P9: 0 | Q9: 0 | R9: 1 | S9: 2 | T9: 0.9 | U9: 0 | V9: 1 | W9: 0 | X9: 0 | Y9: 0
A10: 402301070 | B10: MLPA | C10: PARANÃ | D10: FAZENDA AMAZONAS | E10: 45442.638 | F10: 45457.638 | G10: 45916 | H10: 45200.38 | I10: SIGFI | J10: 1 | K10: 1 | L10: 1 | M10: 0 | N10: 0 | O10: 0 | P10: 0 | Q10: 0 | R10: 1 | S10: 2 | T10: 0.9 | U10: 0 | V10: 1 | W10: 0 | X10: 0 | Y10: 0
A11: 402301017 | B11: MLPA | C11: PARANÃ | D11: FAZENDA SANTA LUZIA | E11: 45305.616 | F11: 45316.616 | G11: 45916 | H11: 45005.57 | I11: SIGFI | J11: 1 | K11: 1 | L11: 1 | M11: 0 | N11: 0 | O11: 0 | P11: 0 | Q11: 0 | R11: 1 | S11: 2 | T11: 0.9 | U11: 0 | V11: 1 | W11: 0 | X11: 0 | Y11: 0
A12: 402301069 | B12: MLPA | C12: PARANÃ | D12: FAZENDA TREVO DA CHAPADA | E12: 45436.681 | F12: 45448.681 | G12: 45916 | H12: 45200.37 | I12: SIGFI | J12: 1 | K12: 1 | L12: 1 | M12: 0 | N12: 0 | O12: 0 | P12: 0 | Q12: 0 | R12: 1 | S12: 2 | T12: 0.9 | U12: 0 | V12: 1 | W12: 0 | X12: 0 | Y12: 0
A13: 402301016 | B13: MLPA | C13: PARANÃ | D13: SÍTIO SOM DO BERRANTE | E13: 45303.609 | F13: 45316.609 | G13: 45916 | H13: 45005.56 | I13: SIGFI | J13: 1 | K13: 1 | L13: 1 | M13: 0 | N13: 0 | O13: 0 | P13: 0 | Q13: 0 | R13: 1 | S13: 2 | T13: 0.9 | U13: 0 | V13: 1 | W13: 0 | X13: 0 | Y13: 0
... A451: 402301121 | B451: MLPA | C451: PARANÃ | D451: FAZENDA RIACHO FUNDO | E451: 45383 | F451: 45398 | G451: 45922 | H451: 45225.43 | I451: SIGFI | J451: 1 | K451: 1 | L451: 1 | M451: 0 | N451: 0 | O451: 0 | P451: 0 | Q451: 0 | R451: 2 | S451: 2 | T451: 0.9 | U451: 0 | V451: 1 | W451: 0 | X451: 0 | Y451: 0

Sheet Planilha1
A1: UF | B1: COD. UF | C1: COD. MUNIC | D1: CD_GEOCODM | E1: NOME DO MUNICÍPIO | F1: POPULAÇÃO ESTIMADA | G1: LAT | H1: LONG
A2: RR | B2: 14 | C2: 00027 | D2: 1400027 | E2: Amajari | F2: 13561 | G2: 3.652118 | H2: -61.42059
A3: RR | B3: 14 | C3: 00050 | D3: 1400050 | E3: Alto Alegre | F3: 15249 | G3: 2.993823 | H3: -61.314022
A4: RR | B4: 14 | C4: 00100 | D4: 1400100 | E4: Boa Vista | F4: 436591 | G4: 2.816682 | H4: -60.670533
A5: RR | B5: 14 | C5: 00159 | D5: 1400159 | E5: Bonfim | F5: 12701 | G5: 3.350289 | H5: -59.878007
A6: RR | B6: 14 | C6: 00175 | D6: 1400175 | E6: Cantá | F6: 19257 | G6: 2.607666 | H6: -60.602063
A7: RR | B7: 14 | C7: 00209 | D7: 1400209 | E7: Caracaraí | F7: 22635 | G7: 1.803871 | H7: -61.149177
A8: RR | B8: 14 | C8: 00233 | D8: 1400233 | E8: Caroebe | F8: 10595 | G8: 0.872675 | H8: -59.69481
A9: RR | B9: 14 | C9: 00282 | D9: 1400282 | E9: Iracema | F9: 12637 | G9: 2.168215 | H9: -61.052259
A10: RR | B10: 14 | C10: 00308 | D10: 1400308 | E10: Mucajaí | F10: 18482 | G10: 2.479772 | H10: -60.911519
A11: RR | B11: 14 | C11: 00407 | D11: 1400407 | E11: Normandia | F11: 11772 | G11: 3.882978 | H11: -59.635206
A12: RR | B12: 14 | C12: 00456 | D12: 1400456 | E12: Pacaraima | F12: 20108 | G12: 4.475259 | H12: -61.147306
A13: RR | B13: 14 | C13: 00472 | D13: 1400472 | E13: Rorainópolis | F13: 31387 | G13: 0.937195 | H13: -60.42506
... A16: RR | B16: 14 | C16: 00704 | D16: 1400704 | E16: Uiramutã | F16: 11014 | G16: 4.58544 | H16: -60.195716

Sheet Planilha6
A1: GEOCODIGO_MUNICIPIO | B1: NOME_MUNICIPIO | C1: LATITUDE | D1: LONGITUDE
A2: 1100015 | B2: ALTA FLORESTA D'OESTE | C2: -11.93554 | D2: -61.999824
A3: 1100023 | B3: ARIQUEMES | C3: -9.9084629 | D3: -63.033269
A4: 1100031 | B4: CABIXI | C4: -13.499763 | D4: -60.544314
A5: 1100049 | B5: CACOAL | C5: -11.433865 | D5: -61.442944
A6: 1100056 | B6: CEREJEIRAS | C6: -13.195033 | D6: -60.818426
A7: 1100064 | B7: COLORADO DO OESTE | C7: -13.130564 | D7: -60.555067
A8: 1100072 | B8: CORUMBIARA | C8: -12.99752 | D8: -60.948701
A9: 1100080 | B9: COSTA MARQUES | C9: -12.436014 | D9: -64.231654
A10: 1100098 | B10: ESPIGAO D'OESTE | C10: -11.528555 | D10: -61.020173
A11: 1100106 | B11: GUAJARA-MIRIM | C11: -10.773884 | D11: -65.323952
A12: 1100114 | B12: JARU | C12: -10.435949 | D12: -62.476231
A13: 1100122 | B13: JI-PARANA | C13: -10.882051 | D13: -61.945095
... A5566: 5300108 | B5566: BRASILIA | C5566: -15.794087 | D5566: -47.887905

Sheet Grupo
B1: MUNICÍPIO | C1: Grupo | D1: lat | E1: long | F1: SIGFI | G1: Custo
A2: 1700400 | B2: ALMAS | C2: 1 | D2: -11.574523 | E2: -47.174172 | F2: 45 | G2: 39252.62
A3: 1702208 | B3: ARAGUATINS | C3: 2 | D3: -5.6505865 | E3: -48.123507 | F3: 80 | G3: 46440.22
A4: 1702406 | B4: ARRAIAS | C4: 3 | D4: -12.93442 | E4: -46.946107 | F4: 160 | G4: 79888.47
A5: 1703826 | B5: CACHOEIRINHA | C5: 4 | D5: -6.1132416 | E5: -47.914198
A6: 1704105 | B6: CENTENÁRIO | C6: 5 | D6: -8.9584636 | E6: -47.338399
A7: 1708205 | B7: FORMOSO DO ARAGUAIA | C7: 6 | D7: -11.805142 | E7: -49.52686
A8: 1711506 | B8: JAU DO TOCANTINS | C8: 7 | D8: -12.652926 | E8: -48.594608
A9: 1712405 | B9: LIZARDA | C9: 8 | D9: -9.5945703 | E9: -46.675165
A10: 1721000 | B10: PALMAS | C10: 9 | D10: -10.163253 | E10: -48.351044
A11: 1716208 | B11: PARANÃ | C11: 10 | D11: -12.620481 | E11: -47.884084
A12: 1717800 | B12: PONTE ALTA DO BOM JESUS | C12: 11 | D12: -12.087813 | E12: -46.469587
A13: 1717909 | B13: PONTE ALTA DO TOCANTINS | C13: 12 | D13: -10.740673 | E13: -47.54118
A14: 1718758 | B14: RIO SONO | C14: 13 | D14: -9.3477893 | E14: -47.899942
A15: 1720101 | B15: SÃO BENTO DO TOCANTINS | C15: 14 | D15: -6.0449993 | E15: -47.919392
A16: 1721208 | B16: TOCANTINÓPOLIS | C16: 15 | D16: -6.3256344 | E16: -47.427413

Sheet Planilha5
A1: 1 | B1: 2 | C1: 3 | D1: 4 | E1: 5 | F1: 6 | G1: 7 | H1: 8 | I1: 9 | J1: 10 | K1: 11 | L1: 12 | M1: 13 | N1: 14 | O1: 15
A2: 1700251 | B2: Abreulândia | C2: abreulandia | E2: -962101 | F2: -491518 | G2: 337 | H2: 63 | I2: America/Sao_Paulo | J2: 17 | K2: TO | L2: Tocantins | M2: tocantins | N2: Norte | O2: norte
A3: 1700301 | B3: Aguiarnópolis | C3: aguiarnopolis | E3: -655409 | F3: -474702 | G3: 72 | H3: 63 | I3: America/Sao_Paulo | J3: 17 | K3: TO | L3: Tocantins | M3: tocantins | N3: Norte | O3: norte
A4: 1700350 | B4: Aliança do Tocantins | C4: alianca-do-tocantins | E4: -113056 | F4: -489361 | G4: 9441 | H4: 63 | I4: America/Sao_Paulo | J4: 17 | K4: TO | L4: Tocantins | M4: tocantins | N4: Norte | O4: norte
A5: 1700400 | B5: Almas | C5: almas | E5: -115706 | F5: -471792 | G5: 9207 | H5: 63 | I5: America/Sao_Paulo | J5: 17 | K5: TO | L5: Tocantins | M5: tocantins | N5: Norte | O5: norte
A6: 1700707 | B6: Alvorada | C6: alvorada | E6: -124785 | F6: -491249 | G6: 9213 | H6: 63 | I6: America/Sao_Paulo | J6: 17 | K6: TO | L6: Tocantins | M6: tocantins | N6: Norte | O6: norte
A7: 1701002 | B7: Ananás | C7: ananas | E7: -636437 | F7: -480735 | G7: 9219 | H7: 63 | I7: America/Sao_Paulo | J7: 17 | K7: TO | L7: Tocantins | M7: tocantins | N7: Norte | O7: norte
A8: 1701051 | B8: Angico | C8: angico | E8: -639179 | F8: -478611 | G8: 165 | H8: 63 | I8: America/Sao_Paulo | J8: 17 | K8: TO | L8: Tocantins | M8: tocantins | N8: Norte | O8: norte
A9: 1701101 | B9: Aparecida do Rio Negro | C9: aparecida-do-rio-negro | E9: -994139 | F9: -479638 | G9: 9713 | H9: 63 | I9: America/Sao_Paulo | J9: 17 | K9: TO | L9: Tocantins | M9: tocantins | N9: Norte | O9: norte
A10: 1701309 | B10: Aragominas | C10: aragominas | E10: -716005 | F10: -485291 | G10: 167 | H10: 63 | I10: America/Sao_Paulo | J10: 17 | K10: TO | L10: Tocantins | M10: tocantins | N10: Norte | O10: norte
A11: 1701903 | B11: Araguacema | C11: araguacema | E11: -880755 | F11: -495569 | G11: 9237 | H11: 63 | I11: America/Sao_Paulo | J11: 17 | K11: TO | L11: Tocantins | M11: tocantins | N11: Norte | O11: norte
A12: 1702158 | B12: Araguanã | C12: araguana | E12: -658225 | F12: -486395 | G12: 169 | H12: 63 | I12: America/Sao_Paulo | J12: 17 | K12: TO | L12: Tocantins | M12: tocantins | N12: Norte | O12: norte
A13: 1702208 | B13: Araguatins | C13: araguatins | E13: -564659 | F13: -481232 | G13: 9243 | H13: 63 | I13: America/Sao_Paulo | J13: 17 | K13: TO | L13: Tocantins | M13: tocantins | N13: Norte | O13: norte
... A60: 1709500 | B60: Gurupi | C60: gurupi | E60: -117279 | F60: -49068 | G60: 9385 | H60: 63 | I60: America/Sao_Paulo | J60: 17 | K60: TO | L60: Tocantins | M60: tocantins | N60: Norte | O60: norte
A61: 1709807 | B61: Ipueiras | C61: ipueiras | E61: -112329 | F61: -48.46 | G61: 84 | H61: 63 | I61: America/Sao_Paulo | J61: 17 | K61: TO | L61: Tocantins | M61: tocantins | N61: Norte | O61: norte
A62: 1710508 | B62: Itacajá | C62: itacaja | E62: -839293 | F62: -477726 | G62: 9405 | H62: 63 | I62: America/Sao_Paulo | J62: 17 | K62: TO | L62: Tocantins | M62: tocantins | N62: Norte | O62: norte
A63: 1710706 | B63: Itaguatins | C63: itaguatins | E63: -577267 | F63: -474864 | G63: 9409 | H63: 63 | I63: America/Sao_Paulo | J63: 17 | K63: TO | L63: Tocantins | M63: tocantins | N63: Norte | O63: norte
A64: 1710904 | B64: Itapiratins | C64: itapiratins | E64: -837982 | F64: -481072 | G64: 347 | H64: 63 | I64: America/Sao_Paulo | J64: 17 | K64: TO | L64: Tocantins | M64: tocantins | N64: Norte | O64: norte
A65: 1711100 | B65: Itaporã do Tocantins | C65: itapora-do-tocantins | E65: -857172 | F65: -486895 | G65: 9417 | H65: 63 | I65: America/Sao_Paulo | J65: 17 | K65: TO | L65: Tocantins | M65: tocantins | N65: Norte | O65: norte
A66: 1711506 | B66: Jaú do Tocantins | C66: JAU DO TOCANTINS | E66: -126509 | F66: -48589 | G66: 329 | H66: 63 | I66: America/Sao_Paulo | J66: 17 | K66: TO | L66: Tocantins | M66: tocantins | N66: Norte | O66: norte
A67: 1711803 | B67: Juarina | C67: juarina | E67: -811951 | F67: -490643 | G67: 349 | H67: 63 | I67: America/Sao_Paulo | J67: 17 | K67: TO | L67: Tocantins | M67: tocantins | N67: Norte | O67: norte
A68: 1711902 | B68: Lagoa da Confusão | C68: lagoa-da-confusao | E68: -107906 | F68: -496199 | G68: 367 | H68: 63 | I68: America/Sao_Paulo | J68: 17 | K68: TO | L68: Tocantins | M68: tocantins | N68: Norte | O68: norte
A69: 1711951 | B69: Lagoa do Tocantins | C69: lagoa-do-tocantins | E69: -10368 | F69: -47538 | G69: 353 | H69: 63 | I69: America/Sao_Paulo | J69: 17 | K69: TO | L69: Tocantins | M69: tocantins | N69: Norte | O69: norte
A70: 1712009 | B70: Lajeado | C70: lajeado | E70: -974996 | F70: -483565 | G70: 351 | H70: 63 | I70: America/Sao_Paulo | J70: 17 | K70: TO | L70: Tocantins | M70: tocantins | N70: Norte | O70: norte
A71: 1712157 | B71: Lavandeira | C71: lavandeira | E71: -127847 | F71: -465099 | G71: 86 | H71: 63 | I71: America/Sao_Paulo | J71: 17 | K71: TO | L71: Tocantins | M71: tocantins | N71: Norte | O71: norte
A72: 1712405 | B72: Lizarda | C72: lizarda | E72: -959002 | F72: -466738 | G72: 9569 | H72: 63 | I72: America/Sao_Paulo | J72: 17 | K72: TO | L72: Tocantins | M72: tocantins | N72: Norte | O72: norte
A73: 1712454 | B73: Luzinópolis | C73: luzinopolis | E73: -617794 | F73: -478582 | G73: 88 | H73: 63 | I73: America/Sao_Paulo | J73: 17 | K73: TO | L73: Tocantins | M73: tocantins | N73: Norte | O73: norte
... A89: 1715507 | B89: Oliveira de Fátima | C89: oliveira-de-fatima | E89: -10707 | F89: -489086 | G89: 92 | H89: 63 | I89: America/Sao_Paulo | J89: 17 | K89: TO | L89: Tocantins | M89: tocantins | N89: Norte | O89: norte
A90: 1721000 | B90: Palmas | C90: palmas | D90: true | E90: -10.24 | F90: -483558 | G90: 9733 | H90: 63 | I90: America/Sao_Paulo | J90: 17 | K90: TO | L90: Tocantins | M90: tocantins | N90: Norte | O90: norte
A91: 1715705 | B91: Palmeirante | C91: palmeirante | E91: -784786 | F91: -479242 | G91: 189 | H91: 63 | I91: America/Sao_Paulo | J91: 17 | K91: TO | L91: Tocantins | M91: tocantins | N91: Norte | O91: norte
A92: 1713809 | B92: Palmeiras do Tocantins | C92: palmeiras-do-tocantins | E92: -661658 | F92: -475464 | G92: 185 | H92: 63 | I92: America/Sao_Paulo | J92: 17 | K92: TO | L92: Tocantins | M92: tocantins | N92: Norte | O92: norte
A93: 1715754 | B93: Palmeirópolis | C93: palmeiropolis | E93: -130447 | F93: -484026 | G93: 9649 | H93: 63 | I93: America/Sao_Paulo | J93: 17 | K93: TO | L93: Tocantins | M93: tocantins | N93: Norte | O93: norte
A94: 1716208 | B94: Paranã | C94: parana | E94: -126167 | F94: -478734 | G94: 9521 | H94: 63 | I94: America/Sao_Paulo | J94: 17 | K94: TO | L94: Tocantins | M94: tocantins | N94: Norte | O94: norte
A95: 1716109 | B95: Paraíso do Tocantins | C95: paraiso-do-tocantins | E95: -10175 | F95: -488823 | G95: 9519 | H95: 63 | I95: America/Sao_Paulo | J95: 17 | K95: TO | L95: Tocantins | M95: tocantins | N95: Norte | O95: norte
A96: 1716307 | B96: Pau D'Arco | C96: pau-darco | E96: -753919 | F96: -49367 | G96: 191 | H96: 63 | I96: America/Sao_Paulo | J96: 17 | K96: TO | L96: Tocantins | M96: tocantins | N96: Norte | O96: norte
A97: 1716505 | B97: Pedro Afonso | C97: pedro-afonso | E97: -897034 | F97: -481729 | G97: 9525 | H97: 63 | I97: America/Sao_Paulo | J97: 17 | K97: TO | L97: Tocantins | M97: tocantins | N97: Norte | O97: norte
A98: 1716604 | B98: Peixe | C98: peixe | E98: -120254 | F98: -485395 | G98: 9527 | H98: 63 | I98: America/Sao_Paulo | J98: 17 | K98: TO | L98: Tocantins | M98: tocantins | N98: Norte | O98: norte
A99: 1716653 | B99: Pequizeiro | C99: pequizeiro | E99: -85932 | F99: -489327 | G99: 9705 | H99: 63 | I99: America/Sao_Paulo | J99: 17 | K99: TO | L99: Tocantins | M99: tocantins | N99: Norte | O99: norte
A100: 1717008 | B100: Pindorama do Tocantins | C100: pindorama-do-tocantins | E100: -111311 | F100: -475726 | G100: 9537 | H100: 63 | I100: America/Sao_Paulo | J100: 17 | K100: TO | L100: Tocantins | M100: tocantins | N100: Norte | O100: norte
A101: 1717206 | B101: Piraquê | C101: piraque | E101: -677302 | F101: -482958 | G101: 355 | H101: 63 | I101: America/Sao_Paulo | J101: 17 | K101: TO | L101: Tocantins | M101: tocantins | N101: Norte | O101: norte
...

Sheet Planilha2
A1: MUNICÍPIO
A2: ALMAS
A3: ARAGUATINS
A4: ARRAIAS
A5: CACHOEIRINHA
