Workbook

Sheet PENDÊNCIAS
B2: PENDÊNCIAS
C5: Aguardar aprovação do Código de Ética da ENBPar e colocar em uma aba. Será necessário repassar o Código de Ética ao Credenciado. É item de avalição do trabalho pelo IMR (item 1.3).
C21: Criar procedimento junto aos Credenciados para certificar-se de todos os itens referentes à avaliação prevista no IMR: quantidade, habilitações e experiência dos profissionais; definição de meios de comunicação; repasse das exigências contratuais e regulamentos;

Sheet Relatório de Fiscalização
B2: Preencher Apenas o Campo Que Está em Vermelho
B4: DIRETORIA DE GESTÃO DE PROGRAMAS DE GOVERNO
B6: RELATÓRIO DE FISCALIZAÇÃO DE CONTRATO DE APOIO ÀS INSPEÇÕES FÍSICAS
B8: 1. IDENTIFICAÇÃO
B10: 1.1. IDENTIFICAÇÃO TERMO DE CREDENCIAMENTO E EMPRESA CREDENCIADA
C13: CONTRATO: | E13: =VLOOKUP(E21,'Relação Empresas-Fiscais'!B3:I15,4,0) -> TERMO DE CREDENCIAMENTO Nº 12/2025
C15: OBJETO: | E15: Prestação de serviços de apoio técnico especializado às atividades de levantamento de campo do Programa Luz para Todos - LPT.
C17: PROCESSO SEI: | E17: =VLOOKUP(E21,'Relação Empresas-Fiscais'!B3:I15,3,0) -> 48110.000954/2025-68
C19: DOTAÇÃO ORÇAMENTÁRIA: | F19: =VLOOKUP(E21,'Relação Empresas-Fiscais'!B3:I15,5,0) -> 2.205.900.00 - Outros Serviços de Terceiros
C21: No. CADASTRO: | E21: 7 | G21: CNPJ: | H21: =VLOOKUP(E21,'Empresas Credenciadas'!B3:G16,3,0) -> 31.759.110/0001-65
C23: NOME EMPRESA:
C24: =VLOOKUP(E21,'Empresas Credenciadas'!B3:G16,2,0) -> AR Construções, Locadora e Serviços Ltda
C26: ENDEREÇO EMPRESA:
C27: =VLOOKUP(E21,'Empresas Credenciadas'!B3:G16,4,0) -> Rua Farmaceutico Jose Rodrigues, nº 802, Centro, Uruburetama, CE, CEP: 62.650-000
C30: CONTATO EMPRESA:
C31: =VLOOKUP(E21,'Empresas Credenciadas'!B3:G16,5,0) -> Alexandre Rikchelmy Vaz Barroso | J31: =VLOOKUP(E21,'Empresas Credenciadas'!B3:G16,6,0) -> (85) 99814-2427
B34: 1.2. IDENTIFICAÇÃO DO FISCAL DO TERMO DE CREDENCIAMENTO
C37: MATRÍCULA: | E37: 100171
C39: NOME:
C40: =VLOOKUP(E37,'Fiscais de Contrato e Gerentes'!B3:H12,2,0) -> EDNILSON COPPINI CASTANHEIRA
C42: FUNÇÃO:
C43: =VLOOKUP(E37,'Fiscais de Contrato e Gerentes'!B3:H12,3,0) -> ASSESSOR(A) II DE PROGRAMA
C45: ATO DE DESIGNAÇÃO DO FISCAL
C46: =VLOOKUP(E21,'Relação Empresas-Fiscais'!B3:J11,8,0) -> 0
B49: 2. ATIVIDADE DE ACOMPANHAMENTO E DA FISCALIZAÇÃO DO CONTRATO
C52: PERÍODO APURADO
C53: DATA DE INÍCIO: | H53: DATA TÉRMINO:
C56: 2.1. RELAÇÃO DE OCORRÊNCIAS E VERIFICAÇÕES | J56: SIM | K56: NÃO
C57: 01 - Cumpriu as Obrigações Contratuais? | J57: X | K57: X
C58: 02 - Obedeceu aos Prazos Estabelecidos? | J58: X | K58: X
C59: 03 - Entregou os Documentos a Que Estava Obrigado? | J59: X | K59: X
C60: 04 - Disponibilizou Profissionais e Materiais Qualificados? | J60: X | K60: X
C61: 05 - Prestou o Serviço com a Qualidade Esperada? | J61: X | K61: X
C62: 06 - Notificação Extrajudicial? | J62: X | K62: X
C63: 07 - Suspensão do Contrato? | J63: X | K63: X
C64: 08 - Necessidade de Rescisão? | J64: X | K64: X
C65: 09 - Alterações Contratuais? | J65: X | K65: X
C66: 10 - Necessidade de Reajuste ou Correção dos Valores? | J66: X | K66: X
C68: 2.2. DESCRIÇÃO DAS ATIVIDADES:
B91: 3. CONCLUSÕES

Sheet Ordem de Serviço Emissão
B2: Preencher Apenas o Campo Que Está em Vermelho
B4: SOLICITAÇÃO DE ORDEM DE SERVIÇO PARA APOIO ÀS INSPEÇÕES FÍSICAS
B6: SOLICITANTE
B9: Matrícula: | D9: Nome: | N9: Telefone/Ramal:
B10: 200000 | D10: =VLOOKUP(B10,'Fiscais de Contrato e Gerentes'!B3:H12,2,0) -> FISCAL DE CONTRATO | N10: =VLOOKUP(B10,'Fiscais de Contrato e Gerentes'!B3:H12,4,0) -> 0
D12: Função: | N12: CPF:
D13: =VLOOKUP(B10,'Fiscais de Contrato e Gerentes'!B3:H12,3,0) -> 0 | N13: =VLOOKUP(B10,'Fiscais de Contrato e Gerentes'!B3:H12,5,0) -> 0
B16: EMPRESA CREDENCIADA
B19: No. Cadastro: | D19: Nome: | N19: CNPJ:
B20: 0 | D20: =VLOOKUP(B20,'Empresas Credenciadas'!B3:G16,2,0) -> ENBPar | N20: =VLOOKUP(B20,'Empresas Credenciadas'!B3:G16,3,0) -> 0
D22: Endereço: | N22: Telefone/Ramal:
D23: =VLOOKUP(B20,'Empresas Credenciadas'!B3:G16,4,0) -> 0 | N23: =VLOOKUP(B20,'Empresas Credenciadas'!B3:G16,6,0) -> 0
D26: Contato:
D27: =VLOOKUP(B20,'Empresas Credenciadas'!B3:G16,5,0) -> 0 | K27: =VLOOKUP(B20,'Empresas Credenciadas'!B3:G16,6,0) -> 0
B30: DESCRIÇÃO DA ATIVIDADE
B32: SOBRE A ATIVIDADE: Equatorial-PA 4ª Tranche - ECM 013-A-2023 - 27 a 31-07-2026 Estado (UF); Concessionária; Contrato / Tranche; Número de Equipes; Período previsto para inspeções; Informações dos locais de inspeção (UC, nome cliente, ODI, Município, Coordenadas geográficas, data prevista para inspeção);
B43: PARÂMETROS PREVISTOS DE DIMENSIONAMENTO DA INSPEÇÃO
C46: Data de Início: | E46: 46230 | G46: =WEEKDAY(E46,1) -> 2 | K46: Data de término: | M46: 46234 | O46: =WEEKDAY(M46,1) -> 6
C48: Tipo de obra: | E48: Sistemas de Geração Descentralizada | L48: Obra Com Deslocamento: | O48: SIM
C50: Número Equipes: | E50: ='Composição Equipes Inspeção'!E5 -> 6 | G50: Profissionais Totais | M50: Tempo por Etapa (h)
G51: Engenheiro Eletricista: | K51: =SUM('Composição Equipes Inspeção'!E24,'Composição Equipes Inspeção'!J24,'Composição Equipes Inspeção'!E30,'Composição Equipes Inspeção'!J30,'Composição Equipes Inspeção'!E36,'Composição Equipes Inspeção'!J36,'Composição Equipes Inspeção'!E42,'Composição Equipes Inspeção'!J42,'Composição Equipes Inspeção'!E48,'Composição Equipes Inspeção'!J48) -> 6 | M51: Planejamento: | O51: ='Custos Inspeções'!E26 -> 4
G52: Engenheiro Generalista: | K52: =SUM('Composição Equipes Inspeção'!E25,'Composição Equipes Inspeção'!J25,'Composição Equipes Inspeção'!E31,'Composição Equipes Inspeção'!J31,'Composição Equipes Inspeção'!E37,'Composição Equipes Inspeção'!J37,'Composição Equipes Inspeção'!E43,'Composição Equipes Inspeção'!J43,'Composição Equipes Inspeção'!E49,'Composição Equipes Inspeção'!J49) -> 0 | M52: Desenvolvimento: | O52: ='Composição Equipes Inspeção'!I9 -> 240
G53: Técnico Eletricista: | K53: ='Composição Equipes Inspeção'!G18 -> 0 | M53: Relatório: | O53: ='Custos Inspeções'!E28 -> 16
M54: Apresentação: | O54: ='Custos Inspeções'!E29 -> 4
B57: PREVISÃO DE CUSTOS (ESTIMATIVA).
C60: PROFISSIONAL | E60: ETAPA | G60: NÚMERO DE PROFISSIONAIS | J60: HORAS TOTAIS ESTIMADAS | L60: CUSTO POR HORA | N60: CUSTO TOTAL
C62: Engenheiro Eletricista e/ou Generalista | E62: Planejamento | G62: 1 | J62: =O51*G62 -> 4 | L62: ='Custos Inspeções'!D19 -> 360 | N62: =J62*L62 -> 1440
E63: Desenvolvimento | G63: ='Composição Equipes Inspeção'!G17 -> 6 | J63: ='Composição Equipes Inspeção'!I17 -> 240 | L63: ='Custos Inspeções'!D17 -> 600 | N63: ='Composição Equipes Inspeção'!J17 -> 144000
E64: Relatório | G64: 1 | J64: =O53*G64 -> 16 | L64: ='Custos Inspeções'!D19 -> 360 | N64: =J64*L64 -> 5760
E65: Apresentação | G65: 1 | J65: =O54*G65 -> 4 | L65: ='Custos Inspeções'!D19 -> 360 | N65: =J65*L65 -> 1440
J66: Subtotal Engenheiro: | N66: =SUM(N62:O65) -> 152640
C67: Técnico | E67: Planejamento | G67: 0 | J67: =O51*G67 -> 0 | L67: ='Custos Inspeções'!D20 -> 273.22 | N67: =J67*L67 -> 0
E68: Desenvolvimento | G68: ='Composição Equipes Inspeção'!G18 -> 0 | J68: ='Composição Equipes Inspeção'!I18 -> 0 | L68: ='Custos Inspeções'!D18 -> 513.22 | N68: ='Composição Equipes Inspeção'!J18 -> 0
E69: Relatório | G69: 0 | J69: =O53*G69 -> 0 | L69: ='Custos Inspeções'!D20 -> 273.22 | N69: =J69*L69 -> 0
J70: Subtotal Técnico Eletricista: | N70: =SUM(N67:O69) -> 0
J71: TOTAL GERAL ESTIMADO: | N71: =N66+N70 -> 152640
B74: RESUMO DAS ATIVIDADES EXECUTADAS PELO CREDENCIADO
B83: CÁLCULO EFETIVO DO DESEMBOLSO
C86: PROFISSIONAL | E86: ETAPA | G86: NÚMERO DE PROFISSIONAIS | J86: HORAS TOTAIS EXECUTADAS | L86: CUSTO POR HORA | N86: CUSTO TOTAL
C88: Engenheiro Eletricista e/ou Generalista | E88: Planejamento | G88: 1 | J88: =O51*G88 -> 4 | L88: ='Custos Inspeções'!D19 -> 360 | N88: =J88*L88 -> 1440
...

Sheet Composição Equipes Inspeção
B2: PREVISÃO DE CUSTOS. ETAPA DE DESENVOLVIMENTO.
B5: NÚMERO TOTAL DE EQUIPES: | E5: 6
B7: PREVISÃO DE CUSTO POR EQUIPE | G7: TOTAIS DA ETAPA DE DESENVOLVIMENTO
B8: EQUIPES | D8: HORAS | E8: CUSTO
B9: EQUIPE 01 | D9: =IF(AND(C23=0,E23=0),0,(E23-C23+1)*8) -> 48 | E9: =(('Custos Inspeções'!$D$17*(E24+E25))+('Custos Inspeções'!$D$18*(E26)))*D9 -> 28800 | G9: HORAS | I9: =SUM(D9:D18) -> 240
B10: EQUIPE 02 | D10: =IF(AND(H23=0,J23=0),0,(J23-H23+1)*8) -> 48 | E10: =(('Custos Inspeções'!$D$17*(J24+J25))+('Custos Inspeções'!$D$18*(J26)))*D10 -> 28800
B11: EQUIPE 03 | D11: =IF(AND(C29=0,E29=0),0,(E29-C29+1)*8) -> 40 | E11: =(('Custos Inspeções'!$D$17*(E30+E31))+('Custos Inspeções'!$D$18*(E32)))*D11 -> 24000 | G11: CUSTO | I11: =SUM(E9:E18) -> 144000
B12: EQUIPE 04 | D12: =IF(AND(H29=0,J29=0),0,(J29-H29+1)*8) -> 48 | E12: =(('Custos Inspeções'!$D$17*(J30+J31))+('Custos Inspeções'!$D$18*(J32)))*D12 -> 28800
B13: EQUIPE 05 | D13: =IF(AND(C35=0,E35=0),0,(E35-C35+1)*8) -> 48 | E13: =(('Custos Inspeções'!$D$17*(E36+E37))+('Custos Inspeções'!$D$18*(E38)))*D13 -> 28800
B14: EQUIPE 06 | D14: =IF(AND(H35=0,J35=0),0,(J35-H35+1)*8) -> 8 | E14: =(('Custos Inspeções'!$D$17*(J36+J37))+('Custos Inspeções'!$D$18*(J38)))*D14 -> 4800
B15: EQUIPE 07 | D15: =IF(AND(C41=0,E41=0),0,(E41-C41+1)*8) -> 0 | E15: =(('Custos Inspeções'!$D$17*(E42+E43))+('Custos Inspeções'!$D$18*(E44)))*D15 -> 0 | G15: DADOS COMPLEMENTARES TOTAIS
B16: EQUIPE 08 | D16: =IF(AND(H41=0,J41=0),0,(J41-H41+1)*8) -> 0 | E16: =(('Custos Inspeções'!$D$17*(J42+J43))+('Custos Inspeções'!$D$18*(J44)))*D16 -> 0 | G16: QUANTID. | H16: PROFISSIONAIS | I16: HORAS | J16: CUSTO
B17: EQUIPE 09 | D17: =IF(AND(C47=0,E47=0),0,(E47-C47+1)*8) -> 0 | E17: =(('Custos Inspeções'!$D$17*(E48+E49))+('Custos Inspeções'!$D$18*(E50)))*D17 -> 0 | G17: =SUM(E24:E25,J24:J25,E30:E31,J30:J31,E36:E37,J36:J37,E42:E43,J42:J43,E48:E49,J48:J49) -> 6 | H17: Engenheiros | I17: =(IF(SUM(E24:E25)>0,IF(AND(C23=0,E23=0),0,(E23-C23+1)),0)+IF(SUM(J24:J25)>0,IF(AND(H23=0,J23=0),0,(J23-H23+1)),0)+IF(SUM(E30:E31)>0,IF(AND(C29=0,E29=0),0,(E29-C29+1)),0)+IF(SUM(J30:J31)>0,IF(AND(H29=0,J29=0),0,(J29-H29+1)),0)+IF(SUM(E36:E37)>0,IF(AND(C35=0,E35=0),0,(E35-C35+1)),0)+IF(SUM(J36:J37)>0,IF(AND(H35=0,J35=0),0,(J35-H35+1)),0)+IF(SUM(E42:E43)>0,IF(AND(C41=0,E41=0),0,(E41-C41+1)),0)+IF(SUM(J42:J43)>0,IF(AND(H41=0,J41=0),0,(J41-H41+1)),0)+IF(SUM(E48:E49)>0,IF(AND(C47=0,E47=0),0,(E47-C47+1)),0)+IF(SUM(J48:J49)>0,IF(AND(H47=0,J47=0),0,(J47-H47+1)),0))*8 -> 240 | J17: =I17*'Custos Inspeções'!D17 -> 144000
B18: EQUIPE 10 | D18: =IF(AND(H47=0,J47=0),0,(J47-H47+1)*8) -> 0 | E18: =(('Custos Inspeções'!$D$17*(J48+J49))+('Custos Inspeções'!$D$18*(J50)))*D18 -> 0 | G18: =SUM(E26,J26,E32,J32,E38,J38,E44,J44,E50,J50) -> 0 | H18: Técnicos | I18: =(IF(E26>0,IF(AND(C23=0,E23=0),0,(E23-C23+1)),0)+IF(J26>0,IF(AND(H23=0,J23=0),0,(J23-H23+1)),0)+IF(E32>0,IF(AND(C29=0,E29=0),0,(E29-C29+1)),0)+IF(J32>0,IF(AND(H29=0,J29=0),0,(J29-H29+1)),0)+IF(E38>0,IF(AND(C35=0,E35=0),0,(E35-C35+1)),0)+IF(J38>0,IF(AND(H35=0,J35=0),0,(J35-H35+1)),0)+IF(E44>0,IF(AND(C41=0,E41=0),0,(E41-C41+1)),0)+IF(J44>0,IF(AND(H41=0,J41=0),0,(J41-H41+1)),0)+IF(E50>0,IF(AND(C47=0,E47=0),0,(E47-C47+1)),0)+IF(J50>0,IF(AND(H47=0,J47=0),0,(J47-H47+1)),0))*8 -> 0 | J18: =I18*'Custos Inspeções'!D18 -> 0
B20: COMPOSIÇÃO DAS EQUIPES
B22: EQUIPE 01: PERÍODO E PROFISSIONAIS | G22: EQUIPE 02: PERÍODO E PROFISSIONAIS
B23: Data de Início: | C23: 46237 | D23: Data de término: | E23: 46242 | G23: Data de Início: | H23: 46237 | I23: Data de término: | J23: 46242
B24: Engenheiro Eletricista: | E24: 1 | G24: Engenheiro Eletricista: | J24: 1
B25: Engenheiro Generalista: | E25: 0 | G25: Engenheiro Generalista: | J25: 0
B26: Técnico Eletricista: | E26: 0 | G26: Técnico Eletricista: | J26: 0
B28: EQUIPE 03: PERÍODO E PROFISSIONAIS | G28: EQUIPE 04: PERÍODO E PROFISSIONAIS
B29: Data de Início: | C29: 46237 | D29: Data de término: | E29: 46241 | G29: Data de Início: | H29: 46237 | I29: Data de término: | J29: 46242
B30: Engenheiro Eletricista: | E30: 1 | G30: Engenheiro Eletricista: | J30: 1
B31: Engenheiro Generalista: | E31: 0 | G31: Engenheiro Generalista: | J31: 0
B32: Técnico Eletricista: | E32: 0 | G32: Técnico Eletricista: | J32: 0
B34: EQUIPE 05: PERÍODO E PROFISSIONAIS | G34: EQUIPE 06: PERÍODO E PROFISSIONAIS
B35: Data de Início: | C35: 46237 | D35: Data de término: | E35: 46242 | G35: Data de Início: | H35: 46237 | I35: Data de término: | J35: 46237
B36: Engenheiro Eletricista: | E36: 1 | G36: Engenheiro Eletricista: | J36: 1
B37: Engenheiro Generalista: | E37: 0 | G37: Engenheiro Generalista: | J37: 0
B38: Técnico Eletricista: | E38: 0 | G38: Técnico Eletricista: | J38: 0
B40: EQUIPE 07: PERÍODO E PROFISSIONAIS | G40: EQUIPE 08: PERÍODO E PROFISSIONAIS
B41: Data de Início: | D41: Data de término: | G41: Data de Início: | I41: Data de término:
B42: Engenheiro Eletricista: | E42: 0 | G42: Engenheiro Eletricista: | J42: 0
B43: Engenheiro Generalista: | E43: 0 | G43: Engenheiro Generalista: | J43: 0
B44: Técnico Eletricista: | E44: 0 | G44: Técnico Eletricista: | J44: 0
B46: EQUIPE 09: PERÍODO E PROFISSIONAIS | G46: EQUIPE 10: PERÍODO E PROFISSIONAIS
B47: Data de Início: | D47: Data de término: | G47: Data de Início: | I47: Data de término:
B48: Engenheiro Eletricista: | E48: 0 | G48: Engenheiro Eletricista: | J48: 0
B49: Engenheiro Generalista: | E49: 0 | G49: Engenheiro Generalista: | J49: 0
B50: Técnico Eletricista: | E50: 0 | G50: Técnico Eletricista: | J50: 0

Sheet IMR
B2: CRITÉRIOS DO INSTRUMENTO DE MEDIÇÃO DE RESULTADO - IMR
B3: ITENS | C3: CRITÉRIOS | D3: GRAVIDADE DA OCORRÊNCIA | E3: NÍVEL DE ATENDIMENTO
B4: CRITÉRIOS NÃO PASSÍVEIS DE CORREÇÃO
B5: 1.1 | C5: A CREDENCIADA contribuiu para o desenvolvimento de uma relação de trabalho respeitosa e de confiança, cooperando com a equipe? | D5: NÍVEL 1 | E5: ATENDE
B6: 1.2 | C6: A CREDENCIADA coordenou os trabalhos da equipe de forma a cumprir com o planejado, dentro dos prazos estabelecidos, durante todas as etapas e atuou para a resolução dos problemas eventuais e/ou fortuitos que surgiram durante os trabalhos? | D6: NÍVEL 3 | E6: ATENDE
B7: 1.3 | C7: A CREDENCIADA cumpriu os preceitos estabelecidos no Código de Ética da ENBPar? | D7: NÍVEL 3 | E7: ATENDE
B8: 1.4 | C8: A CREDENCIADA disponibilizou os recursos humanos e materiais mínimos necessários para execução da demanda e estes foram utilizados nos termos do Edital? | D8: NÍVEL 2 | E8: ATENDE
B9: 1.5 | C9: A CREDENCIADA disponibilizou profissionais qualificados e com o conhecimento técnico adequado para a execução da Demanda, bem como o uso das ferramentas necessárias para sua realização? | D9: NÍVEL 3 | E9: ATENDE
B10: 1.6 | C10: A CREDENCIADA disponibilizou todos os documentos e informações obtidos à ENBPar em formato editável e de forma tempestiva? | D10: NÍVEL 1 | E10: ATENDE
B11: CRITÉRIOS PASSÍVEIS DE CORREÇÃO
B12: 2.1 | C12: O RTE apresentou todas as informações básicas de individualização da DEMANDA previstas no Edital? | D12: NÍVEL 2 | E12: ATENDE
B13: 2.2 | C13: O RTE foi realizado dentro dos procedimentos estabelecidos para realização da DEMANDA? | D13: NÍVEL 3 | E13: ATENDE
B14: 2.3 | C14: O RTE foi formatado de forma adequada? | D14: NÍVEL 1 | E14: ATENDE
B15: 2.4 | C15: O RTE apresentou coerência textual e correta ortografia? | D15: NÍVEL 2 | E15: ATENDE
B16: 2.5 | C16: Os formulários, planilhas, vídeos, fotos, imagens, gráficos, diagramas, tabelas, quadros, foram elaborados, apresentados e disponibilizados com qualidade? | D16: NÍVEL 3 | E16: ATENDE
B17: 2.6 | C17: O RTE apresentou todas as verificações, análises, constatações, recomendações, pontos de melhorias, levantamento completo de dados, os quais foram realizados a contento e estão em conformidade com a normas vigentes do setor elétrico? | D17: NÍVEL 4 | E17: ATENDE
C19: NÍVEL DE GRAVIDADE DO ITEM E PERCENTUAIS DE GLOSA GERAL | D19: NÍVEL 1 | E19: 0.05
D20: NÍVEL 2 | E20: 0.1
D21: NÍVEL 3 | E21: 0.15
D22: NÍVEL 4 | E22: 0.2
C24: NÍVEL DE ATENDIMENTO DO ITEM E PERCENTUAIS DE GLOSA DO ITEM | D24: ATENDE | E24: 0
D25: PARCIALMENTE | E25: 0.5
D26: NÃO ATENDE | E26: 1
C28: PERCENTUAL GERAL DE GLOSA | D28: =(D30*E30)+(D31*E31)+(D32*E32)+(D33*E33)+(D34*E34)+(D35*E35)+(D36*E36)+(D37*E37)+(D38*E38)+(D39*E39)+(D40*E40)+(D41*E41) -> 0
C29: PERCENTUAL DE GLOSA EFETIVO (PERCENTUAL GERAL LIMITADO A 35%) | D29: =IF(D28>0.35,0.35,D28) -> 0
C30: ITEM 1.1 | D30: 0.05 | E30: =IF(E5="ATENDE",0,IF(E5="PARCIALMENTE",0.5,IF(E5="NÃO ATENDE",1,""))) -> 0
C31: ITEM 1.2 | D31: 0.15 | E31: =IF(E6="ATENDE",0,IF(E6="PARCIALMENTE",0.5,IF(E6="NÃO ATENDE",1,""))) -> 0
C32: ITEM 1.3 | D32: 0.15 | E32: =IF(E7="ATENDE",0,IF(E7="PARCIALMENTE",0.5,IF(E7="NÃO ATENDE",1,""))) -> 0
C33: ITEM 1.4 | D33: 0.1 | E33: =IF(E8="ATENDE",0,IF(E8="PARCIALMENTE",0.5,IF(E8="NÃO ATENDE",1,""))) -> 0
C34: ITEM 1.5 | D34: 0.15 | E34: =IF(E9="ATENDE",0,IF(E9="PARCIALMENTE",0.5,IF(E9="NÃO ATENDE",1,""))) -> 0
C35: ITEM 1.6 | D35: 0.05 | E35: =IF(E10="ATENDE",0,IF(E10="PARCIALMENTE",0.5,IF(E10="NÃO ATENDE",1,""))) -> 0
C36: ITEM 2.1 | D36: 0.1 | E36: =IF(E12="ATENDE",0,IF(E12="PARCIALMENTE",0.5,IF(E12="NÃO ATENDE",1,""))) -> 0
C37: ITEM 2.2 | D37: 0.15 | E37: =IF(E13="ATENDE",0,IF(E13="PARCIALMENTE",0.5,IF(E13="NÃO ATENDE",1,""))) -> 0
C38: ITEM 2.3 | D38: 0.05 | E38: =IF(E14="ATENDE",0,IF(E14="PARCIALMENTE",0.5,IF(E14="NÃO ATENDE",1,""))) -> 0
C39: ITEM 2.4 | D39: 0.1 | E39: =IF(E15="ATENDE",0,IF(E15="PARCIALMENTE",0.5,IF(E15="NÃO ATENDE",1,""))) -> 0
C40: ITEM 2.5 | D40: 0.15 | E40: =IF(E16="ATENDE",0,IF(E16="PARCIALMENTE",0.5,IF(E16="NÃO ATENDE",1,""))) -> 0
C41: ITEM 2.6 | D41: 0.2 | E41: =IF(E17="ATENDE",0,IF(E17="PARCIALMENTE",0.5,IF(E17="NÃO ATENDE",1,""))) -> 0

Sheet Custos Inspeções
B2: ÁREA DE CONHECIMENTO | D2: PERFIL PROFISSIONAL | E2: CUSTO R$/HORA SEM DESLOCAMENTO | F2: CUSTO R$/HORA COM DESLOCAMENTO
B3: Extensão de Redes de Distribuição de Energia Elétrica | D3: Eng. Eletricista | E3: 360 | F3: 600
D4: Eletrotécnico | E4: 250 | F4: 593
B5: Sistemas de Geração Descentralizada Com ou Sem Rede Associada | D5: Eng. Generalista | E5: 360 | F5: 600
D6: Técnico | E6: 273.22 | F6: 513.22
B9: LISTA TIPO DE INSPEÇÃO:
B10: Extensão de Redes de Distribuição
B11: Sistemas de Geração Descentralizada
B14: SELEÇÃO AUTOMÁTICA DE CUSTO DE ACORDO COM OS PARÂMETROS PREVITOS NA ORDEM DE SERVIÇO
C16: PERFIL PROFISSIONAL | D16: VALOR DA HORA DE SERVIÇO
B17: ETAPA DE DESENVOLVIMENTO | C17: Engenheiro | D17: {=IF('Ordem de Serviço Emissão'!E48:J48='Custos Inspeções'!B10,IF('Ordem de Serviço Emissão'!O48="NÃO",'Custos Inspeções'!E3,'Custos Inspeções'!F3),IF('Ordem de Serviço Emissão'!E48:J48='Custos Inspeções'!B11,IF('Ordem de Serviço Emissão'!O48="NÃO",'Custos Inspeções'!E5,'Custos Inspeções'!F5),""))} -> 600
C18: Técnico | D18: {=IF('Ordem de Serviço Emissão'!E48:J48='Custos Inspeções'!B10,IF('Ordem de Serviço Emissão'!O48="NÃO",'Custos Inspeções'!E4,'Custos Inspeções'!F4),IF('Ordem de Serviço Emissão'!E48:J48='Custos Inspeções'!B11,IF('Ordem de Serviço Emissão'!O48="NÃO",'Custos Inspeções'!E6,'Custos Inspeções'!F6),""))} -> 513.22
B19: DEMAIS ETAPAS | C19: Engenheiro | D19: {=IF('Ordem de Serviço Emissão'!E48:J48='Custos Inspeções'!B10,'Custos Inspeções'!E3,IF('Ordem de Serviço Emissão'!E48:J48='Custos Inspeções'!B11,'Custos Inspeções'!E5,""))} -> 360
C20: Técnico | D20: {=IF('Ordem de Serviço Emissão'!E48:J48='Custos Inspeções'!B10,'Custos Inspeções'!E4,IF('Ordem de Serviço Emissão'!E48:J48='Custos Inspeções'!B11,'Custos Inspeções'!E6,""))} -> 273.22
B23: SELEÇÃO AUTOMÁTICA DE TEMPO PREVISTO PARA AS ETAPAS DE ACORDO COM OS PARÂMETROS DA ORDEM DE SERVIÇO (h)
B25: ETAPA | C25: EXTENSÃO REDE | D25: GERAÇÃO | E25: AUTOMÁTICO PARA CÁLCULO DE CUSTO
B26: Planejamento | C26: 8 | D26: 4 | E26: {=IF('Ordem de Serviço Emissão'!E48:J48='Custos Inspeções'!B10,8,IF('Ordem de Serviço Emissão'!E48:J48='Custos Inspeções'!B11,4,""))} -> 4
B27: Desenvolvimento | C27: 112 | D27: 56 | E27: {=IF('Ordem de Serviço Emissão'!E48:J48='Custos Inspeções'!B10,112,IF('Ordem de Serviço Emissão'!E48:J48='Custos Inspeções'!B11,56,""))} -> 56
B28: Relatório | C28: 24 | D28: 16 | E28: {=IF('Ordem de Serviço Emissão'!E48:J48='Custos Inspeções'!B10,24,IF('Ordem de Serviço Emissão'!E48:J48='Custos Inspeções'!B11,16,""))} -> 16
B29: Apresentação | C29: 4 | D29: 4 | E29: {=IF('Ordem de Serviço Emissão'!E48:J48='Custos Inspeções'!B10,4,IF('Ordem de Serviço Emissão'!E48:J48='Custos Inspeções'!B11,4,""))} -> 4

Sheet Fiscais de Contrato e Gerentes
B2: MATRÍCULA | C2: NOME | D2: FUNÇÃO | E2: TELEFONE | F2: CPF | G2: SUPERINTENTENDE | H2: DUS
B3: 100049 | C3: ANTONIO RAAD | D3: COORDENADOR DE PROGRAMA | E3: (21) 99382-3013 | F3: 887.397.167-91 | G3: EDUARDO AUGUSTO PEREIRA | H3: MIGUEL DA SILVA MARQUES
B4: 100057 | C4: LUCIMAR OLIVEIRA DE CASTRO | D4: ASSESSOR(A) III DE PROGRAMA | E4: (61)99617-8378 | F4: 701.304.696-53 | G4: EDUARDO AUGUSTO PEREIRA | H4: MIGUEL DA SILVA MARQUES
B5: 100093 | C5: ANGELLINO TAVARES PINHEIRO | D5: ASSESSOR(A) II DE PROGRAMA | E5: (69) 98408-0889 | F5: 579.742.846-68 | G5: EDUARDO AUGUSTO PEREIRA | H5: MIGUEL DA SILVA MARQUES
B6: 100182 | C6: RODRIGO ANTHERO ÁVILA PEREIRA | D6: ASSESSOR(A) II DE PROGRAMA | E6: (61) 98401-8811 | F6: 461.306.831-20 | G6: EDUARDO AUGUSTO PEREIRA | H6: MIGUEL DA SILVA MARQUES
B7: 100171 | C7: EDNILSON COPPINI CASTANHEIRA | D7: ASSESSOR(A) II DE PROGRAMA | E7: (61) 99522-4788 | F7: 163.555.508-60 | G7: EDUARDO AUGUSTO PEREIRA | H7: MIGUEL DA SILVA MARQUES
B9: 100104 | C9: AURELIO PAVAO DE FARIAS | D9: GERENTE | E9: (61) 99286-6675 | F9: 942.505.708-78 | G9: EDUARDO AUGUSTO PEREIRA | H9: MIGUEL DA SILVA MARQUES
B10: 100151 | C10: EDUARDO AUGUSTO PEREIRA | D10: SUPERINTENDENTE | E10: (31) 99399-5829 | F10: 800.680.066-91 | H10: MIGUEL DA SILVA MARQUES
B11: 200010 | C11: MIGUEL DA SILVA MARQUES | D11: DIRETOR(A) | E11: (31) 99164-1626 | F11: 039.194.746-00
B12: 200000 | C12: FISCAL DE CONTRATO

Sheet Empresas Credenciadas
B2: CADASTRO | C2: NOME | D2: CNPJ | E2: ENDEREÇO | F2: CONTATO | G2: TELEFONE | H2: E-MAIL | I2: DADOS BANCÁRIOS | J2: PROFISSIONAIS REDE | K2: PROFISSIONAIS GERAÇÃO
B3: 0 | C3: ENBPar
B4: 1 | C4: CMBr Engenharia Ltda | D4: 25.513.300/0001-03 | E4: Rua Álvaro Chaves Salomon, nº 33, Bairro Porto Velho, Itajubá - Minas Gerais, CEP: 37.501-012 | F4: José Maria de Carvalho | G4: (35) 99243-0018 | H4: cmbr.engenharia@gmail.com | I4: Banco: Banco Santander (033) Ag.: 3160 (CENTRO-ITAJUBA-MG) / CC: 13.002569-2
B5: 2 | C5: FK Consultoria e Serviços de Engenharia Ltda | D5: 04.560.260/0001-72 | E5: Rua Linha Bento Gonçalves, nº 6000, São Liberal, Vista Alegre do Prata, Rio Grande do Sul, CEP: 95.325-000 | F5: Adelar Jorge Kruger | G5: (51) 99901-2741 | H5: fk.ajkruger@gmail.com | I5: Banco: Banco do Estado do Rio Grande do Sul - Banrisul (041) Ag.: 0100 (Agência Central) / CC: 06 258618.0-4
B6: 3 | C6: KTA Engenharia Ltda | D6: 36.342.745/0001-86 | E6: Rua Edgar Luiz Schneider, nº 135, Jardim Isabel, Porto Alegre, Rio Grande do Sul, CEP: 91.760-310 | F6: Kassio Costella Acauan | G6: (51) 99571-5677 | H6: engenharia@ktaengenharia.com.br | I6: Banco: Banco XP S.A. (348) Ag.: 0001 / CC: 17439328
B7: 4 | C7: P3 Engenharia Elétrica Ltda | D7: 06.964.752/0001-59 | E7: Rua Marechal Floriano Peixoto, nº 1100, Bairro dos Estados, Indaial, Santa Catarina, CEP: 89.806-787 | F7: Ricardo Gonçalves de Souza | G7: (47) 9911-9774 (47) 3333-8077 | H7: ricardo.goncalves@p3engenharia.com.br administrativo@p3engenharia.com.br | I7: Banco: Cooperativa Central Ailos / Viacredi Cooperativa de Crédito (085) Ag.: 0101-5 / CC: 814464-8
B8: 5 | C8: COPENGE - Engenharia Ltda | D8: 19.648.254/0001-49 | E8: Rua das Orquideas, nº 777, Vila Bergamo, Indaiatuba, São Paulo, CEP: 13.345-040 | F8: Guilherme Dovichi Cruz | G8: (19) 3392-2560 | H8: guilherme.cruz@copenge.com.br | I8: Banco: Itaú (341) Ag.: 0041 / CC: 19.709-6
B9: 6 | C9: MCPAR Engenharia Ltda | D9: 04.637.111/0001-64 | E9: Avenida Jose de Souza Campos, nº 1815, Conjunto 504, Cambuí, Campinas, São Paulo, CEP: 13.025-320 | F9: Cyro Barbosa Bernardes | G9: (19) 3254-7699 (19) 98128-1764 | H9: mcparengenharia@mcpar.eng.br cyro@mcpar.eng.br | I9: Banco: Itaú (341) Ag.: 1565 (Galleria) / CC: 16364-7
B10: 7 | C10: AR Construções, Locadora e Serviços Ltda | D10: 31.759.110/0001-65 | E10: Rua Farmaceutico Jose Rodrigues, nº 802, Centro, Uruburetama, CE, CEP: 62.650-000 | F10: Alexandre Rikchelmy Vaz Barroso | G10: (85) 99814-2427 | H10: ar.const.servicos@gmail.com | I10: BANCO: Itaú (341) Ag.: 2758 / CC: 99492-1
B11: 8 | C11: ASSIST Consultores Associados Ltda | D11: 07.125.655/0001-35 | E11: Rua Monsenhor Bruno, 1153, Sala 513, 515,517, Aldeota, Fortaleza-CE, CEP: 60115-190 | F11: Liana Albuquerque Barbosa Gadelha | G11: (85) 3249-4514 | H11: liana@assistconsultores.com.br | I11: Banco: Banco do Brasil (001) Ag.: 3515-7 / CC: 40349-0
B12: 9 | C12: TPF Engenharia Ltda | D12: 12.285.441/0001-66 | F12: Thais Macedo | G12: (85) 3133-4900 | H12: licitacoes-ce@tpfe.com.br thais.macedo@tpfe.com.br
B13: 10 | C13: GEOPAC Engenharia e Consultoria Ltda | D13: 10.551.296/0010-92 | F13: Paula Leite | G13: (85) 3241-3147 / 98678-8694 | H13: financeiro@geopac.com.br paula@geopac.com.br
B14: 11 | C14: ECR Engenharia Ltda | D14: 42.161.372/0001-40 | F14: Gabriel Caetano Pereira da Silva | G14: (11) 3138-4949 | H14: g.silva@ecrengenharia.com.br comercial@ecrengenharia.com.br
B15: 12 | C15: STRATO Construções e Serviços Ltda | D15: 03.835.152/0001-00 | E15: Avenida Senador Vitorino Freire, 01, Quadra 41, Edifício São Luís Offices, Sala 608, CEP 65.030-015, Areinha, São Luís-MA | F15: SÉRGIO LUIS MARQUES DE OLIVEIRA | G15: (98) 98313-7740 | H15: strato.eng@gmail.com | I15: Banco: Nu Pagamentos (260) Ag.: AG- 0001 / CC: 588555376-6
C19: Atualizado dia 19/09/2025

Sheet Relação Empresas-Fiscais
B2: CADASTRO | C2: NOME | D2: PROCESSO SEI | E2: TERMO DE CREDENCIAMENTO | F2: DOTAÇÃO ORÇAMENTÁRIA | G2: FISCAL | H2: SUPLENTE | I2: ATO DE DESIGNAÇÃO | J2: STATUS | K2: WEBNAR | L2: EMPRESAS | M2: OBSERVAÇÕES | N2: OBSERVAÇÕES2 | O2: OBSERVAÇÕES3 | P2: OBSERVAÇÕES4
B3: 1 | C3: CMBr Engenharia Ltda | D3: 48110.000766/2025-30 | E3: TERMO DE CREDENCIAMENTO Nº 05/2025 | F3: 2.205.900.00 - Outros Serviços de Terceiros | G3: ='Fiscais de Contrato e Gerentes'!C4 -> LUCIMAR OLIVEIRA DE CASTRO | H3: ='Fiscais de Contrato e Gerentes'!C6 -> RODRIGO ANTHERO ÁVILA PEREIRA | I3: Despacho SEI 0022685 | J3: TERMO DE CREDENCIAMENTO Nº 5/2025 ASSINADO E PUBLICADO | K3: Webnar realizado dia 18/06/25 | L3: CMBR (6-6)
B4: 2 | C4: FK Consultoria e Serviços de Engenharia Ltda | D4: 48110.000784/2025-11 | E4: TERMO DE CREDENCIAMENTO Nº 06/2025 | F4: 2.205.900.00 - Outros Serviços de Terceiros | G4: ='Fiscais de Contrato e Gerentes'!C3 -> ANTONIO RAAD | H4: ='Fiscais de Contrato e Gerentes'!C5 -> ANGELLINO TAVARES PINHEIRO | I4: Despacho SEI 0022685 | J4: TERMO DE CREDENCIAMENTO Nº 6/2025 ASSINADO E PUBLICADO | K4: Webnar realizado dia 18/06/25 | L4: FK (5-6)
B5: 3 | C5: KTA Engenharia Ltda | D5: 48110.000840/2025-18 | E5: TERMO DE CREDENCIAMENTO Nº 07/2025 | F5: 2.205.900.00 - Outros Serviços de Terceiros | G5: ='Fiscais de Contrato e Gerentes'!C5 -> ANGELLINO TAVARES PINHEIRO | H5: ='Fiscais de Contrato e Gerentes'!C3 -> ANTONIO RAAD | I5: Despacho SEI 0022685 | J5: TERMO DE CREDENCIAMENTO Nº 7/2025 ASSINADO E PUBLICADO | K5: Webnar realizado dia 18/06/25 | L5: KTA (2-2) | M5: 1º Chamamento reprovado por não ter profissionais
B6: 4 | C6: P3 Engenharia Elétrica Ltda | D6: 48110.000852/2025-42 | E6: TERMO DE CREDENCIAMENTO Nº 08/2025 | F6: 2.205.900.00 - Outros Serviços de Terceiros | G6: ='Fiscais de Contrato e Gerentes'!C6 -> RODRIGO ANTHERO ÁVILA PEREIRA | H6: ='Fiscais de Contrato e Gerentes'!C4 -> LUCIMAR OLIVEIRA DE CASTRO | I6: Despacho SEI 0022685 | J6: TERMO DE CREDENCIAMENTO Nº 8/2025 ASSINADO E PUBLICADO | K6: Webnar realizado dia 18/06/25 e 04/07/25 | L6: P3 (3-2)
B7: 5 | C7: COPENGE - Engenharia Ltda | D7: 48110.000910/2025-38 | E7: TERMO DE CREDENCIAMENTO Nº 09/2025 | F7: 2.205.900.00 - Outros Serviços de Terceiros | G7: ='Fiscais de Contrato e Gerentes'!C6 -> RODRIGO ANTHERO ÁVILA PEREIRA | H7: ='Fiscais de Contrato e Gerentes'!C4 -> LUCIMAR OLIVEIRA DE CASTRO | I7: Termo de Designação de Fiscal SEI 0024132 | J7: TERMO DE CREDENCIAMENTO Nº 9/2025 ASSINADO E PUBLICADO | K7: Webnar realizado dia 04/07/25 às 15h | L7: Copenge (4-0)
B8: 6 | C8: MCPAR Engenharia Ltda | D8: 48110.000950/2025-80 | E8: TERMO DE CREDENCIAMENTO Nº 11/2025 | F8: 2.205.900.00 - Outros Serviços de Terceiros | G8: ='Fiscais de Contrato e Gerentes'!C7 -> EDNILSON COPPINI CASTANHEIRA | H8: ='Fiscais de Contrato e Gerentes'!C4 -> LUCIMAR OLIVEIRA DE CASTRO | J8: TERMO DE CREDENCIAMENTO Nº 11/2025 ASSINADO E PUBLICADO | K8: Webnar realizado dia 01/09/25 às 15:30min | L8: MCPAR (4-2)
B9: 7 | C9: AR Construções, Locadora e Serviços Ltda | D9: 48110.000954/2025-68 | E9: TERMO DE CREDENCIAMENTO Nº 12/2025 | F9: 2.205.900.00 - Outros Serviços de Terceiros | G9: ='Fiscais de Contrato e Gerentes'!C7 -> EDNILSON COPPINI CASTANHEIRA | H9: ='Fiscais de Contrato e Gerentes'!C6 -> RODRIGO ANTHERO ÁVILA PEREIRA | J9: TERMO DE CREDENCIAMENTO Nº 12/2025 ASSINADO E PUBLICADO | K9: Webnar realizado dia 01/09/25 às 15:30min | L9: AR (0-2)
B10: 8 | C10: ASSIST Consultores Associados Ltda | D10: 48110.0009552025-69 | E10: TERMO DE CREDENCIAMENTO Nº 13/2025 | F10: 2.205.900.00 - Outros Serviços de Terceiros | G10: ='Fiscais de Contrato e Gerentes'!C5 -> ANGELLINO TAVARES PINHEIRO | H10: ='Fiscais de Contrato e Gerentes'!C3 -> ANTONIO RAAD | J10: TERMO DE CREDENCIAMENTO Nº 13/2025 ASSINADO E PUBLICADO | L10: ASSIST (2-0) | M10: Nota Técnica 379(0030382) em 08/09/25 - HABILITADA | N10: Despacho Resultado Preliminar - ASSIST (0031012) dia 12/09/25 - HABILITADA | O10: Despacho Resultado Final - ASSIST (0032205) dia 18/09/2025 - HABILITADA | P10: Ato 44 Homologação de Resultado (0032226). Aguardando o Termo de Credenciamento e a publicação no DOU.
B11: 9 | C11: TPF Engenharia Ltda | E11: TERMO DE CREDENCIAMENTO Nº 14/2025 | F11: 2.205.900.00 - Outros Serviços de Terceiros | J11: Em publicação do Termo de Credenciamento nº 14/2025 | L11: TPF (2-0) | M11: Despacho Resultado Final - TPF (0029803)dia 04/09/2025 - INABILITADA | N11: Despacho GLIC - TPF (2º Pedido) (0030932) dia 11/09/2025; Documento de Habilitação - TPF (2º Pedido) (0030936) | O11: Prazo para análise dos documentos dia 25/09. Análise realizada - HABILITADA | P11: Nota Técnica 402 - TPF (0031789) em andamento
B12: 10 | C12: GEOPAC Engenharia e Consultoria Ltda | J12: Análise interna da documentação - prazo dia 10/09/2025 | L12: GEOPAC | M12: Nota Técnica 384(0030547) assinada dia 10/09/25 - INABILITADA Despacho Resultado Preliminar - ECR (0031097) dia 12/09/2025 - INABILITADA | N12: Despacho Resultado Final - GEOPAC (0032215) dia 18/09/2025 - INABILITADA | O12: Ato 44 Homologação de Resultado (0032226). Aguardando o Termo de Credenciamento e a publicação no DOU.
B13: 11 | C13: ECR Engenharia Ltda | J13: Análise interna da documentação - prazo dia 10/09/2025 | L13: ECR | M13: Nota Técnica 385(0030580) assinada dia 10/09/25 - INABILITADA Despacho Resultado Preliminar - ECR (0031113) dia 12/09/2025 - INABILITADA | N13: Enviado recurso dia 17/09 para análise. Análise realizada continua INABILITADA | O13: Resposta do recurso até dia 26/09 em andamento
B14: 12 | C14: STRATO Construções e Serviços Ltda | J14: Análise interna da documentação - prazo dia 26/09/2025 | L14: STRATO | M14: Prazo para análise dos documentos dia 25/09. Análise realizada INABILITADA | N14: Nota Técnica 401 (0031702) em andamento

Sheet Controle Fila Credenciadas
B2: CONTROLE DE RODÍZIO DAS EMPRESAS CREDENCIADAS
B3: POSIÇÃO INICIAL NA FILA | C3: ='Empresas Credenciadas'!B4 -> 1 | D3: ='Empresas Credenciadas'!B5 -> 2 | E3: ='Empresas Credenciadas'!B6 -> 3 | F3: ='Empresas Credenciadas'!B7 -> 4 | G3: ='Empresas Credenciadas'!B8 -> 5 | H3: ='Empresas Credenciadas'!B9 -> 6 | I3: ='Empresas Credenciadas'!B10 -> 7 | J3: ='Empresas Credenciadas'!B11 -> 8 | K3: ='Empresas Credenciadas'!B12 -> 9 | L3: 10
B4: CREDENCIADAS | C4: ='Empresas Credenciadas'!C4 -> CMBr Engenharia Ltda | D4: ='Empresas Credenciadas'!C5 -> FK Consultoria e Serviços de Engenharia Ltda | E4: ='Empresas Credenciadas'!C6 -> KTA Engenharia Ltda | F4: ='Empresas Credenciadas'!C7 -> P3 Engenharia Elétrica Ltda | G4: ='Empresas Credenciadas'!C8 -> COPENGE - Engenharia Ltda | H4: ='Empresas Credenciadas'!C9 -> MCPAR Engenharia Ltda | I4: ='Empresas Credenciadas'!C10 -> AR Construções, Locadora e Serviços Ltda | J4: ='Empresas Credenciadas'!C11 -> ASSIST Consultores Associados Ltda | K4: ='Empresas Credenciadas'!C12 -> TPF Engenharia Ltda
B5: ÁREA DE CONHECIMENTO | C5: Rede de Distribuição e Geração FV | D5: Rede de Distribuição | E5: Rede de Distribuição e Geração FV | F5: Rede de Distribuição e Geração FV | G5: Rede de Distribuição | H5: Rede de Distribuição e Geração FV | I5: Geração FV | J5: Rede de Distribuição | K5: Rede de Distribuição
B6: POSIÇÃO ATUAL FILA REDE | C6: 4º | D6: 5º | E6: 2º | F6: 6º | G6: 1º | H6: 3º | I6: --
B7: POSIÇÃO ATUAL FILA GERAÇÃO | C7: 4º | D7: 5º | E7: 1º | F7: 6º | G7: -- | H7: 2º | I7: 3º
B8: DATAS | C8: EVENTOS
B9: 45748 | C9: Assinatura Edital | D9: Assinatura Edital | E9: Assinatura Edital | F9: Assinatura Edital | G9: Assinatura Edital | H9: Assinatura Edital | I9: Assinatura Edital
B10: 45751 | C10: Publicação Edital | D10: Publicação Edital | E10: Publicação Edital | F10: Publicação Edital | G10: Publicação Edital | H10: Publicação Edital | I10: Publicação Edital
B11: 45811 | C11: Ato de Homologação | D11: Ato de Homologação | E11: Ato de Homologação | F11: Ato de Homologação
B12: 45820 | C12: Termo de Credenciamento | D12: Termo de Credenciamento | E12: Termo de Credenciamento | F12: Termo de Credenciamento
B13: 45824 | C13: Designação de Fiscal do Contrato | D13: Designação de Fiscal do Contrato | E13: Designação de Fiscal do Contrato | F13: Designação de Fiscal do Contrato
B14: 45825 | G14: Ato de Homologação
B15: 45826 | C15: Publicação D.O.U. | D15: Publicação D.O.U. | E15: Publicação D.O.U. | F15: Publicação D.O.U.
B16: 45835 | G16: Termo de Credenciamento
B17: 45842 | G17: Designação de Fiscal do Contrato
B18: 45845 | G18: Publicação D.O.U.
B19: 45863 | C19: Convocação Apoio Inspeção
B20: 45869 | C20: Emissão O.S.
B21: 45870 | D21: Convocação Apoio Inspeção
B22: 45876 | D22: Emissão O.S.
B23: 45883 | E23: Convocação Apoio Inspeção | H23: Ato de Homologação | I23: Ato de Homologação
B24: 45884 | E24: Recusa de Participação
B25: 45887 | F25: Convocação Apoio Inspeção
B26: 45891 | F26: Emissão O.S.
B27: 45895 | H27: Termo de Credenciamento | I27: Termo de Credenciamento
B28: 45909 | H28: Publicação D.O.U. | I28: Publicação D.O.U.
B29: 45924 | J29: Ato de Homologação
B30: 45930 | K30: Despacho Resultado Final
B31: 45933 | J31: Termo de Credenciamento | K31: Ato Homologação 2º Pedido
B32: 45940 | J32: Publicação D.O.U.
I38: Atualizado em 17/10/2025

Sheet Controle das Credenciadas
B2: Nºs | C2: EMPRESAS | D2: CNPJ | E2: CONTATO | F2: E-MAIL | G2: TELEFONE | H2: STATUS | I2: WEBNAR | J2: EMPRESAS | K2: OBSERVAÇÕES
B3: 1 | C3: CMBr Engenharia Ltda | D3: 25.513.300/0001-03 | E3: José Maria de Carvalho | F3: cmbr.engenharia@gmail.com | G3: (35) 99243-0018 | H3: TERMO DE CREDENCIAMENTO Nº 5/2025 ASSINADO E PUBLICADO | I3: Realizado dia 18/06/25 | J3: CMBR (6-6)
B4: 2 | C4: FK CONSULTORIA E SERVIÇOS DE ENGENHARIA LTDA | D4: 04.560.260/0001-72 | E4: Adelar Jorge Kruger | F4: fk.ajkruger@gmail.com | G4: (51) 99901-2741 | H4: TERMO DE CREDENCIAMENTO Nº 6/2025 ASSINADO E PUBLICADO | I4: Realizado dia 18/06/25 | J4: FK (5-1)
B5: 3 | C5: KTA ENGENHARIA LTDA | D5: 36.342.745/0001-86 | E5: Kassio Costella Acauan | F5: engenharia@ktaengenharia.com.br | G5: (51) 99648-2304 | H5: TERMO DE CREDENCIAMENTO Nº 7/2025 ASSINADO E PUBLICADO | I5: Realizado dia 18/06/25 | J5: KTA (2-3)
B6: 4 | C6: P3 ENGENHARIA ELETRICA LTDA | D6: 06.964.752/0001-59 | E6: Ricardo Gonçalves de Souza | F6: administrativo@p3engenharia.com.br | G6: (47) 9911-9774 | H6: TERMO DE CREDENCIAMENTO Nº 8/2025 ASSINADO E PUBLICADO | I6: Realizado dia 18/06/25 e 04/07/25 | J6: P3 (3-2)
B7: 5 | C7: Copenge Engenharia LTDA | D7: 19.648.254/0001-49 | E7: Guilherme Dovichi Cruz | F7: guilherme.cruz@copenge.com.br | G7: (19) 3392-2560 | H7: TERMO DE CREDENCIAMENTO Nº 9/2025 ASSINADO E PUBLICADO | I7: Realizado dia 04/07/25 às 15h | J7: Copenge (4-0)
B8: 6 | C8: MCPAR ENGENHARIA LTDA | D8: 04.637.111/0001-64 | E8: Cyro Barbosa Bernardes | F8: cyro@mcpar.eng.br | G8: (19) 3254-7699 / (19) 98128-1764 | H8: TERMO DE CREDENCIAMENTO Nº 11/2025 ASSINADO E PUBLICADO | I8: Realizado dia 01/09/25 às 15:30min | J8: MCPAR (4-2)
B9: 7 | C9: AR CONSTRUÇÕES, LOCADORA E SERVIÇOS LTDA | D9: 31.759.110/0001-65 | E9: Alexandre Rikchelmy Vaz Barroso | F9: ar.const.servicos@gmail.com | G9: (85) 998142427 | H9: TERMO DE CREDENCIAMENTO Nº 12/2025 ASSINADO E PUBLICADO | I9: Realizado dia 01/09/25 às 15:30min | J9: AR (1-3)
B10: 8 | C10: ASSIST Consultoria Associados Ltda | D10: 07.125.655/0001-35 | E10: Liana Albuquerque Barbosa Gadelha | F10: Liana@assistconsultores.com.br | G10: (85) 3249-4514 | H10: Data limite para recepção dos documentos 04/09/2025 | J10: ASSIST (2-0) | K10: Nota Técnica 379(0030382) em 08/09/25 HABILITADA; Despacho Resultado Preliminar - ASSIST (0031012) dia 12/09/25 HABILITADA | L10: Despacho Resultado Preliminar - ASSIST (0031012) dia 12/09/25 - HABILITADA | M10: Despacho Resultado Final - ASSIST (0032205) - HABILITADA | N10: Ato 44 Homologação de Resultado - ASSIST e GEOPAC (0032226)dia 24/09/25 - HABILITADA | O10: Termo de Credenciamento nº 13 ASSIST (0034585) dia 03/10/25 - HABILITADA | P10: Despacho publicado no DOU dia 10/10/25 - HABILITADA
B11: 9 | C11: TPF Engenharia Ltda | D11: 12.285.441/0001-66 | E11: Thais Macedo | F11: licitacoes-ce@tpfe.com.br thais.macedo@tpfe.com.br | G11: (85) 3133-4900 | H11: Despacho Resultado Preliminar - TPF (0029216) dia 29/08/2025 - INABILITADA | J11: TPF | K11: Despacho Resultado Final - TPF (0029803)dia 04/09/25 - INABILITADA | L11: Despacho GLIC - TPF (2º Pedido) (0030932) dia 11/09/25; Documento de Habilitação - TPF (2º Pedido) (0030936) | M11: Nota Técnica 402 - TPF (0031789); Despacho (004009) dia 23/09/25 HABILITADA | N11: Relatório 43 Check-list (2º pedido) (0034168) e Despacho Resultado Preliminar 2º pedido) (0034182) dia 24/09/25 - HABILITADA | O11: Despacho Resultado Preliminar - TPF(2ºpedido)(0034182)dia 24/09/25 HABILITADA | P11: Despacho Resultado Final - TPF(2ºpedido)(90036372)dia 30/09/25 - HABILITADA | Q11: Ato 46 Homologação 2º Pedido (0036373) dia 03/10/25 - HABILITADA | R11: Termo de Credenciamento 14 - TPF (0038850) dia 17/08/25 - HABILITADA | S11: Despacho GLIC (0039761) formalização do Termo de Credenciamento; Despacho - Extrato para publicação do D.O.U. (0039857) HABILITADA - Dia 22/10/25
B12: 10 | C12: GEOPAC Engenharia e Consultoria Ltda | D12: 10.551.296/0010-92 | E12: Paula Leite | F12: financeiro@geopac.com.br paula@geopac.com.br | G12: (85) 3241-3147 / 98678-8694 | H12: Análise interna da documentação - prazo dia 10/09/2025 | J12: GEOPAC | K12: Nota Técnica 384(0030547) assinada dia 10/09/25 - INABILITADA | L12: Relatório 40 Check List (0031054) INABILITADA | M12: Despacho Resultado Preliminar - GEOPAC (0031097) dia 12/09/2025 - INABILITADA | N12: Despacho Resultado Final - GEOPAC (0032215) dia 18/09/25 - INABILITADA | O12: Ato 44 Homologação de Resultado - ASSIST e GEOPAC (0032226)dia 24/09/25 - INABILITADA
B13: 11 | C13: ECR Engenharia Ltda | D13: 42.161.372/0001-40 | E13: Gabriel Caetano Pereira da Silva | F13: g.silva@ecrengenharia.com.br comercial@ecrengenharia.com.br | G13: (11) 3138-4949 | H13: Análise interna da documentação - prazo dia 10/09/2025 | J13: ECR | K13: Nota Técnica 385(0030580) assinada dia 10/09/25 - INABILITADA; Despacho Resultado Preliminar - ECR (0031113) dia 12/09/2025 - INABILITADA | L13: Enviado recurso dia 17/09/25 para análise. Análise realizada continua INABILITADA | M13: Resposta do recurso Nota Técnica 412 (0033881) e Despacho (0034029) dia 23/09/25 - INABILITADA | N13: Despacho Recurso ECR (0034074) dia 24/09/25 INABILITADA | O13: Despacho Resultado Final - ECR (0037325) dia 03/10/25 - INABILITADA | P13: Ato 48 Homologação - ECR (037329) dia - INABILITADA | Q13: Documentos de Habilitação - ECR (2º Pedido) (0038461)e Despacho GLIC - ECR (2º Pedido) (0038463) dia 13/10/25 | R13: Aguardando resposta do email de solicitação de Diligência, prazo 20/10/25 | S13: Nota Técnica 490 - Análise de Documentação Técnica ECR (0039736) dia 22/10/25 - INABILITADA | T13: Despacho Análise Documentação Técnica 2º Pedido ECR (0039942); Relatório 46 Check-List - ECR - 2º Pedido (0039949); Despacho Resultado Preliminar - ECR - 2º Pedido (0039965) Dia 23/10/25 INABILITADA
B14: 12 | C14: STRATO Construções e Serviços Ltda | D14: 03.835.152/0001-00 | E14: SÉRGIO LUIS MARQUES DE OLIVEIRA | F14: STRATO.ENG@GMAIL.COM | G14: (98) 98313-7740 | H14: Análise interna da documentação - prazo dia 26/09/2025 | J14: STRATO | K14: Nota Técnica 408 (0033420) dia 25/09/25 INABILITADA | L14: Relatório 44 Check List (0035002), INABILITADA | M14: Despacho Resultado Preliminar - STRATO (0035003) - INABILITADA | N14: Despacho Resultado Final - STRATO (0037011) dia 01/10/25 - INABILITADA | O14: Ato 47 Homologação - STRATO (0037012) dia 03/10/25 - INABILITADA
B15: 13 | C15: COSAMPA Energia Ltda | D15: 21.947.956/0001-75 | E15: Jânio Kleilthon Teixeira Costa | F15: contabilidade@cosampa.com.br | G15: (85) 3289-2363 | H15: Análise interna da documentação - prazo dia 05/11/2025 | J15: COSAMPA | K15: Documentos de Habilitação (0039885)Despacho GLIC (0039886) Dia 23/10/25 | L15: Pedido de Diligência por email pelo credenciamento dia 29/10/25 com prazo de resposta da COSAMPA para o dia 31/10/25. Email diligência SEI (0040577)
Q18: Atualizado em 30/10/25
