Workbook

Sheet Resumo
B2: Paraíba 7ª TRANCHE - LPT Rural - Lote 1 - Erro 9,00%
B3: Lote | D3: ODI | E3: Municípios | F3: UC | G3: Trafos | H3: Postes | I3: km AT | J3: km BT | K3: Dias | L3: Equipe | M3: Custo Estimado (R$)
B4: Extrato | C4: 5 | D4: {=ROWS(_xlfn.UNIQUE(_xlfn._xlws.FILTER('Amostra 1_5_extrato_erro_9%'!$A$2:$A$108,'Amostra 1_5_extrato_erro_9%'!$V$2:$V$108="Selecionado")))} -> 15 | E4: {=ROWS(_xlfn.UNIQUE(_xlfn._xlws.FILTER('Amostra 1_5_extrato_erro_9%'!$C$2:$C$108,'Amostra 1_5_extrato_erro_9%'!$V$2:$V$108="Selecionado")))} -> 14 | F4: =SUMIFS('Amostra 1_5_extrato_erro_9%'!$G$2:$G$108,'Amostra 1_5_extrato_erro_9%'!$V$2:$V$108,"Selecionado") -> 21 | G4: =SUMIFS('Amostra 1_5_extrato_erro_9%'!$O$2:$O$108,'Amostra 1_5_extrato_erro_9%'!$V$2:$V$108,"Selecionado") -> 8 | H4: =SUMIFS('Amostra 1_5_extrato_erro_9%'!$K$2:$K$108,'Amostra 1_5_extrato_erro_9%'!$V$2:$V$108,"Selecionado") -> 116 | I4: =SUMIFS('Amostra 1_5_extrato_erro_9%'!$L$2:$L$108,'Amostra 1_5_extrato_erro_9%'!$V$2:$V$108,"Selecionado") -> 3.7 | J4: =SUMIFS('Amostra 1_5_extrato_erro_9%'!$M$2:$M$108,'Amostra 1_5_extrato_erro_9%'!$V$2:$V$108,"Selecionado") -> 1.64 | K4: 7 | L4: 2 | M4: 89760
C5: 4 | D5: {=ROWS(_xlfn.UNIQUE(_xlfn._xlws.FILTER('Amostra 1_4_extrato_erro_9%'!$A$2:$A$108,'Amostra 1_4_extrato_erro_9%'!$V$2:$V$108="Selecionado")))} -> 19 | E5: {=ROWS(_xlfn.UNIQUE(_xlfn._xlws.FILTER('Amostra 1_4_extrato_erro_9%'!$C$2:$C$108,'Amostra 1_4_extrato_erro_9%'!$V$2:$V$108="Selecionado")))} -> 18 | F5: =SUMIFS('Amostra 1_4_extrato_erro_9%'!$G$2:$G$108,'Amostra 1_4_extrato_erro_9%'!$V$2:$V$108,"Selecionado") -> 19 | G5: =SUMIFS('Amostra 1_4_extrato_erro_9%'!$O$2:$O$108,'Amostra 1_4_extrato_erro_9%'!$V$2:$V$108,"Selecionado") -> 7 | H5: =SUMIFS('Amostra 1_4_extrato_erro_9%'!$K$2:$K$108,'Amostra 1_4_extrato_erro_9%'!$V$2:$V$108,"Selecionado") -> 132 | I5: =SUMIFS('Amostra 1_4_extrato_erro_9%'!$L$2:$L$108,'Amostra 1_4_extrato_erro_9%'!$V$2:$V$108,"Selecionado") -> 4.45 | J5: =SUMIFS('Amostra 1_4_extrato_erro_9%'!$M$2:$M$108,'Amostra 1_4_extrato_erro_9%'!$V$2:$V$108,"Selecionado") -> 2.32 | K5: 5 | L5: 2 | M5: 70560
C6: 3 | D6: {=ROWS(_xlfn.UNIQUE(_xlfn._xlws.FILTER('Amostra 1_3_extrato_erro_9%'!$A$2:$A$108,'Amostra 1_3_extrato_erro_9%'!$V$2:$V$108="Selecionado")))} -> 26 | E6: {=ROWS(_xlfn.UNIQUE(_xlfn._xlws.FILTER('Amostra 1_3_extrato_erro_9%'!$C$2:$C$108,'Amostra 1_3_extrato_erro_9%'!$V$2:$V$108="Selecionado")))} -> 25 | F6: =SUMIFS('Amostra 1_3_extrato_erro_9%'!$G$2:$G$108,'Amostra 1_3_extrato_erro_9%'!$V$2:$V$108,"Selecionado") -> 27 | G6: =SUMIFS('Amostra 1_3_extrato_erro_9%'!$O$2:$O$108,'Amostra 1_3_extrato_erro_9%'!$V$2:$V$108,"Selecionado") -> 11 | H6: =SUMIFS('Amostra 1_3_extrato_erro_9%'!$K$2:$K$108,'Amostra 1_3_extrato_erro_9%'!$V$2:$V$108,"Selecionado") -> 185 | I6: =SUMIFS('Amostra 1_3_extrato_erro_9%'!$L$2:$L$108,'Amostra 1_3_extrato_erro_9%'!$V$2:$V$108,"Selecionado") -> 3.86 | J6: =SUMIFS('Amostra 1_3_extrato_erro_9%'!$M$2:$M$108,'Amostra 1_3_extrato_erro_9%'!$V$2:$V$108,"Selecionado") -> 2.95 | K6: 8 | L6: 2 | M6: 99360

Sheet Amostra 1_3_extrato_erro_9%
A1: ODI | B1: Projeto | C1: Município | D1: Data Inicio | E1: Data Fim | F1: Custo(R$) | G1: Cons. | H1: Kit | I1: Regional | J1: Grupo | K1: Poste | L1: Rede AT km | M1: Rede BT km | N1: Medidor | O1: Trafo | P1: Equip. | Q1: VR | R1: Estrato | S1: regionale | T1: NGH | U1: NPH | V1: STATUS
A2: 12500186 | B2: LPT EPB - 7ª TRANCHE META EXCEPCIONAL | C2: GURINHEM | D2: 01/08/2025 | E2: 08/08/2025 | F2: 5812.89 | G2: 1 | H2: 0 | I2: LESTE | J2: 0 | K2: 1 | L2: 0 | M2: 0.05 | N2: 1 | O2: 0 | P2: 0 | Q2: 42.75 | R2: 1 | S2: 1 | T2: 70 | U2: 12
A3: 12500231 | B3: LPT EPB - 7ª TRANCHE META EXCEPCIONAL | C3: CURRAL DE CIMA | D3: 14/08/2025 | E3: 20/08/2025 | F3: 8863.59 | G3: 1 | H3: 0 | I3: CENTRO | J3: 0 | K3: 2 | L3: 0 | M3: 0.04 | N3: 1 | O3: 0 | P3: 0 | Q3: 72.2 | R3: 1 | S3: 1 | T3: 70 | U3: 12
A4: 12500453 | B4: LPT EPB - 7ª TRANCHE META EXCEPCIONAL | C4: LUCENA | D4: 23/06/2025 | E4: 10/07/2025 | F4: 7628.76 | G4: 1 | H4: 0 | I4: LESTE | J4: 0 | K4: 2 | L4: 0 | M4: 0.06 | N4: 1 | O4: 0 | P4: 0 | Q4: 73.3 | R4: 1 | S4: 1 | T4: 70 | U4: 12
A5: 12500626 | B5: LPT EPB - 7ª TRANCHE META EXCEPCIONAL | C5: MAMANGUAPE | D5: 14/05/2025 | E5: 07/06/2025 | F5: 12357.51 | G5: 1 | H5: 0 | I5: LESTE | J5: 0 | K5: 3 | L5: 0 | M5: 0.09 | N5: 1 | O5: 0 | P5: 0 | Q5: 104.95 | R5: 1 | S5: 1 | T5: 70 | U5: 12 | V5: Selecionado
A6: 12500634 | B6: LPT EPB - 7ª TRANCHE META EXCEPCIONAL | C6: SOBRADO | D6: 11/06/2025 | E6: 07/07/2025 | F6: 7497.67 | G6: 1 | H6: 0 | I6: LESTE | J6: 0 | K6: 1 | L6: 0 | M6: 0.08 | N6: 1 | O6: 0 | P6: 0 | Q6: 44.4 | R6: 1 | S6: 1 | T6: 70 | U6: 12
A7: 22500311 | B7: LPT EPB - 7ª TRANCHE META EXCEPCIONAL | C7: CASSERENGUE | D7: 07/05/2025 | E7: 23/06/2025 | F7: 29306.9 | G7: 1 | H7: 0 | I7: CENTRO | J7: 0 | K7: 8 | L7: 0 | M7: 0.37 | N7: 1 | O7: 0 | P7: 0 | Q7: 270.35 | R7: 2 | S7: 2 | T7: 28 | U7: 8
A8: 32402500 | B8: LPT EPB - 7ª TRANCHE META EXCEPCIONAL | C8: JURU | D8: 01/08/2025 | E8: 20/08/2025 | F8: 22698.3 | G8: 1 | H8: 0 | I8: OESTE | J8: 0 | K8: 6 | L8: 0 | M8: 0.29 | N8: 1 | O8: 0 | P8: 0 | Q8: 205.95 | R8: 2 | S8: 2 | T8: 28 | U8: 8
A9: 22500857 | B9: LPT EPB - 7ª TRANCHE META EXCEPCIONAL | C9: OURO VELHO | D9: 08/08/2025 | E9: 02/09/2025 | F9: 10941.05 | G9: 1 | H9: 0 | I9: CENTRO | J9: 0 | K9: 3 | L9: 0 | M9: 0.08 | N9: 1 | O9: 0 | P9: 0 | Q9: 104.4 | R9: 1 | S9: 1 | T9: 70 | U9: 12
A10: 32500217 | B10: LPT EPB - 7ª TRANCHE META EXCEPCIONAL | C10: RIACHO DOS CAVALOS | D10: 21/05/2025 | E10: 22/05/2025 | F10: 15678.41 | G10: 1 | H10: 0 | I10: OESTE | J10: 0 | K10: 3 | L10: 0 | M10: 0.11 | N10: 1 | O10: 0 | P10: 0 | Q10: 106.05 | R10: 1 | S10: 1 | T10: 70 | U10: 12
A11: 32500220 | B11: LPT EPB - 7ª TRANCHE META EXCEPCIONAL | C11: SANTA TERESINHA | D11: 08/05/2025 | E11: 28/05/2025 | F11: 17692.65 | G11: 1 | H11: 0 | I11: OESTE | J11: 0 | K11: 4 | L11: 0 | M11: 0.15 | N11: 1 | O11: 0 | P11: 0 | Q11: 138.25 | R11: 1 | S11: 1 | T11: 70 | U11: 12 | V11: Selecionado
A12: 32500241 | B12: LPT EPB - 7ª TRANCHE META EXCEPCIONAL | C12: SANTA LUZIA | D12: 09/05/2025 | E12: 30/07/2025 | F12: 16364.82 | G12: 1 | H12: 0 | I12: OESTE | J12: 0 | K12: 4 | L12: 0 | M12: 0.13 | N12: 1 | O12: 0 | P12: 0 | Q12: 137.15 | R12: 1 | S12: 1 | T12: 70 | U12: 12
A13: 32500309 | B13: LPT EPB - 7ª TRANCHE META EXCEPCIONAL | C13: AGUA BRANCA | D13: 16/05/2025 | E13: 02/06/2025 | F13: 45318.52 | G13: 1 | H13: 0 | I13: OESTE | J13: 0 | K13: 6 | L13: 0.24 | M13: 0.04 | N13: 1 | O13: 1 | P13: 0 | Q13: 248.6 | R13: 2 | S13: 2 | T13: 28 | U13: 8 | V13: Selecionado
A14: 32500354 | B14: LPT EPB - 7ª TRANCHE META EXCEPCIONAL | C14: AGUA BRANCA | D14: 17/04/2025 | E14: 29/08/2025 | F14: 17985.69 | G14: 1 | H14: 0 | I14: OESTE | J14: 0 | K14: 3 | L14: 0 | M14: 0.12 | N14: 1 | O14: 0 | P14: 0 | Q14: 106.6 | R14: 1 | S14: 1 | T14: 70 | U14: 12
A15: 32500356 | B15: LPT EPB - 7ª TRANCHE META EXCEPCIONAL | C15: IMACULADA | D15: 09/05/2025 | E15: 15/05/2025 | F15: 7082.6 | G15: 1 | H15: 0 | I15: OESTE | J15: 0 | K15: 2 | L15: 0 | M15: 0.04 | N15: 1 | O15: 0 | P15: 0 | Q15: 72.2 | R15: 1 | S15: 1 | T15: 70 | U15: 12
A16: 32500357 | B16: LPT EPB - 7ª TRANCHE META EXCEPCIONAL | C16: POCO DE JOSE DE MOURA | D16: 21/05/2025 | E16: 22/05/2025 | F16: 14952.68 | G16: 1 | H16: 0 | I16: OESTE | J16: 0 | K16: 1 | L16: 0.02 | M16: 0.02 | N16: 1 | O16: 1 | P16: 0 | Q16: 73.3 | R16: 1 | S16: 1 | T16: 70 | U16: 12
A17: 32500400 | B17: LPT EPB - 7ª TRANCHE META EXCEPCIONAL | C17: VARZEA | D17: 08/07/2025 | E17: 17/10/2025 | F17: 41372.24 | G17: 2 | H17: 0 | I17: OESTE | J17: 0 | K17: 7 | L17: 0.14 | M17: 0.27 | N17: 2 | O17: 0 | P17: 0 | Q17: 260.25 | R17: 2 | S17: 2 | T17: 28 | U17: 8
A18: 32500448 | B18: LPT EPB - 7ª TRANCHE META EXCEPCIONAL | C18: VARZEA | D18: 09/04/2025 | E18: 15/04/2025 | F18: 11775.02 | G18: 1 | H18: 0 | I18: OESTE | J18: 0 | K18: 3 | L18: 0 | M18: 0.13 | N18: 1 | O18: 0 | P18: 0 | Q18: 107.15 | R18: 1 | S18: 1 | T18: 70 | U18: 12
A19: 32500469 | B19: LPT EPB - 7ª TRANCHE META EXCEPCIONAL | C19: CONCEICAO | D19: 10/04/2025 | E19: 19/07/2025 | F19: 8036.9 | G19: 1 | H19: 0 | I19: OESTE | J19: 0 | K19: 2 | L19: 0 | M19: 0.08 | N19: 1 | O19: 0 | P19: 0 | Q19: 74.4 | R19: 1 | S19: 1 | T19: 70 | U19: 12
A20: 32500510 | B20: LPT EPB - 7ª TRANCHE META EXCEPCIONAL | C20: CAJAZEIRAS | D20: 30/04/2025 | E20: 05/05/2025 | F20: 10732.6 | G20: 1 | H20: 0 | I20: OESTE | J20: 0 | K20: 2 | L20: 0 | M20: 0.08 | N20: 1 | O20: 0 | P20: 0 | Q20: 74.4 | R20: 1 | S20: 1 | T20: 70 | U20: 12 | V20: Selecionado
A21: 32500476 | B21: LPT EPB - 7ª TRANCHE META EXCEPCIONAL | C21: SAO MAMEDE | D21: 09/05/2025 | E21: 14/08/2025 | F21: 27593.97 | G21: 1 | H21: 0 | I21: OESTE | J21: 0 | K21: 3 | L21: 0.05 | M21: 0.05 | N21: 1 | O21: 1 | P21: 0 | Q21: 138.25 | R21: 1 | S21: 1 | T21: 70 | U21: 12
A22: 32500512 | B22: LPT EPB - 7ª TRANCHE META EXCEPCIONAL | C22: SAO JOSE DE CAIANA | D22: 07/05/2025 | E22: 01/08/2025 | F22: 15415.61 | G22: 1 | H22: 0 | I22: OESTE | J22: 0 | K22: 4 | L22: 0 | M22: 0.13 | N22: 1 | O22: 0 | P22: 0 | Q22: 137.15 | R22: 1 | S22: 1 | T22: 70 | U22: 12
A23: 32500524 | B23: LPT EPB - 7ª TRANCHE META EXCEPCIONAL | C23: SANTA INES | D23: 21/05/2025 | E23: 01/09/2025 | F23: 48419.31 | G23: 1 | H23: 0 | I23: OESTE | J23: 0 | K23: 9 | L23: 0.1 | M23: 0.26 | N23: 1 | O23: 1 | P23: 0 | Q23: 335.3 | R23: 2 | S23: 2 | T23: 28 | U23: 8 | V23: Selecionado
A24: 32500562 | B24: LPT EPB - 7ª TRANCHE META EXCEPCIONAL | C24: DESTERRO | D24: 14/05/2025 | E24: 01/07/2025 | F24: 23357.2 | G24: 1 | H24: 0 | I24: OESTE | J24: 0 | K24: 3 | L24: 0.04 | M24: 0.04 | N24: 1 | O24: 1 | P24: 0 | Q24: 136.6 | R24: 1 | S24: 1 | T24: 70 | U24: 12 | V24: Selecionado
A25: 32500579 | B25: LPT EPB - 7ª TRANCHE META EXCEPCIONAL | C25: PAULISTA | D25: 24/04/2025 | E25: 07/05/2025 | F25: 14075.53 | G25: 1 | H25: 0 | I25: OESTE | J25: 0 | K25: 3 | L25: 0 | M25: 0.18 | N25: 1 | O25: 0 | P25: 0 | Q25: 109.9 | R25: 1 | S25: 1 | T25: 70 | U25: 12
A26: 32500614 | B26: LPT EPB - 7ª TRANCHE META EXCEPCIONAL | C26: SAO JOSE DA LAGOA TAPADA | D26: 23/06/2025 | E26: 14/08/2025 | F26: 29265.94 | G26: 1 | H26: 0 | I26: OESTE | J26: 0 | K26: 6 | L26: 0 | M26: 0.31 | N26: 1 | O26: 0 | P26: 0 | Q26: 207.05 | R26: 2 | S26: 2 | T26: 28 | U26: 8 | V26: Selecionado
A27: 32500630 | B27: LPT EPB - 7ª TRANCHE META EXCEPCIONAL | C27: SAO JOSE DA LAGOA TAPADA | D27: 08/05/2025 | E27: 23/06/2025 | F27: 11894.85 | G27: 1 | H27: 0 | I27: OESTE | J27: 0 | K27: 3 | L27: 0 | M27: 0.13 | N27: 1 | O27: 0 | P27: 0 | Q27: 107.15 | R27: 1 | S27: 1 | T27: 70 | U27: 12
A28: 32500633 | B28: LPT EPB - 7ª TRANCHE META EXCEPCIONAL | C28: TRIUNFO | D28: 16/04/2025 | E28: 24/04/2025 | F28: 15723.92 | G28: 1 | H28: 0 | I28: OESTE | J28: 0 | K28: 4 | L28: 0 | M28: 0.18 | N28: 1 | O28: 0 | P28: 0 | Q28: 139.9 | R28: 1 | S28: 1 | T28: 70 | U28: 12
A29: 32500636 | B29: LPT EPB - 7ª TRANCHE META EXCEPCIONAL | C29: AGUA BRANCA | D29: 28/05/2025 | E29: 05/06/2025 | F29: 9287.75 | G29: 1 | H29: 0 | I29: OESTE | J29: 0 | K29: 2 | L29: 0 | M29: 0.09 | N29: 1 | O29: 0 | P29: 0 | Q29: 74.95 | R29: 1 | S29: 1 | T29: 70 | U29: 12
A30: 32500654 | B30: LPT EPB - 7ª TRANCHE META EXCEPCIONAL | C30: MANAIRA | D30: 30/04/2025 | E30: 14/05/2025 | F30: 42496.78 | G30: 1 | H30: 0 | I30: OESTE | J30: 0 | K30: 9 | L30: 0.48 | M30: 0.04 | N30: 1 | O30: 1 | P30: 0 | Q30: 365 | R30: 2 | S30: 2 | T30: 28 | U30: 8
A31: 32500687 | B31: LPT EPB - 7ª TRANCHE META EXCEPCIONAL | C31: MAE D'AGUA | D31: 30/04/2025 | E31: 14/05/2025 | F31: 20653.1 | G31: 1 | H31: 0 | I31: OESTE | J31: 0 | K31: 3 | L31: 0.13 | M31: 0.03 | N31: 1 | O31: 1 | P31: 0 | Q31: 145.95 | R31: 1 | S31: 1 | T31: 70 | U31: 12
A32: 32500699 | B32: LPT EPB - 7ª TRANCHE META EXCEPCIONAL | C32: AGUA BRANCA | D32: 07/05/2025 | E32: 04/07/2025 | F32: 10758.43 | G32: 1 | H32: 0 | I32: OESTE | J32: 0 | K32: 1 | L32: 0 | M32: 0.1 | N32: 1 | O32: 0 | P32: 0 | Q32: 45.5 | R32: 1 | S32: 1 | T32: 70 | U32: 12
A33: 32500704 | B33: LPT EPB - 7ª TRANCHE META EXCEPCIONAL | C33: JURU | D33: 01/08/2025 | E33: 09/10/2025 | F33: 78753.87 | G33: 1 | H33: 0 | I33: OESTE | J33: 0 | K33: 21 | L33: 1.17 | M33: 0.02 | N33: 1 | O33: 1 | P33: 0 | Q33: 799.8 | R33: 3 | S33: 3 | T33: 9 | U33: 6
A34: 32500721 | B34: LPT EPB - 7ª TRANCHE META EXCEPCIONAL | C34: SAO JOAO DO RIO DO PEIXE | D34: 30/04/2025 | E34: 14/05/2025 | F34: 7378.28 | G34: 1 | H34: 0 | I34: OESTE | J34: 0 | K34: 1 | L34: 0 | M34: 0.03 | N34: 1 | O34: 0 | P34: 0 | Q34: 41.65 | R34: 1 | S34: 1 | T34: 70 | U34: 12
A35: 32500740 | B35: LPT EPB - 7ª TRANCHE META EXCEPCIONAL | C35: APARECIDA | D35: 09/04/2025 | E35: 13/05/2025 | F35: 25445.97 | G35: 1 | H35: 0 | I35: OESTE | J35: 0 | K35: 4 | L35: 0 | M35: 0.14 | N35: 1 | O35: 0 | P35: 0 | Q35: 137.7 | R35: 1 | S35: 1 | T35: 70 | U35: 12
A36: 32500744 | B36: LPT EPB - 7ª TRANCHE META EXCEPCIONAL | C36: SAO JOSE DE CAIANA | D36: 16/04/2025 | E36: 06/06/2025 | F36: 15008.16 | G36: 1 | H36: 0 | I36: OESTE | J36: 0 | K36: 4 | L36: 0 | M36: 0.16 | N36: 1 | O36: 0 | P36: 0 | Q36: 138.8 | R36: 1 | S36: 1 | T36: 70 | U36: 12 | V36: Selecionado
A37: 32500748 | B37: LPT EPB - 7ª TRANCHE META EXCEPCIONAL | C37: MATUREIA | D37: 17/04/2025 | E37: 18/06/2025 | F37: 7354.23 | G37: 1 | H37: 0 | I37: OESTE | J37: 0 | K37: 1 | L37: 0 | M37: 0.04 | N37: 1 | O37: 0 | P37: 0 | Q37: 42.2 | R37: 1 | S37: 1 | T37: 70 | U37: 12 | V37: Selecionado
A38: 32500755 | B38: LPT EPB - 7ª TRANCHE META EXCEPCIONAL | C38: BERNARDINO BATISTA | D38: 15/05/2025 | E38: 05/06/2025 | F38: 34501.56 | G38: 1 | H38: 0 | I38: OESTE | J38: 0 | K38: 8 | L38: 0.29 | M38: 0.08 | N38: 1 | O38: 0 | P38: 0 | Q38: 286.3 | R38: 2 | S38: 2 | T38: 28 | U38: 8 | V38: Selecionado
A39: 32500761 | B39: LPT EPB - 7ª TRANCHE META EXCEPCIONAL | C39: TEIXEIRA | D39: 13/06/2025 | E39: 04/07/2025 | F39: 18034.8 | G39: 1 | H39: 0 | I39: OESTE | J39: 0 | K39: 3 | L39: 0.04 | M39: 0.03 | N39: 1 | O39: 1 | P39: 0 | Q39: 136.05 | R39: 1 | S39: 1 | T39: 70 | U39: 12
A40: 32500765 | B40: LPT EPB - 7ª TRANCHE META EXCEPCIONAL | C40: MANAIRA | D40: 17/07/2025 | E40: 04/08/2025 | F40: 21648.15 | G40: 1 | H40: 0 | I40: OESTE | J40: 0 | K40: 2 | L40: 0.04 | M40: 0.04 | N40: 1 | O40: 1 | P40: 0 | Q40: 106.6 | R40: 1 | S40: 1 | T40: 70 | U40: 12
...

Sheet Planilha4
A1: Município | C1: Município | E1: Município
A2: AGUA BRANCA | C2: AGUA BRANCA | E2: AGUA BRANCA
A3: ALCANTIL | C3: BARRA DE SANTA ROSA | E3: ALCANTIL
A4: AREIA | C4: BERNARDINO BATISTA | E4: AREIA
A5: AROEIRAS | C5: CONGO | E5: BARRA DE SANTA ROSA
A6: BARRA DE SANTA ROSA | C6: COXIXOLA | E6: CUBATI
A7: BERNARDINO BATISTA | C7: CUITE | E7: CUITE
A8: BOA VISTA | C8: GADO BRAVO | E8: CURRAL DE CIMA
A9: BOQUEIRAO | C9: INGA | E9: ESPERANCA
A10: CAJAZEIRAS | C10: JURU | E10: JURU
A11: CONDE | C11: LUCENA | E11: NATUBA
A12: COXIXOLA | C12: MONTEIRO | E12: REMIGIO
... A15: DESTERRO | C15: SAO DOMINGOS DO CARIRI | E15: SOLEDADE
A16: MAMANGUAPE | C16: SAO JOSE DA LAGOA TAPADA
A17: MATUREIA | C17: SAO JOSE DE CAIANA
A18: OLIVEDOS | C18: SOBRADO
A19: PICUI | C19: SOLEDADE
A20: SANTA CECILIA
A21: SANTA INES
A22: SANTA TERESINHA
A23: SAO JOSE DA LAGOA TAPADA
A24: SAO JOSE DE CAIANA
A25: SAO SEBASTIAO DE LAGOA DE ROCA
A26: SOLEDADE

Sheet Amostra 1_4_extrato_erro_9%
A1: ODI | B1: Projeto | C1: Município | D1: Data Inicio | E1: Data Fim | F1: Custo(R$) | G1: Cons. | H1: Kit | I1: Regional | J1: Grupo | K1: Poste | L1: Rede AT km | M1: Rede BT km | N1: Medidor | O1: Trafo | P1: Equip. | Q1: VR | R1: Estrato | S1: regionale | T1: NGH | U1: NPH | V1: STATUS
A2: 12500186 | B2: LPT EPB - 7ª TRANCHE META EXCEPCIONAL | C2: GURINHEM | D2: 01/08/2025 | E2: 08/08/2025 | F2: 5812.89 | G2: 1 | H2: 0 | I2: LESTE | J2: 0 | K2: 1 | L2: 0 | M2: 0.05 | N2: 1 | O2: 0 | P2: 0 | Q2: 42.75 | R2: 1 | S2: 1 | T2: 61 | U2: 8
A3: 12500231 | B3: LPT EPB - 7ª TRANCHE META EXCEPCIONAL | C3: CURRAL DE CIMA | D3: 14/08/2025 | E3: 20/08/2025 | F3: 8863.59 | G3: 1 | H3: 0 | I3: CENTRO | J3: 0 | K3: 2 | L3: 0 | M3: 0.04 | N3: 1 | O3: 0 | P3: 0 | Q3: 72.2 | R3: 1 | S3: 1 | T3: 61 | U3: 8
A4: 12500453 | B4: LPT EPB - 7ª TRANCHE META EXCEPCIONAL | C4: LUCENA | D4: 23/06/2025 | E4: 10/07/2025 | F4: 7628.76 | G4: 1 | H4: 0 | I4: LESTE | J4: 0 | K4: 2 | L4: 0 | M4: 0.06 | N4: 1 | O4: 0 | P4: 0 | Q4: 73.3 | R4: 1 | S4: 1 | T4: 61 | U4: 8 | V4: Selecionado
A5: 12500626 | B5: LPT EPB - 7ª TRANCHE META EXCEPCIONAL | C5: MAMANGUAPE | D5: 14/05/2025 | E5: 07/06/2025 | F5: 12357.51 | G5: 1 | H5: 0 | I5: LESTE | J5: 0 | K5: 3 | L5: 0 | M5: 0.09 | N5: 1 | O5: 0 | P5: 0 | Q5: 104.95 | R5: 1 | S5: 1 | T5: 61 | U5: 8
A6: 12500634 | B6: LPT EPB - 7ª TRANCHE META EXCEPCIONAL | C6: SOBRADO | D6: 11/06/2025 | E6: 07/07/2025 | F6: 7497.67 | G6: 1 | H6: 0 | I6: LESTE | J6: 0 | K6: 1 | L6: 0 | M6: 0.08 | N6: 1 | O6: 0 | P6: 0 | Q6: 44.4 | R6: 1 | S6: 1 | T6: 61 | U6: 8 | V6: Selecionado
A7: 22500311 | B7: LPT EPB - 7ª TRANCHE META EXCEPCIONAL | C7: CASSERENGUE | D7: 07/05/2025 | E7: 23/06/2025 | F7: 29306.9 | G7: 1 | H7: 0 | I7: CENTRO | J7: 0 | K7: 8 | L7: 0 | M7: 0.37 | N7: 1 | O7: 0 | P7: 0 | Q7: 270.35 | R7: 2 | S7: 2 | T7: 30 | U7: 5
A8: 32402500 | B8: LPT EPB - 7ª TRANCHE META EXCEPCIONAL | C8: JURU | D8: 01/08/2025 | E8: 20/08/2025 | F8: 22698.3 | G8: 1 | H8: 0 | I8: OESTE | J8: 0 | K8: 6 | L8: 0 | M8: 0.29 | N8: 1 | O8: 0 | P8: 0 | Q8: 205.95 | R8: 2 | S8: 2 | T8: 30 | U8: 5
A9: 22500857 | B9: LPT EPB - 7ª TRANCHE META EXCEPCIONAL | C9: OURO VELHO | D9: 08/08/2025 | E9: 02/09/2025 | F9: 10941.05 | G9: 1 | H9: 0 | I9: CENTRO | J9: 0 | K9: 3 | L9: 0 | M9: 0.08 | N9: 1 | O9: 0 | P9: 0 | Q9: 104.4 | R9: 1 | S9: 1 | T9: 61 | U9: 8
A10: 32500217 | B10: LPT EPB - 7ª TRANCHE META EXCEPCIONAL | C10: RIACHO DOS CAVALOS | D10: 21/05/2025 | E10: 22/05/2025 | F10: 15678.41 | G10: 1 | H10: 0 | I10: OESTE | J10: 0 | K10: 3 | L10: 0 | M10: 0.11 | N10: 1 | O10: 0 | P10: 0 | Q10: 106.05 | R10: 1 | S10: 1 | T10: 61 | U10: 8 | V10: Selecionado
A11: 32500220 | B11: LPT EPB - 7ª TRANCHE META EXCEPCIONAL | C11: SANTA TERESINHA | D11: 08/05/2025 | E11: 28/05/2025 | F11: 17692.65 | G11: 1 | H11: 0 | I11: OESTE | J11: 0 | K11: 4 | L11: 0 | M11: 0.15 | N11: 1 | O11: 0 | P11: 0 | Q11: 138.25 | R11: 1 | S11: 1 | T11: 61 | U11: 8 | V11: Selecionado
A12: 32500241 | B12: LPT EPB - 7ª TRANCHE META EXCEPCIONAL | C12: SANTA LUZIA | D12: 09/05/2025 | E12: 30/07/2025 | F12: 16364.82 | G12: 1 | H12: 0 | I12: OESTE | J12: 0 | K12: 4 | L12: 0 | M12: 0.13 | N12: 1 | O12: 0 | P12: 0 | Q12: 137.15 | R12: 1 | S12: 1 | T12: 61 | U12: 8
A13: 32500309 | B13: LPT EPB - 7ª TRANCHE META EXCEPCIONAL | C13: AGUA BRANCA | D13: 16/05/2025 | E13: 02/06/2025 | F13: 45318.52 | G13: 1 | H13: 0 | I13: OESTE | J13: 0 | K13: 6 | L13: 0.24 | M13: 0.04 | N13: 1 | O13: 1 | P13: 0 | Q13: 248.6 | R13: 2 | S13: 2 | T13: 30 | U13: 5 | V13: Selecionado
A14: 32500354 | B14: LPT EPB - 7ª TRANCHE META EXCEPCIONAL | C14: AGUA BRANCA | D14: 17/04/2025 | E14: 29/08/2025 | F14: 17985.69 | G14: 1 | H14: 0 | I14: OESTE | J14: 0 | K14: 3 | L14: 0 | M14: 0.12 | N14: 1 | O14: 0 | P14: 0 | Q14: 106.6 | R14: 1 | S14: 1 | T14: 61 | U14: 8
A15: 32500356 | B15: LPT EPB - 7ª TRANCHE META EXCEPCIONAL | C15: IMACULADA | D15: 09/05/2025 | E15: 15/05/2025 | F15: 7082.6 | G15: 1 | H15: 0 | I15: OESTE | J15: 0 | K15: 2 | L15: 0 | M15: 0.04 | N15: 1 | O15: 0 | P15: 0 | Q15: 72.2 | R15: 1 | S15: 1 | T15: 61 | U15: 8
A16: 32500357 | B16: LPT EPB - 7ª TRANCHE META EXCEPCIONAL | C16: POCO DE JOSE DE MOURA | D16: 21/05/2025 | E16: 22/05/2025 | F16: 14952.68 | G16: 1 | H16: 0 | I16: OESTE | J16: 0 | K16: 1 | L16: 0.02 | M16: 0.02 | N16: 1 | O16: 1 | P16: 0 | Q16: 73.3 | R16: 1 | S16: 1 | T16: 61 | U16: 8
A17: 32500400 | B17: LPT EPB - 7ª TRANCHE META EXCEPCIONAL | C17: VARZEA | D17: 08/07/2025 | E17: 17/10/2025 | F17: 41372.24 | G17: 2 | H17: 0 | I17: OESTE | J17: 0 | K17: 7 | L17: 0.14 | M17: 0.27 | N17: 2 | O17: 0 | P17: 0 | Q17: 260.25 | R17: 2 | S17: 2 | T17: 30 | U17: 5
A18: 32500448 | B18: LPT EPB - 7ª TRANCHE META EXCEPCIONAL | C18: VARZEA | D18: 09/04/2025 | E18: 15/04/2025 | F18: 11775.02 | G18: 1 | H18: 0 | I18: OESTE | J18: 0 | K18: 3 | L18: 0 | M18: 0.13 | N18: 1 | O18: 0 | P18: 0 | Q18: 107.15 | R18: 1 | S18: 1 | T18: 61 | U18: 8
A19: 32500469 | B19: LPT EPB - 7ª TRANCHE META EXCEPCIONAL | C19: CONCEICAO | D19: 10/04/2025 | E19: 19/07/2025 | F19: 8036.9 | G19: 1 | H19: 0 | I19: OESTE | J19: 0 | K19: 2 | L19: 0 | M19: 0.08 | N19: 1 | O19: 0 | P19: 0 | Q19: 74.4 | R19: 1 | S19: 1 | T19: 61 | U19: 8
A20: 32500510 | B20: LPT EPB - 7ª TRANCHE META EXCEPCIONAL | C20: CAJAZEIRAS | D20: 30/04/2025 | E20: 05/05/2025 | F20: 10732.6 | G20: 1 | H20: 0 | I20: OESTE | J20: 0 | K20: 2 | L20: 0 | M20: 0.08 | N20: 1 | O20: 0 | P20: 0 | Q20: 74.4 | R20: 1 | S20: 1 | T20: 61 | U20: 8
A21: 32500476 | B21: LPT EPB - 7ª TRANCHE META EXCEPCIONAL | C21: SAO MAMEDE | D21: 09/05/2025 | E21: 14/08/2025 | F21: 27593.97 | G21: 1 | H21: 0 | I21: OESTE | J21: 0 | K21: 3 | L21: 0.05 | M21: 0.05 | N21: 1 | O21: 1 | P21: 0 | Q21: 138.25 | R21: 1 | S21: 1 | T21: 61 | U21: 8
A22: 32500512 | B22: LPT EPB - 7ª TRANCHE META EXCEPCIONAL | C22: SAO JOSE DE CAIANA | D22: 07/05/2025 | E22: 01/08/2025 | F22: 15415.61 | G22: 1 | H22: 0 | I22: OESTE | J22: 0 | K22: 4 | L22: 0 | M22: 0.13 | N22: 1 | O22: 0 | P22: 0 | Q22: 137.15 | R22: 1 | S22: 1 | T22: 61 | U22: 8 | V22: Selecionado
A23: 32500524 | B23: LPT EPB - 7ª TRANCHE META EXCEPCIONAL | C23: SANTA INES | D23: 21/05/2025 | E23: 01/09/2025 | F23: 48419.31 | G23: 1 | H23: 0 | I23: OESTE | J23: 0 | K23: 9 | L23: 0.1 | M23: 0.26 | N23: 1 | O23: 1 | P23: 0 | Q23: 335.3 | R23: 3 | S23: 3 | T23: 11 | U23: 4
A24: 32500562 | B24: LPT EPB - 7ª TRANCHE META EXCEPCIONAL | C24: DESTERRO | D24: 14/05/2025 | E24: 01/07/2025 | F24: 23357.2 | G24: 1 | H24: 0 | I24: OESTE | J24: 0 | K24: 3 | L24: 0.04 | M24: 0.04 | N24: 1 | O24: 1 | P24: 0 | Q24: 136.6 | R24: 1 | S24: 1 | T24: 61 | U24: 8
A25: 32500579 | B25: LPT EPB - 7ª TRANCHE META EXCEPCIONAL | C25: PAULISTA | D25: 24/04/2025 | E25: 07/05/2025 | F25: 14075.53 | G25: 1 | H25: 0 | I25: OESTE | J25: 0 | K25: 3 | L25: 0 | M25: 0.18 | N25: 1 | O25: 0 | P25: 0 | Q25: 109.9 | R25: 1 | S25: 1 | T25: 61 | U25: 8
A26: 32500614 | B26: LPT EPB - 7ª TRANCHE META EXCEPCIONAL | C26: SAO JOSE DA LAGOA TAPADA | D26: 23/06/2025 | E26: 14/08/2025 | F26: 29265.94 | G26: 1 | H26: 0 | I26: OESTE | J26: 0 | K26: 6 | L26: 0 | M26: 0.31 | N26: 1 | O26: 0 | P26: 0 | Q26: 207.05 | R26: 2 | S26: 2 | T26: 30 | U26: 5
A27: 32500630 | B27: LPT EPB - 7ª TRANCHE META EXCEPCIONAL | C27: SAO JOSE DA LAGOA TAPADA | D27: 08/05/2025 | E27: 23/06/2025 | F27: 11894.85 | G27: 1 | H27: 0 | I27: OESTE | J27: 0 | K27: 3 | L27: 0 | M27: 0.13 | N27: 1 | O27: 0 | P27: 0 | Q27: 107.15 | R27: 1 | S27: 1 | T27: 61 | U27: 8 | V27: Selecionado
A28: 32500633 | B28: LPT EPB - 7ª TRANCHE META EXCEPCIONAL | C28: TRIUNFO | D28: 16/04/2025 | E28: 24/04/2025 | F28: 15723.92 | G28: 1 | H28: 0 | I28: OESTE | J28: 0 | K28: 4 | L28: 0 | M28: 0.18 | N28: 1 | O28: 0 | P28: 0 | Q28: 139.9 | R28: 1 | S28: 1 | T28: 61 | U28: 8
A29: 32500636 | B29: LPT EPB - 7ª TRANCHE META EXCEPCIONAL | C29: AGUA BRANCA | D29: 28/05/2025 | E29: 05/06/2025 | F29: 9287.75 | G29: 1 | H29: 0 | I29: OESTE | J29: 0 | K29: 2 | L29: 0 | M29: 0.09 | N29: 1 | O29: 0 | P29: 0 | Q29: 74.95 | R29: 1 | S29: 1 | T29: 61 | U29: 8
A30: 32500654 | B30: LPT EPB - 7ª TRANCHE META EXCEPCIONAL | C30: MANAIRA | D30: 30/04/2025 | E30: 14/05/2025 | F30: 42496.78 | G30: 1 | H30: 0 | I30: OESTE | J30: 0 | K30: 9 | L30: 0.48 | M30: 0.04 | N30: 1 | O30: 1 | P30: 0 | Q30: 365 | R30: 3 | S30: 3 | T30: 11 | U30: 4
A31: 32500687 | B31: LPT EPB - 7ª TRANCHE META EXCEPCIONAL | C31: MAE D'AGUA | D31: 30/04/2025 | E31: 14/05/2025 | F31: 20653.1 | G31: 1 | H31: 0 | I31: OESTE | J31: 0 | K31: 3 | L31: 0.13 | M31: 0.03 | N31: 1 | O31: 1 | P31: 0 | Q31: 145.95 | R31: 1 | S31: 1 | T31: 61 | U31: 8
A32: 32500699 | B32: LPT EPB - 7ª TRANCHE META EXCEPCIONAL | C32: AGUA BRANCA | D32: 07/05/2025 | E32: 04/07/2025 | F32: 10758.43 | G32: 1 | H32: 0 | I32: OESTE | J32: 0 | K32: 1 | L32: 0 | M32: 0.1 | N32: 1 | O32: 0 | P32: 0 | Q32: 45.5 | R32: 1 | S32: 1 | T32: 61 | U32: 8
A33: 32500704 | B33: LPT EPB - 7ª TRANCHE META EXCEPCIONAL | C33: JURU | D33: 01/08/2025 | E33: 09/10/2025 | F33: 78753.87 | G33: 1 | H33: 0 | I33: OESTE | J33: 0 | K33: 21 | L33: 1.17 | M33: 0.02 | N33: 1 | O33: 1 | P33: 0 | Q33: 799.8 | R33: 4 | S33: 4 | T33: 5 | U33: 2 | V33: Selecionado
A34: 32500721 | B34: LPT EPB - 7ª TRANCHE META EXCEPCIONAL | C34: SAO JOAO DO RIO DO PEIXE | D34: 30/04/2025 | E34: 14/05/2025 | F34: 7378.28 | G34: 1 | H34: 0 | I34: OESTE | J34: 0 | K34: 1 | L34: 0 | M34: 0.03 | N34: 1 | O34: 0 | P34: 0 | Q34: 41.65 | R34: 1 | S34: 1 | T34: 61 | U34: 8
A35: 32500740 | B35: LPT EPB - 7ª TRANCHE META EXCEPCIONAL | C35: APARECIDA | D35: 09/04/2025 | E35: 13/05/2025 | F35: 25445.97 | G35: 1 | H35: 0 | I35: OESTE | J35: 0 | K35: 4 | L35: 0 | M35: 0.14 | N35: 1 | O35: 0 | P35: 0 | Q35: 137.7 | R35: 1 | S35: 1 | T35: 61 | U35: 8
A36: 32500744 | B36: LPT EPB - 7ª TRANCHE META EXCEPCIONAL | C36: SAO JOSE DE CAIANA | D36: 16/04/2025 | E36: 06/06/2025 | F36: 15008.16 | G36: 1 | H36: 0 | I36: OESTE | J36: 0 | K36: 4 | L36: 0 | M36: 0.16 | N36: 1 | O36: 0 | P36: 0 | Q36: 138.8 | R36: 1 | S36: 1 | T36: 61 | U36: 8
A37: 32500748 | B37: LPT EPB - 7ª TRANCHE META EXCEPCIONAL | C37: MATUREIA | D37: 17/04/2025 | E37: 18/06/2025 | F37: 7354.23 | G37: 1 | H37: 0 | I37: OESTE | J37: 0 | K37: 1 | L37: 0 | M37: 0.04 | N37: 1 | O37: 0 | P37: 0 | Q37: 42.2 | R37: 1 | S37: 1 | T37: 61 | U37: 8
A38: 32500755 | B38: LPT EPB - 7ª TRANCHE META EXCEPCIONAL | C38: BERNARDINO BATISTA | D38: 15/05/2025 | E38: 05/06/2025 | F38: 34501.56 | G38: 1 | H38: 0 | I38: OESTE | J38: 0 | K38: 8 | L38: 0.29 | M38: 0.08 | N38: 1 | O38: 0 | P38: 0 | Q38: 286.3 | R38: 2 | S38: 2 | T38: 30 | U38: 5 | V38: Selecionado
A39: 32500761 | B39: LPT EPB - 7ª TRANCHE META EXCEPCIONAL | C39: TEIXEIRA | D39: 13/06/2025 | E39: 04/07/2025 | F39: 18034.8 | G39: 1 | H39: 0 | I39: OESTE | J39: 0 | K39: 3 | L39: 0.04 | M39: 0.03 | N39: 1 | O39: 1 | P39: 0 | Q39: 136.05 | R39: 1 | S39: 1 | T39: 61 | U39: 8
A40: 32500765 | B40: LPT EPB - 7ª TRANCHE META EXCEPCIONAL | C40: MANAIRA | D40: 17/07/2025 | E40: 04/08/2025 | F40: 21648.15 | G40: 1 | H40: 0 | I40: OESTE | J40: 0 | K40: 2 | L40: 0.04 | M40: 0.04 | N40: 1 | O40: 1 | P40: 0 | Q40: 106.6 | R40: 1 | S40: 1 | T40: 61 | U40: 8
...

Sheet Amostra 1_5_extrato_erro_9%
A1: ODI | B1: Projeto | C1: Município | D1: Data Inicio | E1: Data Fim | F1: Custo(R$) | G1: Cons. | H1: Kit | I1: Regional | J1: Grupo | K1: Poste | L1: Rede AT km | M1: Rede BT km | N1: Medidor | O1: Trafo | P1: Equip. | Q1: VR | R1: Estrato | S1: regionale | T1: NGH | U1: NPH | V1: STATUS
A2: 12500186 | B2: LPT EPB - 7ª TRANCHE META EXCEPCIONAL | C2: GURINHEM | D2: 01/08/2025 | E2: 08/08/2025 | F2: 5812.89 | G2: 1 | H2: 0 | I2: LESTE | J2: 0 | K2: 1 | L2: 0 | M2: 0.05 | N2: 1 | O2: 0 | P2: 0 | Q2: 42.75 | R2: 1 | S2: 1 | T2: 40 | U2: 4
A3: 12500231 | B3: LPT EPB - 7ª TRANCHE META EXCEPCIONAL | C3: CURRAL DE CIMA | D3: 14/08/2025 | E3: 20/08/2025 | F3: 8863.59 | G3: 1 | H3: 0 | I3: CENTRO | J3: 0 | K3: 2 | L3: 0 | M3: 0.04 | N3: 1 | O3: 0 | P3: 0 | Q3: 72.2 | R3: 1 | S3: 1 | T3: 40 | U3: 4 | V3: Selecionado
A4: 12500453 | B4: LPT EPB - 7ª TRANCHE META EXCEPCIONAL | C4: LUCENA | D4: 23/06/2025 | E4: 10/07/2025 | F4: 7628.76 | G4: 1 | H4: 0 | I4: LESTE | J4: 0 | K4: 2 | L4: 0 | M4: 0.06 | N4: 1 | O4: 0 | P4: 0 | Q4: 73.3 | R4: 1 | S4: 1 | T4: 40 | U4: 4
A5: 12500626 | B5: LPT EPB - 7ª TRANCHE META EXCEPCIONAL | C5: MAMANGUAPE | D5: 14/05/2025 | E5: 07/06/2025 | F5: 12357.51 | G5: 1 | H5: 0 | I5: LESTE | J5: 0 | K5: 3 | L5: 0 | M5: 0.09 | N5: 1 | O5: 0 | P5: 0 | Q5: 104.95 | R5: 1 | S5: 1 | T5: 40 | U5: 4
A6: 12500634 | B6: LPT EPB - 7ª TRANCHE META EXCEPCIONAL | C6: SOBRADO | D6: 11/06/2025 | E6: 07/07/2025 | F6: 7497.67 | G6: 1 | H6: 0 | I6: LESTE | J6: 0 | K6: 1 | L6: 0 | M6: 0.08 | N6: 1 | O6: 0 | P6: 0 | Q6: 44.4 | R6: 1 | S6: 1 | T6: 40 | U6: 4
A7: 22500311 | B7: LPT EPB - 7ª TRANCHE META EXCEPCIONAL | C7: CASSERENGUE | D7: 07/05/2025 | E7: 23/06/2025 | F7: 29306.9 | G7: 1 | H7: 0 | I7: CENTRO | J7: 0 | K7: 8 | L7: 0 | M7: 0.37 | N7: 1 | O7: 0 | P7: 0 | Q7: 270.35 | R7: 3 | S7: 3 | T7: 18 | U7: 3
A8: 32402500 | B8: LPT EPB - 7ª TRANCHE META EXCEPCIONAL | C8: JURU | D8: 01/08/2025 | E8: 20/08/2025 | F8: 22698.3 | G8: 1 | H8: 0 | I8: OESTE | J8: 0 | K8: 6 | L8: 0 | M8: 0.29 | N8: 1 | O8: 0 | P8: 0 | Q8: 205.95 | R8: 2 | S8: 2 | T8: 39 | U8: 4
A9: 22500857 | B9: LPT EPB - 7ª TRANCHE META EXCEPCIONAL | C9: OURO VELHO | D9: 08/08/2025 | E9: 02/09/2025 | F9: 10941.05 | G9: 1 | H9: 0 | I9: CENTRO | J9: 0 | K9: 3 | L9: 0 | M9: 0.08 | N9: 1 | O9: 0 | P9: 0 | Q9: 104.4 | R9: 1 | S9: 1 | T9: 40 | U9: 4
A10: 32500217 | B10: LPT EPB - 7ª TRANCHE META EXCEPCIONAL | C10: RIACHO DOS CAVALOS | D10: 21/05/2025 | E10: 22/05/2025 | F10: 15678.41 | G10: 1 | H10: 0 | I10: OESTE | J10: 0 | K10: 3 | L10: 0 | M10: 0.11 | N10: 1 | O10: 0 | P10: 0 | Q10: 106.05 | R10: 1 | S10: 1 | T10: 40 | U10: 4
A11: 32500220 | B11: LPT EPB - 7ª TRANCHE META EXCEPCIONAL | C11: SANTA TERESINHA | D11: 08/05/2025 | E11: 28/05/2025 | F11: 17692.65 | G11: 1 | H11: 0 | I11: OESTE | J11: 0 | K11: 4 | L11: 0 | M11: 0.15 | N11: 1 | O11: 0 | P11: 0 | Q11: 138.25 | R11: 2 | S11: 2 | T11: 39 | U11: 4
A12: 32500241 | B12: LPT EPB - 7ª TRANCHE META EXCEPCIONAL | C12: SANTA LUZIA | D12: 09/05/2025 | E12: 30/07/2025 | F12: 16364.82 | G12: 1 | H12: 0 | I12: OESTE | J12: 0 | K12: 4 | L12: 0 | M12: 0.13 | N12: 1 | O12: 0 | P12: 0 | Q12: 137.15 | R12: 2 | S12: 2 | T12: 39 | U12: 4
A13: 32500309 | B13: LPT EPB - 7ª TRANCHE META EXCEPCIONAL | C13: AGUA BRANCA | D13: 16/05/2025 | E13: 02/06/2025 | F13: 45318.52 | G13: 1 | H13: 0 | I13: OESTE | J13: 0 | K13: 6 | L13: 0.24 | M13: 0.04 | N13: 1 | O13: 1 | P13: 0 | Q13: 248.6 | R13: 3 | S13: 3 | T13: 18 | U13: 3 | V13: Selecionado
A14: 32500354 | B14: LPT EPB - 7ª TRANCHE META EXCEPCIONAL | C14: AGUA BRANCA | D14: 17/04/2025 | E14: 29/08/2025 | F14: 17985.69 | G14: 1 | H14: 0 | I14: OESTE | J14: 0 | K14: 3 | L14: 0 | M14: 0.12 | N14: 1 | O14: 0 | P14: 0 | Q14: 106.6 | R14: 1 | S14: 1 | T14: 40 | U14: 4
A15: 32500356 | B15: LPT EPB - 7ª TRANCHE META EXCEPCIONAL | C15: IMACULADA | D15: 09/05/2025 | E15: 15/05/2025 | F15: 7082.6 | G15: 1 | H15: 0 | I15: OESTE | J15: 0 | K15: 2 | L15: 0 | M15: 0.04 | N15: 1 | O15: 0 | P15: 0 | Q15: 72.2 | R15: 1 | S15: 1 | T15: 40 | U15: 4
A16: 32500357 | B16: LPT EPB - 7ª TRANCHE META EXCEPCIONAL | C16: POCO DE JOSE DE MOURA | D16: 21/05/2025 | E16: 22/05/2025 | F16: 14952.68 | G16: 1 | H16: 0 | I16: OESTE | J16: 0 | K16: 1 | L16: 0.02 | M16: 0.02 | N16: 1 | O16: 1 | P16: 0 | Q16: 73.3 | R16: 1 | S16: 1 | T16: 40 | U16: 4
A17: 32500400 | B17: LPT EPB - 7ª TRANCHE META EXCEPCIONAL | C17: VARZEA | D17: 08/07/2025 | E17: 17/10/2025 | F17: 41372.24 | G17: 2 | H17: 0 | I17: OESTE | J17: 0 | K17: 7 | L17: 0.14 | M17: 0.27 | N17: 2 | O17: 0 | P17: 0 | Q17: 260.25 | R17: 3 | S17: 3 | T17: 18 | U17: 3
A18: 32500448 | B18: LPT EPB - 7ª TRANCHE META EXCEPCIONAL | C18: VARZEA | D18: 09/04/2025 | E18: 15/04/2025 | F18: 11775.02 | G18: 1 | H18: 0 | I18: OESTE | J18: 0 | K18: 3 | L18: 0 | M18: 0.13 | N18: 1 | O18: 0 | P18: 0 | Q18: 107.15 | R18: 1 | S18: 1 | T18: 40 | U18: 4
A19: 32500469 | B19: LPT EPB - 7ª TRANCHE META EXCEPCIONAL | C19: CONCEICAO | D19: 10/04/2025 | E19: 19/07/2025 | F19: 8036.9 | G19: 1 | H19: 0 | I19: OESTE | J19: 0 | K19: 2 | L19: 0 | M19: 0.08 | N19: 1 | O19: 0 | P19: 0 | Q19: 74.4 | R19: 1 | S19: 1 | T19: 40 | U19: 4
A20: 32500510 | B20: LPT EPB - 7ª TRANCHE META EXCEPCIONAL | C20: CAJAZEIRAS | D20: 30/04/2025 | E20: 05/05/2025 | F20: 10732.6 | G20: 1 | H20: 0 | I20: OESTE | J20: 0 | K20: 2 | L20: 0 | M20: 0.08 | N20: 1 | O20: 0 | P20: 0 | Q20: 74.4 | R20: 1 | S20: 1 | T20: 40 | U20: 4
A21: 32500476 | B21: LPT EPB - 7ª TRANCHE META EXCEPCIONAL | C21: SAO MAMEDE | D21: 09/05/2025 | E21: 14/08/2025 | F21: 27593.97 | G21: 1 | H21: 0 | I21: OESTE | J21: 0 | K21: 3 | L21: 0.05 | M21: 0.05 | N21: 1 | O21: 1 | P21: 0 | Q21: 138.25 | R21: 2 | S21: 2 | T21: 39 | U21: 4
A22: 32500512 | B22: LPT EPB - 7ª TRANCHE META EXCEPCIONAL | C22: SAO JOSE DE CAIANA | D22: 07/05/2025 | E22: 01/08/2025 | F22: 15415.61 | G22: 1 | H22: 0 | I22: OESTE | J22: 0 | K22: 4 | L22: 0 | M22: 0.13 | N22: 1 | O22: 0 | P22: 0 | Q22: 137.15 | R22: 2 | S22: 2 | T22: 39 | U22: 4
A23: 32500524 | B23: LPT EPB - 7ª TRANCHE META EXCEPCIONAL | C23: SANTA INES | D23: 21/05/2025 | E23: 01/09/2025 | F23: 48419.31 | G23: 1 | H23: 0 | I23: OESTE | J23: 0 | K23: 9 | L23: 0.1 | M23: 0.26 | N23: 1 | O23: 1 | P23: 0 | Q23: 335.3 | R23: 3 | S23: 3 | T23: 18 | U23: 3
A24: 32500562 | B24: LPT EPB - 7ª TRANCHE META EXCEPCIONAL | C24: DESTERRO | D24: 14/05/2025 | E24: 01/07/2025 | F24: 23357.2 | G24: 1 | H24: 0 | I24: OESTE | J24: 0 | K24: 3 | L24: 0.04 | M24: 0.04 | N24: 1 | O24: 1 | P24: 0 | Q24: 136.6 | R24: 2 | S24: 2 | T24: 39 | U24: 4
A25: 32500579 | B25: LPT EPB - 7ª TRANCHE META EXCEPCIONAL | C25: PAULISTA | D25: 24/04/2025 | E25: 07/05/2025 | F25: 14075.53 | G25: 1 | H25: 0 | I25: OESTE | J25: 0 | K25: 3 | L25: 0 | M25: 0.18 | N25: 1 | O25: 0 | P25: 0 | Q25: 109.9 | R25: 1 | S25: 1 | T25: 40 | U25: 4
... A32: 32500699 | B32: LPT EPB - 7ª TRANCHE META EXCEPCIONAL | C32: AGUA BRANCA | D32: 07/05/2025 | E32: 04/07/2025 | F32: 10758.43 | G32: 1 | H32: 0 | I32: OESTE | J32: 0 | K32: 1 | L32: 0 | M32: 0.1 | N32: 1 | O32: 0 | P32: 0 | Q32: 45.5 | R32: 1 | S32: 1 | T32: 40 | U32: 4
A33: 32500704 | B33: LPT EPB - 7ª TRANCHE META EXCEPCIONAL | C33: JURU | D33: 01/08/2025 | E33: 09/10/2025 | F33: 78753.87 | G33: 1 | H33: 0 | I33: OESTE | J33: 0 | K33: 21 | L33: 1.17 | M33: 0.02 | N33: 1 | O33: 1 | P33: 0 | Q33: 799.8 | R33: 5 | S33: 5 | T33: 5 | U33: 2 | V33: Selecionado
A34: 32500721 | B34: LPT EPB - 7ª TRANCHE META EXCEPCIONAL | C34: SAO JOAO DO RIO DO PEIXE | D34: 30/04/2025 | E34: 14/05/2025 | F34: 7378.28 | G34: 1 | H34: 0 | I34: OESTE | J34: 0 | K34: 1 | L34: 0 | M34: 0.03 | N34: 1 | O34: 0 | P34: 0 | Q34: 41.65 | R34: 1 | S34: 1 | T34: 40 | U34: 4
A35: 32500740 | B35: LPT EPB - 7ª TRANCHE META EXCEPCIONAL | C35: APARECIDA | D35: 09/04/2025 | E35: 13/05/2025 | F35: 25445.97 | G35: 1 | H35: 0 | I35: OESTE | J35: 0 | K35: 4 | L35: 0 | M35: 0.14 | N35: 1 | O35: 0 | P35: 0 | Q35: 137.7 | R35: 2 | S35: 2 | T35: 39 | U35: 4
A36: 32500744 | B36: LPT EPB - 7ª TRANCHE META EXCEPCIONAL | C36: SAO JOSE DE CAIANA | D36: 16/04/2025 | E36: 06/06/2025 | F36: 15008.16 | G36: 1 | H36: 0 | I36: OESTE | J36: 0 | K36: 4 | L36: 0 | M36: 0.16 | N36: 1 | O36: 0 | P36: 0 | Q36: 138.8 | R36: 2 | S36: 2 | T36: 39 | U36: 4
A37: 32500748 | B37: LPT EPB - 7ª TRANCHE META EXCEPCIONAL | C37: MATUREIA | D37: 17/04/2025 | E37: 18/06/2025 | F37: 7354.23 | G37: 1 | H37: 0 | I37: OESTE | J37: 0 | K37: 1 | L37: 0 | M37: 0.04 | N37: 1 | O37: 0 | P37: 0 | Q37: 42.2 | R37: 1 | S37: 1 | T37: 40 | U37: 4
A38: 32500755 | B38: LPT EPB - 7ª TRANCHE META EXCEPCIONAL | C38: BERNARDINO BATISTA | D38: 15/05/2025 | E38: 05/06/2025 | F38: 34501.56 | G38: 1 | H38: 0 | I38: OESTE | J38: 0 | K38: 8 | L38: 0.29 | M38: 0.08 | N38: 1 | O38: 0 | P38: 0 | Q38: 286.3 | R38: 3 | S38: 3 | T38: 18 | U38: 3
A39: 32500761 | B39: LPT EPB - 7ª TRANCHE META EXCEPCIONAL | C39: TEIXEIRA | D39: 13/06/2025 | E39: 04/07/2025 | F39: 18034.8 | G39: 1 | H39: 0 | I39: OESTE | J39: 0 | K39: 3 | L39: 0.04 | M39: 0.03 | N39: 1 | O39: 1 | P39: 0 | Q39: 136.05 | R39: 2 | S39: 2 | T39: 39 | U39: 4
A40: 32500765 | B40: LPT EPB - 7ª TRANCHE META EXCEPCIONAL | C40: MANAIRA | D40: 17/07/2025 | E40: 04/08/2025 | F40: 21648.15 | G40: 1 | H40: 0 | I40: OESTE | J40: 0 | K40: 2 | L40: 0.04 | M40: 0.04 | N40: 1 | O40: 1 | P40: 0 | Q40: 106.6 | R40: 1 | S40: 1 | T40: 40 | U40: 4
A41: 32501989 | B41: LPT EPB - 7ª TRANCHE META EXCEPCIONAL | C41: VARZEA | D41: 28/08/2025 | E41: 23/09/2025 | F41: 18640.32 | G41: 1 | H41: 0 | I41: OESTE | J41: 0 | K41: 4 | L41: 0 | M41: 0.13 | N41: 1 | O41: 0 | P41: 0 | Q41: 137.15 | R41: 2 | S41: 2 | T41: 39 | U41: 4
A42: 22500262 | B42: LPT EPB - 7ª TRANCHE META EXCEPCIONAL | C42: SOLEDADE | D42: 14/07/2025 | E42: 20/08/2025 | F42: 35779.87 | G42: 1 | H42: 0 | I42: CENTRO | J42: 0 | K42: 9 | L42: 0 | M42: 0.35 | N42: 1 | O42: 0 | P42: 0 | Q42: 299.25 | R42: 3 | S42: 3 | T42: 18 | U42: 3 | V42: Selecionado
A43: 22500328 | B43: LPT EPB - 7ª TRANCHE META EXCEPCIONAL | C43: SAO SEBASTIAO DO UMBUZEIRO | D43: 29/04/2025 | E43: 25/07/2025 | F43: 27461.25 | G43: 1 | H43: 0 | I43: CENTRO | J43: 0 | K43: 3 | L43: 0.05 | M43: 0.05 | N43: 1 | O43: 1 | P43: 0 | Q43: 138.25 | R43: 2 | S43: 2 | T43: 39 | U43: 4 | V43: Selecionado
A44: 22500330 | B44: LPT EPB - 7ª TRANCHE META EXCEPCIONAL | C44: BOQUEIRAO | D44: 08/08/2025 | E44: 13/08/2025 | F44: 20597.34 | G44: 1 | H44: 0 | I44: CENTRO | J44: 0 | K44: 6 | L44: 0 | M44: 0.2 | N44: 1 | O44: 0 | P44: 0 | Q44: 201 | R44: 2 | S44: 2 | T44: 39 | U44: 4
A45: 22500583 | B45: LPT EPB - 7ª TRANCHE META EXCEPCIONAL | C45: SERIDO | D45: 29/04/2025 | E45: 09/09/2025 | F45: 13988.21 | G45: 1 | H45: 0 | I45: CENTRO | J45: 0 | K45: 4 | L45: 0 | M45: 0.15 | N45: 1 | O45: 0 | P45: 0 | Q45: 138.25 | R45: 2 | S45: 2 | T45: 39 | U45: 4
A46: 22500662 | B46: LPT EPB - 7ª TRANCHE META EXCEPCIONAL | C46: AROEIRAS | D46: 13/08/2025 | E46: 28/10/2025 | F46: 10733.31 | G46: 1 | H46: 0 | I46: CENTRO | J46: 0 | K46: 2 | L46: 0 | M46: 0.04 | N46: 1 | O46: 0 | P46: 0 | Q46: 72.2 | R46: 1 | S46: 1 | T46: 40 | U46: 4
...
