Workbook

Sheet Resumo
B2: ENERGISA RO 3ª Tranche - LPT AmL - Lote 1 - Erro 5,00%
B3: Lote | C3: Lote | D3: ODI | E3: Municípios | F3: SIGFI 80 | G3: SIGFI 160 | H3: UC | I3: Dias | J3: Equipe | K3: Custo Estimado (R$)
B4: Extrato | C4: 3 | D4: {=ROWS(_xlfn.UNIQUE(_xlfn._xlws.FILTER('Amostra 1_3_extrato_erro_5%'!$A:$A,'Amostra 1_3_extrato_erro_5%'!$V:$V="Selecionado")))} -> 45 | E4: {=ROWS(_xlfn.UNIQUE(_xlfn._xlws.FILTER('Amostra 1_3_extrato_erro_5%'!$C:$C,'Amostra 1_3_extrato_erro_5%'!$V:$V="Selecionado")))} -> 13 | F4: 44 | G4: 1 | H4: =SUM(F4:G4) -> 45 | I4: 14 | J4: 4 | K4: 296640
C5: 4 | D5: {=ROWS(_xlfn.UNIQUE(_xlfn._xlws.FILTER('Amostra 1_4_extrato_erro_5%'!$A:$A,'Amostra 1_4_extrato_erro_5%'!$V:$V="Selecionado")))} -> 22 | E5: {=ROWS(_xlfn.UNIQUE(_xlfn._xlws.FILTER('Amostra 1_4_extrato_erro_5%'!$C:$C,'Amostra 1_4_extrato_erro_5%'!$V:$V="Selecionado")))} -> 9 | F5: 22 | G5: =SUMIFS('Amostra 1_4_extrato_erro_5%'!$O$2:$O$108,'Amostra 1_4_extrato_erro_5%'!$V$2:$V$108,"Selecionado") -> 0 | H5: =SUM(F5:G5) -> 22 | I5: 7 | J5: 2 | K5: 85440
C6: 5 | D6: {=ROWS(_xlfn.UNIQUE(_xlfn._xlws.FILTER('Amostra 1_5_extrato_erro_5%'!$A:$A,'Amostra 1_5_extrato_erro_5%'!$V:$V="Selecionado")))} -> 15 | E6: {=ROWS(_xlfn.UNIQUE(_xlfn._xlws.FILTER('Amostra 1_5_extrato_erro_5%'!$C:$C,'Amostra 1_5_extrato_erro_5%'!$V:$V="Selecionado")))} -> 9 | F6: 15 | G6: =SUMIFS('Amostra 1_5_extrato_erro_5%'!$O$2:$O$108,'Amostra 1_5_extrato_erro_5%'!$V$2:$V$108,"Selecionado") -> 0 | H6: =SUM(F6:G6) -> 15 | I6: 5 | J6: 2 | K6: 66240
C7: 6 | D7: {=ROWS(_xlfn.UNIQUE(_xlfn._xlws.FILTER('Amostra 1_6_extrato_erro_5%'!$A:$A,'Amostra 1_6_extrato_erro_5%'!$V:$V="Selecionado")))} -> 12 | E7: {=ROWS(_xlfn.UNIQUE(_xlfn._xlws.FILTER('Amostra 1_6_extrato_erro_5%'!$C:$C,'Amostra 1_6_extrato_erro_5%'!$V:$V="Selecionado")))} -> 8 | F7: 12 | G7: 0 | H7: =SUM(F7:G7) -> 12 | I7: 4 | J7: 2 | K7: 56640
L57: =12/40 -> 0.3

Sheet Dimensionamento_Inspecao
B2: RELATÓRIO TÉCNICO CONSOLIDADO — VALIDAÇÃO DA AMOSTRA, ANÁLISE LOGÍSTICA E DIMENSIONAMENTO DE EQUIPES
B3: Inspeção física de unidades consumidoras (UCs) — Estado de Rondônia | Amostras: 1_3, 1_4, 1_5 e 1_6 (extrato, erro 5%) | Referência histórica: Contrato ECM-015/2024, 2ª tranche
B5: 1. RESUMO EXECUTIVO
B6: Indicador-chave | D6: Valor | E6: Unidade / observação
B7: AMOSTRA SELECIONADA PARA A INSPEÇÃO | D7: {=INDEX($B$123:$B$126,$D$140)} -> Amostra 1_3_extrato_erro_5% | E7: eleita entre as 4 alternativas
B8: UCs a inspecionar | D8: =C127 -> 45 | E8: UCs
B9: Municípios abrangidos | D9: =D127 -> 13 | E9: municípios
B10: Clusters logísticos ativos | D10: =E127 -> 4 | E10: agrupamentos geográficos
B11: Município mais distante da capital | D11: {=INDEX($J$103:$J$106,$D$140)} -> 747 | E11: km rodoviários estimados
B12: Produtividade média bruta histórica (Rondônia) | D12: =D39 -> 1.125 | E12: UC / equipe / dia
B13: Produtividade líquida de inspeção (base de cálculo) | D13: =D42 -> 1.5 | E13: UC / equipe / dia
B14: Produtividade ajustada da amostra selecionada | D14: =P127 -> 1 | E14: UC / equipe / dia
B15: EQUIPES RECOMENDADAS | D15: =C147 -> 4 | E15: equipes
B16: PRAZO RECOMENDADO — dias de campo | D16: =G147 -> 13 | E16: dias de execução
B17: PRAZO TOTAL RECOMENDADO | D17: =I147 -> 14 | E17: dias corridos (campo + mobilização)
B18: Score da amostra selecionada na matriz de decisão | D18: =MAX(I138:L138) -> 0.65 | E18: de 0 a 1
B20: {="SÍNTESE: as abas 1_3, 1_4, 1_5 e 1_6 são quatro desenhos amostrais alternativos para o mesmo universo, e não parcelas de um mesmo escopo. Dimensionadas isoladamente, exigem "&I123&", "&I124&", "&I125&" e "&I126&" equipe-dias e prazos ótimos de "&O123&", "&O124&", "&O125&" e "&O126&" dias, respectivamente. Como todas percorrem os mesmos "&D60&" clusters logísticos, o custo de deslocamento é quase fixo e as amostras menores tornam-se as menos eficientes: o esforço por UC vai de "&TEXT(Q123,"0,00")&" na 1_3 a "&TEXT(Q126,"0,00")&" equipe-dias na 1_6. Pela matriz de decisão ponderada, recomenda-se a "&INDEX($B$123:$B$126,$D$140)&" ("&C127&" UCs em "&D127&" municípios), executada por "&C147&" equipes em "&I147&" dias corridos."} -> SÍNTESE: as abas 1_3, 1_4, 1_5 e 1_6 são quatro desenhos amostrais alternativos para o mesmo universo, e não parcelas de um mesmo escopo. Dimensionadas isoladamente, exigem 45, 28, 23 e 23 equipe-dias e prazos ótimos de 14, 9, 8 e 8 dias, respectivamente. Como todas percorrem os mesmos 4 clusters logísticos, o custo de deslocamento é quase fixo e as amostras menores tornam-se as menos eficientes: o esforço por UC vai de 1,00 na 1_3 a 1,92 equipe-dias na 1_6. Pela matriz de decisão ponderada, recomenda-se a Amostra 1_3_extrato_erro_5% (45 UCs em 13 municípios), executada por 4 equipes em 14 dias corridos.
B22: 2. METODOLOGIA UTILIZADA
B23: Etapa 1 — Extração da amostra: leitura das abas "Amostra 1_3", "1_4", "1_5" e "1_6" (extrato, erro 5%), filtrando exclusivamente os registros cuja coluna V (STATUS) contém o valor "Selecionado".
B24: Etapa 2 — Validação: verificação de duplicidade de código de UC, ausência de município, ausência de identificador de UC, ausência de coordenadas geográficas e divergência de grafia de municípios.
B25: Etapa 3 — Georreferenciamento: cálculo do centroide (média das coordenadas das UCs selecionadas) de cada município a partir das colunas X (Latitude_UC) e Y (Longitude_UC).
B26: Etapa 4 — Distâncias: distância geodésica capital–município pela fórmula de Haversine (raio 6.371 km) e conversão para distância rodoviária por fator de sinuosidade calibrado para a malha de Rondônia.
B27: Etapa 5 — Clusterização logística: agrupamento dos municípios por eixo rodoviário e proximidade, permitindo roteirização encadeada e diluição do deslocamento entre várias UCs.
B28: Etapa 6 — Produtividade: extração dos indicadores históricos de Rondônia (produtividade por equipe e produtividade diária) e segregação entre produtividade bruta e produtividade líquida de inspeção (expurgados os dias de deslocamento).
B29: Etapa 7 — Dimensionamento independente: para cada uma das quatro amostras, cálculo do esforço em equipe-dias (inspeção + deslocamento), do caminho crítico por cluster e do prazo com 2, 3, 4 e com o número ótimo de equipes.
B30: Etapa 8 — Seleção da amostra: matriz de decisão multicritério ponderada (robustez amostral, eficiência logística, prazo, esforço total e concentração geográfica) para eleger, entre as quatro alternativas, a mais adequada à execução da inspeção.
B32: 3. HISTÓRICO DE REFERÊNCIA — RONDÔNIA, CONTRATO ECM-015/2024 (2ª TRANCHE)
B33: Parâmetro histórico | D33: Valor | E33: Unidade
B34: UCs inspecionadas na 2ª tranche | D34: 18 | E34: UCs
B35: Equipes mobilizadas | D35: 2 | E35: equipes
B36: Dias de execução | D36: 8 | E36: dias
B37: Municípios abrangidos | D37: 3 | E37: municípios
B38: Produtividade média por equipe = 18 ÷ 2 | D38: =D34/D35 -> 9 | E38: UC / equipe
B39: Produtividade média por dia (bruta) = 18 ÷ (2 × 8) | D39: =D34/(D35*D36) -> 1.125 | E39: UC / equipe / dia
B40: Dias de deslocamento embutidos no histórico (ida e volta à capital) | D40: =D56 -> 2 | E40: dias / equipe
B41: Dias efetivos de inspeção por equipe = 8 − 2 | D41: =D36-D40 -> 6 | E41: dias / equipe
B42: Produtividade líquida de inspeção = 18 ÷ (2 × 6) | D42: =D34/(D35*D41) -> 1.5 | E42: UC / equipe / dia
B43: Dispersão geográfica histórica = 3 municípios ÷ 18 UCs | D43: =D37/D34 -> 0.16666667 | E43: municípios / UC
B44: UCs por município no histórico = 18 ÷ 3 | D44: =D34/D37 -> 6 | E44: UCs / município
B45: Esforço total histórico = 2 equipes × 8 dias | D45: =D35*D36 -> 16 | E45: equipe-dias
...

Sheet Estimativa_extra.6

Sheet Planilha4
A1: Município | C1: Município | E1: Município | G1: Município
A2: Alta Floresta d'Oeste | C2: Cujubim | E2: Cacoal | G2: Espigão D'Oeste
A3: Cacoal | C3: Espigão D'Oeste | E3: Candeias do Jamari | G3: Guajará-Mirim
A4: Candeias do Jamari | C4: Guajará-Mirim | E4: Espigão D'Oeste | G4: Ji-Paraná
A5: Cujubim | C5: Ji-Paraná | E5: Guajará-Mirim | G5: Nova Mamoré
A6: Guajará-Mirim | C6: Pimenta Bueno | E6: Ji-Paraná | G6: Pimenta Bueno
A7: Ji-Paraná | C7: Porto Velho | E7: Pimenta Bueno | G7: Porto Velho
A8: Machadinho D'oeste | C8: São Miguel do Guaporé | E8: Porto Velho | G8: São Francisco do Guaporé
A9: Nova Mamoré | C9: Vale do Anari | E9: São Miguel do Guaporé | G9: Vilhena
A10: Pimenta Bueno | C10: Vilhena | E10: Vilhena
A11: Porto Velho
A12: São Francisco do Guaporé
A13: São Miguel do Guaporé
A14: Vilhena

Sheet Estimativa_extra.5

Sheet Estimativa_extra.4

Sheet Estimativa_extra.3

Sheet Amostra 1_3_extrato_erro_5%
A1: UC | B1: Projeto | C1: Município | D1: Data Inicio | E1: Data Fim | F1: Custo(R$) | G1: Cons. | H1: Kit | I1: Regional | J1: Grupo | K1: Poste | L1: Rede AT km | M1: Rede BT km | N1: Medidor | O1: Trafo | P1: Equip. | Q1: VR | R1: Estrato | S1: regionale | T1: NGH | U1: NPH | V1: STATUS | W1: SIGFI | X1: Latitude_UC | Y1: Longitude_UC
A2: 2595147 | B2: POSTO DE SAUDE ALDEIA PALHAL | C2: Vilhena | D2: 45500 | E2: 45500 | F2: 34042.861 | G2: 1 | H2: 1 | J2: 0 | Q2: 144.5618 | R2: 3 | S2: 3 | T2: 187 | U2: 9 | W2: =_xlfn.XLOOKUP(A2,[1]CALCULO_VR!$D:$D,[1]CALCULO_VR!$J:$J) -> 80 | X2: =_xlfn.XLOOKUP(A2,[1]CALCULO_VR!$D:$D,[1]CALCULO_VR!$O:$O) -> -11.479878 | Y2: =_xlfn.XLOOKUP(A2,[1]CALCULO_VR!$D:$D,[1]CALCULO_VR!$P:$P) -> -60.460112
A3: 2595177 | B3: GERSON CINTA LARGA | C3: São Francisco do Guaporé | D3: 45504 | E3: 45504 | F3: 52970.941 | G3: 1 | H3: 1 | J3: 0 | Q3: 70.928033 | R3: 2 | S3: 2 | T3: 225 | U3: 9 | W3: =_xlfn.XLOOKUP(A3,[1]CALCULO_VR!$D:$D,[1]CALCULO_VR!$J:$J) -> 160 | X3: =_xlfn.XLOOKUP(A3,[1]CALCULO_VR!$D:$D,[1]CALCULO_VR!$O:$O) -> -12.408093 | Y3: =_xlfn.XLOOKUP(A3,[1]CALCULO_VR!$D:$D,[1]CALCULO_VR!$P:$P) -> -63.021408
A4: 2595236 | B4: POSTO DE SAUDE ALDEIA CAJUI | C4: São Francisco do Guaporé | D4: 45505 | E4: 45505 | F4: 34042.861 | G4: 1 | H4: 1 | J4: 0 | Q4: 70.937531 | R4: 2 | S4: 2 | T4: 225 | U4: 9 | W4: =_xlfn.XLOOKUP(A4,[1]CALCULO_VR!$D:$D,[1]CALCULO_VR!$J:$J) -> 80 | X4: =_xlfn.XLOOKUP(A4,[1]CALCULO_VR!$D:$D,[1]CALCULO_VR!$O:$O) -> -12.407253 | Y4: =_xlfn.XLOOKUP(A4,[1]CALCULO_VR!$D:$D,[1]CALCULO_VR!$P:$P) -> -63.020755
A5: 2595237 | B5: EIEEFM KON KOATT TUPARI | C5: São Francisco do Guaporé | D5: 45505 | E5: 45505 | F5: 34042.861 | G5: 1 | H5: 1 | J5: 0 | Q5: 70.910302 | R5: 2 | S5: 2 | T5: 225 | U5: 9 | W5: =_xlfn.XLOOKUP(A5,[1]CALCULO_VR!$D:$D,[1]CALCULO_VR!$J:$J) -> 80 | X5: =_xlfn.XLOOKUP(A5,[1]CALCULO_VR!$D:$D,[1]CALCULO_VR!$O:$O) -> -12.40728 | Y5: =_xlfn.XLOOKUP(A5,[1]CALCULO_VR!$D:$D,[1]CALCULO_VR!$P:$P) -> -63.02107
A6: 2595249 | B6: ROSEANE TENHARIN | C6: São Francisco do Guaporé | D6: 45500 | E6: 45500 | F6: 52970.941 | G6: 1 | H6: 1 | J6: 0 | Q6: 90.038796 | R6: 2 | S6: 2 | T6: 225 | U6: 9 | W6: =_xlfn.XLOOKUP(A6,[1]CALCULO_VR!$D:$D,[1]CALCULO_VR!$J:$J) -> 160 | X6: =_xlfn.XLOOKUP(A6,[1]CALCULO_VR!$D:$D,[1]CALCULO_VR!$O:$O) -> -12.34808 | Y6: =_xlfn.XLOOKUP(A6,[1]CALCULO_VR!$D:$D,[1]CALCULO_VR!$P:$P) -> -62.795132
A7: 2595250 | B7: OSMAR MAINTAKA TUPARI | C7: São Francisco do Guaporé | D7: 45500 | E7: 45500 | F7: 52970.941 | G7: 1 | H7: 1 | J7: 0 | Q7: 89.873976 | R7: 2 | S7: 2 | T7: 225 | U7: 9 | V7: Selecionado | W7: =_xlfn.XLOOKUP(A7,[1]CALCULO_VR!$D:$D,[1]CALCULO_VR!$J:$J) -> 160 | X7: =_xlfn.XLOOKUP(A7,[1]CALCULO_VR!$D:$D,[1]CALCULO_VR!$O:$O) -> -12.347225 | Y7: =_xlfn.XLOOKUP(A7,[1]CALCULO_VR!$D:$D,[1]CALCULO_VR!$P:$P) -> -62.796425
A8: 2595269 | B8: EIEEFM KON KOATT TUPARI | C8: São Francisco do Guaporé | D8: 45506 | E8: 45506 | F8: 34042.861 | G8: 1 | H8: 1 | J8: 0 | Q8: 70.974094 | R8: 2 | S8: 2 | T8: 225 | U8: 9 | W8: =_xlfn.XLOOKUP(A8,[1]CALCULO_VR!$D:$D,[1]CALCULO_VR!$J:$J) -> 80 | X8: =_xlfn.XLOOKUP(A8,[1]CALCULO_VR!$D:$D,[1]CALCULO_VR!$O:$O) -> -12.41203 | Y8: =_xlfn.XLOOKUP(A8,[1]CALCULO_VR!$D:$D,[1]CALCULO_VR!$P:$P) -> -63.023502
A9: 2595272 | B9: WALDIR FIRMINO VALE | C9: São Francisco do Guaporé | D9: 45502 | E9: 45502 | F9: 52970.941 | G9: 1 | H9: 1 | J9: 0 | Q9: 89.869751 | R9: 2 | S9: 2 | T9: 225 | U9: 9 | W9: =_xlfn.XLOOKUP(A9,[1]CALCULO_VR!$D:$D,[1]CALCULO_VR!$J:$J) -> 160 | X9: =_xlfn.XLOOKUP(A9,[1]CALCULO_VR!$D:$D,[1]CALCULO_VR!$O:$O) -> -12.347462 | Y9: =_xlfn.XLOOKUP(A9,[1]CALCULO_VR!$D:$D,[1]CALCULO_VR!$P:$P) -> -62.796557
A10: 2583661 | B10: DIVINO GOMES LIMA | C10: Guajará-Mirim | D10: 45459 | E10: 45459 | F10: 34042.861 | G10: 1 | H10: 1 | J10: 0 | Q10: 54.60863 | R10: 1 | S10: 1 | T10: 450 | U10: 27 | W10: =_xlfn.XLOOKUP(A10,[1]CALCULO_VR!$D:$D,[1]CALCULO_VR!$J:$J) -> 80 | X10: =_xlfn.XLOOKUP(A10,[1]CALCULO_VR!$D:$D,[1]CALCULO_VR!$O:$O) -> -10.681757 | Y10: =_xlfn.XLOOKUP(A10,[1]CALCULO_VR!$D:$D,[1]CALCULO_VR!$P:$P) -> -64.832982
A11: 2583662 | B11: JOSE PEREIRA ALVES | C11: Guajará-Mirim | D11: 45458 | E11: 45458 | F11: 34042.861 | G11: 1 | H11: 1 | J11: 0 | Q11: 56.302057 | R11: 1 | S11: 1 | T11: 450 | U11: 27 | W11: =_xlfn.XLOOKUP(A11,[1]CALCULO_VR!$D:$D,[1]CALCULO_VR!$J:$J) -> 80 | X11: =_xlfn.XLOOKUP(A11,[1]CALCULO_VR!$D:$D,[1]CALCULO_VR!$O:$O) -> -10.673628 | Y11: =_xlfn.XLOOKUP(A11,[1]CALCULO_VR!$D:$D,[1]CALCULO_VR!$P:$P) -> -64.818818
A12: 2583663 | B12: ELIETE BIRA MACIEL | C12: Guajará-Mirim | D12: 45459 | E12: 45459 | F12: 34042.861 | G12: 1 | H12: 1 | J12: 0 | Q12: 56.649232 | R12: 1 | S12: 1 | T12: 450 | U12: 27 | W12: =_xlfn.XLOOKUP(A12,[1]CALCULO_VR!$D:$D,[1]CALCULO_VR!$J:$J) -> 80 | X12: =_xlfn.XLOOKUP(A12,[1]CALCULO_VR!$D:$D,[1]CALCULO_VR!$O:$O) -> -10.669567 | Y12: =_xlfn.XLOOKUP(A12,[1]CALCULO_VR!$D:$D,[1]CALCULO_VR!$P:$P) -> -64.816427
A13: 2583664 | B13: JOSE ELEUTERIO FILHO | C13: Guajará-Mirim | D13: 45459 | E13: 45459 | F13: 34042.861 | G13: 1 | H13: 1 | J13: 0 | Q13: 57.074959 | R13: 1 | S13: 1 | T13: 450 | U13: 27 | W13: =_xlfn.XLOOKUP(A13,[1]CALCULO_VR!$D:$D,[1]CALCULO_VR!$J:$J) -> 80 | X13: =_xlfn.XLOOKUP(A13,[1]CALCULO_VR!$D:$D,[1]CALCULO_VR!$O:$O) -> -10.674992 | Y13: =_xlfn.XLOOKUP(A13,[1]CALCULO_VR!$D:$D,[1]CALCULO_VR!$P:$P) -> -64.811327
A14: 2583665 | B14: CARMOZINA FIGUEIREDO DIAS | C14: Guajará-Mirim | D14: 45457 | E14: 45457 | F14: 34042.861 | G14: 1 | H14: 1 | J14: 0 | Q14: 54.358934 | R14: 1 | S14: 1 | T14: 450 | U14: 27 | W14: =_xlfn.XLOOKUP(A14,[1]CALCULO_VR!$D:$D,[1]CALCULO_VR!$J:$J) -> 80 | X14: =_xlfn.XLOOKUP(A14,[1]CALCULO_VR!$D:$D,[1]CALCULO_VR!$O:$O) -> -10.682125 | Y14: =_xlfn.XLOOKUP(A14,[1]CALCULO_VR!$D:$D,[1]CALCULO_VR!$P:$P) -> -64.835237
A15: 2583667 | B15: MARIA IRES DA SILVA RAMOS FERREIRA | C15: Guajará-Mirim | D15: 45458 | E15: 45458 | F15: 34042.861 | G15: 1 | H15: 1 | J15: 0 | Q15: 55.814782 | R15: 1 | S15: 1 | T15: 450 | U15: 27 | W15: =_xlfn.XLOOKUP(A15,[1]CALCULO_VR!$D:$D,[1]CALCULO_VR!$J:$J) -> 80 | X15: =_xlfn.XLOOKUP(A15,[1]CALCULO_VR!$D:$D,[1]CALCULO_VR!$O:$O) -> -10.677553 | Y15: =_xlfn.XLOOKUP(A15,[1]CALCULO_VR!$D:$D,[1]CALCULO_VR!$P:$P) -> -64.822568
A16: 2585819 | B16: DELCILENE ORO MON | C16: Nova Mamoré | D16: 45462 | E16: 45462 | F16: 34042.861 | G16: 1 | H16: 1 | J16: 0 | Q16: 27.565715 | R16: 1 | S16: 1 | T16: 450 | U16: 27 | W16: =_xlfn.XLOOKUP(A16,[1]CALCULO_VR!$D:$D,[1]CALCULO_VR!$J:$J) -> 80 | X16: =_xlfn.XLOOKUP(A16,[1]CALCULO_VR!$D:$D,[1]CALCULO_VR!$O:$O) -> -10.36488 | Y16: =_xlfn.XLOOKUP(A16,[1]CALCULO_VR!$D:$D,[1]CALCULO_VR!$P:$P) -> -65.081663
A17: 2583668 | B17: JOSE CASIMIRO DOS SANTOS | C17: Guajará-Mirim | D17: 45461 | E17: 45461 | F17: 34042.861 | G17: 1 | H17: 1 | J17: 0 | Q17: 60.379099 | R17: 1 | S17: 1 | T17: 450 | U17: 27 | W17: =_xlfn.XLOOKUP(A17,[1]CALCULO_VR!$D:$D,[1]CALCULO_VR!$J:$J) -> 80 | X17: =_xlfn.XLOOKUP(A17,[1]CALCULO_VR!$D:$D,[1]CALCULO_VR!$O:$O) -> -10.640712 | Y17: =_xlfn.XLOOKUP(A17,[1]CALCULO_VR!$D:$D,[1]CALCULO_VR!$P:$P) -> -64.788205
A18: 2583702 | B18: IRACEMA DA SILVA GOMES | C18: Guajará-Mirim | D18: 45458 | E18: 45458 | F18: 34042.861 | G18: 1 | H18: 1 | J18: 0 | Q18: 54.615242 | R18: 1 | S18: 1 | T18: 450 | U18: 27 | W18: =_xlfn.XLOOKUP(A18,[1]CALCULO_VR!$D:$D,[1]CALCULO_VR!$J:$J) -> 80 | X18: =_xlfn.XLOOKUP(A18,[1]CALCULO_VR!$D:$D,[1]CALCULO_VR!$O:$O) -> -10.681718 | Y18: =_xlfn.XLOOKUP(A18,[1]CALCULO_VR!$D:$D,[1]CALCULO_VR!$P:$P) -> -64.832928
A19: 2583669 | B19: CICERO MACIEL DO NASCIMENTO | C19: Guajará-Mirim | D19: 45459 | E19: 45459 | F19: 34042.861 | G19: 1 | H19: 1 | J19: 0 | Q19: 57.711664 | R19: 1 | S19: 1 | T19: 450 | U19: 27 | W19: =_xlfn.XLOOKUP(A19,[1]CALCULO_VR!$D:$D,[1]CALCULO_VR!$J:$J) -> 80 | X19: =_xlfn.XLOOKUP(A19,[1]CALCULO_VR!$D:$D,[1]CALCULO_VR!$O:$O) -> -10.672623 | Y19: =_xlfn.XLOOKUP(A19,[1]CALCULO_VR!$D:$D,[1]CALCULO_VR!$P:$P) -> -64.805865
... A21: 2583410 | B21: FRANCISCO ASSIS DE ALMEIDA | C21: Guajará-Mirim | D21: 45459 | E21: 45459 | F21: 34042.861 | G21: 1 | H21: 1 | J21: 0 | Q21: 57.249923 | R21: 1 | S21: 1 | T21: 450 | U21: 27 | W21: =_xlfn.XLOOKUP(A21,[1]CALCULO_VR!$D:$D,[1]CALCULO_VR!$J:$J) -> 80 | X21: =_xlfn.XLOOKUP(A21,[1]CALCULO_VR!$D:$D,[1]CALCULO_VR!$O:$O) -> -10.673652 | Y21: =_xlfn.XLOOKUP(A21,[1]CALCULO_VR!$D:$D,[1]CALCULO_VR!$P:$P) -> -64.809965
A22: 2583920 | B22: ESCOLA ENSINO FUNDAMENTAL VALDEMAR CABIXI | C22: Guajará-Mirim | D22: 45455 | E22: 45455 | F22: 34042.861 | G22: 1 | H22: 1 | J22: 0 | Q22: 129.99808 | R22: 3 | S22: 3 | T22: 187 | U22: 9 | V22: Selecionado | W22: =_xlfn.XLOOKUP(A22,[1]CALCULO_VR!$D:$D,[1]CALCULO_VR!$J:$J) -> 80 | X22: =_xlfn.XLOOKUP(A22,[1]CALCULO_VR!$D:$D,[1]CALCULO_VR!$O:$O) -> -11.15186 | Y22: =_xlfn.XLOOKUP(A22,[1]CALCULO_VR!$D:$D,[1]CALCULO_VR!$P:$P) -> -64.19707
A23: 2583764 | B23: EVERLANI ORO WIN | C23: Guajará-Mirim | D23: 45456 | E23: 45456 | F23: 34042.861 | G23: 1 | H23: 1 | J23: 0 | Q23: 130.13093 | R23: 3 | S23: 3 | T23: 187 | U23: 9 | W23: =_xlfn.XLOOKUP(A23,[1]CALCULO_VR!$D:$D,[1]CALCULO_VR!$J:$J) -> 80 | X23: =_xlfn.XLOOKUP(A23,[1]CALCULO_VR!$D:$D,[1]CALCULO_VR!$O:$O) -> -11.150538 | Y23: =_xlfn.XLOOKUP(A23,[1]CALCULO_VR!$D:$D,[1]CALCULO_VR!$P:$P) -> -64.195328
A24: 2583766 | B24: WELINTON CABIXI MACURAP | C24: Guajará-Mirim | D24: 45456 | E24: 45456 | F24: 34042.861 | G24: 1 | H24: 1 | J24: 0 | Q24: 129.95073 | R24: 3 | S24: 3 | T24: 187 | U24: 9 | W24: =_xlfn.XLOOKUP(A24,[1]CALCULO_VR!$D:$D,[1]CALCULO_VR!$J:$J) -> 80 | X24: =_xlfn.XLOOKUP(A24,[1]CALCULO_VR!$D:$D,[1]CALCULO_VR!$O:$O) -> -11.152557 | Y24: =_xlfn.XLOOKUP(A24,[1]CALCULO_VR!$D:$D,[1]CALCULO_VR!$P:$P) -> -64.19777
A25: 2583767 | B25: FABRICIO ORO NAO CABIXI | C25: Guajará-Mirim | D25: 45457 | E25: 45457 | F25: 34042.861 | G25: 1 | H25: 1 | J25: 0 | Q25: 130.05216 | R25: 3 | S25: 3 | T25: 187 | U25: 9 | W25: =_xlfn.XLOOKUP(A25,[1]CALCULO_VR!$D:$D,[1]CALCULO_VR!$J:$J) -> 80 | X25: =_xlfn.XLOOKUP(A25,[1]CALCULO_VR!$D:$D,[1]CALCULO_VR!$O:$O) -> -11.15322 | Y25: =_xlfn.XLOOKUP(A25,[1]CALCULO_VR!$D:$D,[1]CALCULO_VR!$P:$P) -> -64.197018
A26: 2583768 | B26: TANIA ORO WIN CABIXI | C26: Guajará-Mirim | D26: 45457 | E26: 45457 | F26: 34042.861 | G26: 1 | H26: 1 | J26: 0 | Q26: 130.05496 | R26: 3 | S26: 3 | T26: 187 | U26: 9 | W26: =_xlfn.XLOOKUP(A26,[1]CALCULO_VR!$D:$D,[1]CALCULO_VR!$J:$J) -> 80 | X26: =_xlfn.XLOOKUP(A26,[1]CALCULO_VR!$D:$D,[1]CALCULO_VR!$O:$O) -> -11.154017 | Y26: =_xlfn.XLOOKUP(A26,[1]CALCULO_VR!$D:$D,[1]CALCULO_VR!$P:$P) -> -64.197268
A27: 2583769 | B27: ELIENETE ORO NAO CABIXI | C27: Guajará-Mirim | D27: 45457 | E27: 45457 | F27: 34042.861 | G27: 1 | H27: 1 | J27: 0 | Q27: 129.97582 | R27: 3 | S27: 3 | T27: 187 | U27: 9 | W27: =_xlfn.XLOOKUP(A27,[1]CALCULO_VR!$D:$D,[1]CALCULO_VR!$J:$J) -> 80 | X27: =_xlfn.XLOOKUP(A27,[1]CALCULO_VR!$D:$D,[1]CALCULO_VR!$O:$O) -> -11.148292 | Y27: =_xlfn.XLOOKUP(A27,[1]CALCULO_VR!$D:$D,[1]CALCULO_VR!$P:$P) -> -64.196057
A28: 2583770 | B28: ROMARIO ORO WIN | C28: Guajará-Mirim | D28: 45457 | E28: 45457 | F28: 34042.861 | G28: 1 | H28: 1 | J28: 0 | Q28: 130.04754 | R28: 3 | S28: 3 | T28: 187 | U28: 9 | W28: =_xlfn.XLOOKUP(A28,[1]CALCULO_VR!$D:$D,[1]CALCULO_VR!$J:$J) -> 80 | X28: =_xlfn.XLOOKUP(A28,[1]CALCULO_VR!$D:$D,[1]CALCULO_VR!$O:$O) -> -11.153937 | Y28: =_xlfn.XLOOKUP(A28,[1]CALCULO_VR!$D:$D,[1]CALCULO_VR!$P:$P) -> -64.197312
A29: 2585862 | B29: ROSILEIA ORO MON | C29: Nova Mamoré | D29: 45462 | E29: 45462 | F29: 34042.861 | G29: 1 | H29: 1 | J29: 0 | Q29: 27.487788 | R29: 1 | S29: 1 | T29: 450 | U29: 27 | W29: =_xlfn.XLOOKUP(A29,[1]CALCULO_VR!$D:$D,[1]CALCULO_VR!$J:$J) -> 80 | X29: =_xlfn.XLOOKUP(A29,[1]CALCULO_VR!$D:$D,[1]CALCULO_VR!$O:$O) -> -10.365348 | Y29: =_xlfn.XLOOKUP(A29,[1]CALCULO_VR!$D:$D,[1]CALCULO_VR!$P:$P) -> -65.082297
A30: 2583772 | B30: JOEL DA SILVA PANTOJA | C30: Guajará-Mirim | D30: 45457 | E30: 45457 | F30: 34042.861 | G30: 1 | H30: 1 | J30: 0 | Q30: 130.1332 | R30: 3 | S30: 3 | T30: 187 | U30: 9 | W30: =_xlfn.XLOOKUP(A30,[1]CALCULO_VR!$D:$D,[1]CALCULO_VR!$J:$J) -> 80 | X30: =_xlfn.XLOOKUP(A30,[1]CALCULO_VR!$D:$D,[1]CALCULO_VR!$O:$O) -> -11.150477 | Y30: =_xlfn.XLOOKUP(A30,[1]CALCULO_VR!$D:$D,[1]CALCULO_VR!$P:$P) -> -64.195285
A31: 2585863 | B31: REGIANE ORO MON | C31: Nova Mamoré | D31: 45462 | E31: 45462 | F31: 34042.861 | G31: 1 | H31: 1 | J31: 0 | Q31: 27.499203 | R31: 1 | S31: 1 | T31: 450 | U31: 27 | W31: =_xlfn.XLOOKUP(A31,[1]CALCULO_VR!$D:$D,[1]CALCULO_VR!$J:$J) -> 80 | X31: =_xlfn.XLOOKUP(A31,[1]CALCULO_VR!$D:$D,[1]CALCULO_VR!$O:$O) -> -10.364902 | Y31: =_xlfn.XLOOKUP(A31,[1]CALCULO_VR!$D:$D,[1]CALCULO_VR!$P:$P) -> -65.082278
A32: 2583659 | B32: RICARDO BORGES DE AMORIM | C32: Guajará-Mirim | D32: 45462 | E32: 45462 | F32: 34042.861 | G32: 1 | H32: 1 | J32: 0 | Q32: 114.8648 | R32: 3 | S32: 3 | T32: 187 | U32: 9 | W32: =_xlfn.XLOOKUP(A32,[1]CALCULO_VR!$D:$D,[1]CALCULO_VR!$J:$J) -> 80 | X32: =_xlfn.XLOOKUP(A32,[1]CALCULO_VR!$D:$D,[1]CALCULO_VR!$O:$O) -> -11.211737 | Y32: =_xlfn.XLOOKUP(A32,[1]CALCULO_VR!$D:$D,[1]CALCULO_VR!$P:$P) -> -64.370842
A33: 2583774 | B33: LUIZA ORO NAO | C33: Guajará-Mirim | D33: 45462 | E33: 45462 | F33: 34042.861 | G33: 1 | H33: 1 | J33: 0 | Q33: 129.40783 | R33: 3 | S33: 3 | T33: 187 | U33: 9 | W33: =_xlfn.XLOOKUP(A33,[1]CALCULO_VR!$D:$D,[1]CALCULO_VR!$J:$J) -> 80 | X33: =_xlfn.XLOOKUP(A33,[1]CALCULO_VR!$D:$D,[1]CALCULO_VR!$O:$O) -> -11.17219 | Y33: =_xlfn.XLOOKUP(A33,[1]CALCULO_VR!$D:$D,[1]CALCULO_VR!$P:$P) -> -64.210073
A34: 2585864 | B34: FRANCIMAR ORO WARAM XIJEIN | C34: Nova Mamoré | D34: 45463 | E34: 45463 | F34: 34042.861 | G34: 1 | H34: 1 | J34: 0 | Q34: 27.553453 | R34: 1 | S34: 1 | T34: 450 | U34: 27 | W34: =_xlfn.XLOOKUP(A34,[1]CALCULO_VR!$D:$D,[1]CALCULO_VR!$J:$J) -> 80 | X34: =_xlfn.XLOOKUP(A34,[1]CALCULO_VR!$D:$D,[1]CALCULO_VR!$O:$O) -> -10.366462 | Y34: =_xlfn.XLOOKUP(A34,[1]CALCULO_VR!$D:$D,[1]CALCULO_VR!$P:$P) -> -65.081472
... A59: 2583922 | B59: ESCOLA JOAO FARIAS DE BARROS | C59: Guajará-Mirim | D59: 45460 | E59: 45460 | F59: 34042.861 | G59: 1 | H59: 1 | J59: 0 | Q59: 140.12685 | R59: 3 | S59: 3 | T59: 187 | U59: 9 | W59: =_xlfn.XLOOKUP(A59,[1]CALCULO_VR!$D:$D,[1]CALCULO_VR!$J:$J) -> 80 | X59: =_xlfn.XLOOKUP(A59,[1]CALCULO_VR!$D:$D,[1]CALCULO_VR!$O:$O) -> -11.087058 | Y59: =_xlfn.XLOOKUP(A59,[1]CALCULO_VR!$D:$D,[1]CALCULO_VR!$P:$P) -> -64.080738
A60: 2583788 | B60: SILVANA KARITIANA | C60: Porto Velho | D60: 45468 | E60: 45468 | F60: 34042.861 | G60: 1 | H60: 1 | J60: 0 | Q60: 48.832983 | R60: 1 | S60: 1 | T60: 450 | U60: 27 | V60: Selecionado | W60: =_xlfn.XLOOKUP(A60,[1]CALCULO_VR!$D:$D,[1]CALCULO_VR!$J:$J) -> 80 | X60: =_xlfn.XLOOKUP(A60,[1]CALCULO_VR!$D:$D,[1]CALCULO_VR!$O:$O) -> -9.192673 | Y60: =_xlfn.XLOOKUP(A60,[1]CALCULO_VR!$D:$D,[1]CALCULO_VR!$P:$P) -> -63.948097
A61: 2583789 | B61: GEICILENE ORO JOWIN | C61: Guajará-Mirim | D61: 45460 | E61: 45460 | F61: 34042.861 | G61: 1 | H61: 1 | J61: 0 | Q61: 140.19906 | R61: 3 | S61: 3 | T61: 187 | U61: 9 | W61: =_xlfn.XLOOKUP(A61,[1]CALCULO_VR!$D:$D,[1]CALCULO_VR!$J:$J) -> 80 | X61: =_xlfn.XLOOKUP(A61,[1]CALCULO_VR!$D:$D,[1]CALCULO_VR!$O:$O) -> -11.087127 | Y61: =_xlfn.XLOOKUP(A61,[1]CALCULO_VR!$D:$D,[1]CALCULO_VR!$P:$P) -> -64.080073
A62: 2583790 | B62: ROSENDA FERREIRA INUMA | C62: Guajará-Mirim | D62: 45469 | E62: 45469 | F62: 34042.861 | G62: 1 | H62: 1 | J62: 0 | Q62: 94.114195 | R62: 2 | S62: 2 | T62: 225 | U62: 9 | W62: =_xlfn.XLOOKUP(A62,[1]CALCULO_VR!$D:$D,[1]CALCULO_VR!$J:$J) -> 80 | X62: =_xlfn.XLOOKUP(A62,[1]CALCULO_VR!$D:$D,[1]CALCULO_VR!$O:$O) -> -11.380303 | Y62: =_xlfn.XLOOKUP(A62,[1]CALCULO_VR!$D:$D,[1]CALCULO_VR!$P:$P) -> -64.72229
A63: 2583791 | B63: NEIDE MORAIS KARITIANA LOPES | C63: Porto Velho | D63: 45469 | E63: 45469 | F63: 34042.861 | G63: 1 | H63: 1 | J63: 0 | Q63: 66.468637 | R63: 1 | S63: 1 | T63: 450 | U63: 27 | W63: =_xlfn.XLOOKUP(A63,[1]CALCULO_VR!$D:$D,[1]CALCULO_VR!$J:$J) -> 80 | X63: =_xlfn.XLOOKUP(A63,[1]CALCULO_VR!$D:$D,[1]CALCULO_VR!$O:$O) -> -9.320778 | Y63: =_xlfn.XLOOKUP(A63,[1]CALCULO_VR!$D:$D,[1]CALCULO_VR!$P:$P) -> -64.064005
A64: 2583792 | B64: JOAO FERREIRA LOPES | C64: Guajará-Mirim | D64: 45468 | E64: 45468 | F64: 34042.861 | G64: 1 | H64: 1 | J64: 0 | Q64: 86.782843 | R64: 2 | S64: 2 | T64: 225 | U64: 9 | W64: =_xlfn.XLOOKUP(A64,[1]CALCULO_VR!$D:$D,[1]CALCULO_VR!$J:$J) -> 80 | X64: =_xlfn.XLOOKUP(A64,[1]CALCULO_VR!$D:$D,[1]CALCULO_VR!$O:$O) -> -11.353395 | Y64: =_xlfn.XLOOKUP(A64,[1]CALCULO_VR!$D:$D,[1]CALCULO_VR!$P:$P) -> -64.791288
A65: 2583923 | B65: ESCOLA INDIGENA NYJNYJI | C65: Porto Velho | D65: 45469 | E65: 45469 | F65: 34042.861 | G65: 1 | H65: 1 | J65: 0 | Q65: 66.366 | R65: 1 | S65: 1 | T65: 450 | U65: 27 | W65: =_xlfn.XLOOKUP(A65,[1]CALCULO_VR!$D:$D,[1]CALCULO_VR!$J:$J) -> 80 | X65: =_xlfn.XLOOKUP(A65,[1]CALCULO_VR!$D:$D,[1]CALCULO_VR!$O:$O) -> -9.32021 | Y65: =_xlfn.XLOOKUP(A65,[1]CALCULO_VR!$D:$D,[1]CALCULO_VR!$P:$P) -> -64.062953
...

Sheet Planilha2
A1: UC | B1: Projeto | C1: Município | D1: SIGFI | E1: Latitude | F1: Longitude
A2: 2595250 | B2: OSMAR MAINTAKA TUPARI | C2: São Francisco do Guaporé | D2: 160 | E2: -12.347225 | F2: -62.796425
A3: 2583920 | B3: ESCOLA ENSINO FUNDAMENTAL VALDEMAR CABIXI | C3: Guajará-Mirim | D3: 80 | E3: -11.15186 | F3: -64.19707
A4: 2583788 | B4: SILVANA KARITIANA | C4: Porto Velho | D4: 80 | E4: -9.192673 | F4: -63.948097
A5: 2583928 | B5: ESCOLA INDIGINA ESTADUAL DE ENSINO | C5: Porto Velho | D5: 80 | E5: -9.192465 | F5: -63.94769
A6: 2583826 | B6: SALOMAO ORO WIN | C6: Guajará-Mirim | D6: 80 | E6: -11.086663 | F6: -64.080385
A7: 2585878 | B7: ANGELINA ORO MON | C7: Nova Mamoré | D7: 80 | E7: -10.368292 | F7: -65.081318
A8: 2583675 | B8: ALDELINNO FIRMINO NEVES | C8: Guajará-Mirim | D8: 80 | E8: -10.680527 | F8: -64.813467
A9: 2583679 | B9: EULIDES BRASIL DA SILVA | C9: Guajará-Mirim | D9: 80 | E9: -10.685668 | F9: -64.806282
A10: 2583936 | B10: POSTO DE SAUDE ALDEIA CRISTO REI | C10: Guajará-Mirim | D10: 80 | E10: -11.121872 | F10: -64.145563
A11: 2583880 | B11: RAIMUNDO DURAES PEREIRA DA SILVA | C11: Guajará-Mirim | D11: 80 | E11: -10.955988 | F11: -65.267307
A12: 2583904 | B12: MARIA DEL CARMEN RUIZ ARAUZ | C12: Guajará-Mirim | D12: 80 | E12: -10.949367 | F12: -65.26786
A13: 2595017 | B13: MIRIAN MACURAP | C13: Guajará-Mirim | D13: 80 | E13: -12.029373 | F13: -64.805922
... A46: 2787454 | B46: ELIENAI ROSALINO DA SILVA FERNANDES | C46: Vilhena | D46: 80 | E46: -12.513032 | F46: -60.269265

Sheet Planilha3
A1: UC | B1: Projeto | C1: Município | D1: SIGFI | E1: Latitude | F1: Longitude
A2: 2583701 | B2: MARIA LILIA OLIVEIRA GONCALVES | C2: Guajará-Mirim | D2: 80 | E2: -11.20843 | F2: -64.80945
A3: 2583802 | B3: RAIMUNDO NONATO KARITIANA | C3: Porto Velho | D3: 80 | E3: -9.191817 | F3: -63.947215
A4: 2583810 | B4: JEAN ORO WARAM | C4: Guajará-Mirim | D4: 80 | E4: -11.087268 | F4: -64.079673
A5: 2583839 | B5: ALEX FRANCISCO DELGADO PIN KARITIANA | C5: Porto Velho | D5: 80 | E5: -9.440863 | F5: -64.197193
A6: 2583862 | B6: TANGAE URU EU WAU WAU DE OLIVEIRA | C6: Porto Velho | D6: 80 | E6: -9.754347 | F6: -64.31926
A7: 2583873 | B7: SERGIO ORO WIN CABIXI | C7: Guajará-Mirim | D7: 80 | E7: -11.15165 | F7: -64.196308
A8: 2583705 | B8: CLEONICE MASSAKA | C8: Guajará-Mirim | D8: 80 | E8: -11.08904 | F8: -65.278228
A9: 2595137 | B9: VALDEIR SEV KALAV GAVIAO | C9: Ji-Paraná | D9: 80 | E9: -10.712018 | F9: -61.599498
A10: 2595287 | B10: ANTONIO BORTONE NETO DIAS | C10: Pimenta Bueno | D10: 80 | E10: -12.243135 | F10: -60.396132
A11: 2595585 | B11: DIVA CINTA LARGA | C11: Espigão D'Oeste | D11: 80 | E11: -11.357113 | F11: -60.556003
A12: 2614648 | B12: VALDIR CHEREMBOMBAL GAVIAO | C12: Ji-Paraná | D12: 80 | E12: -10.434537 | F12: -61.65337
A13: 2629576 | B13: NATANAEL JESUS DO VALE SANTOS | C13: Cujubim | D13: 80 | E13: -8.851893 | F13: -62.35451
... A23: 2787427 | B23: DEIVIDE STEFANI CACULA ARCOVERDE | C23: Vilhena | D23: 80 | E23: -12.525523 | F23: -60.265687

Sheet Amostra 1_4_extrato_erro_5%
A1: UC | B1: Projeto | C1: Município | D1: Data Inicio | E1: Data Fim | F1: Custo(R$) | G1: Cons. | H1: Kit | I1: Regional | J1: Grupo | K1: Poste | L1: Rede AT km | M1: Rede BT km | N1: Medidor | O1: Trafo | P1: Equip. | Q1: VR | R1: Estrato | S1: regionale | T1: NGH | U1: NPH | V1: STATUS | W1: SIGFI | X1: Latitude_UC | Y1: Longitude_UC
A2: 2595147 | B2: POSTO DE SAUDE ALDEIA PALHAL | C2: Vilhena | D2: 45500 | E2: 45500 | F2: 34042.861 | G2: 1 | H2: 1 | J2: 0 | Q2: 144.5618 | R2: 4 | S2: 4 | T2: 163 | U2: 5 | W2: =_xlfn.XLOOKUP(A2,[1]CALCULO_VR!$D:$D,[1]CALCULO_VR!$J:$J) -> 80 | X2: =_xlfn.XLOOKUP(A2,[1]CALCULO_VR!$D:$D,[1]CALCULO_VR!$O:$O) -> -11.479878 | Y2: =_xlfn.XLOOKUP(A2,[1]CALCULO_VR!$D:$D,[1]CALCULO_VR!$P:$P) -> -60.460112
A3: 2595177 | B3: GERSON CINTA LARGA | C3: São Francisco do Guaporé | D3: 45504 | E3: 45504 | F3: 52970.941 | G3: 1 | H3: 1 | J3: 0 | Q3: 70.928033 | R3: 2 | S3: 2 | T3: 251 | U3: 5 | W3: =_xlfn.XLOOKUP(A3,[1]CALCULO_VR!$D:$D,[1]CALCULO_VR!$J:$J) -> 160 | X3: =_xlfn.XLOOKUP(A3,[1]CALCULO_VR!$D:$D,[1]CALCULO_VR!$O:$O) -> -12.408093 | Y3: =_xlfn.XLOOKUP(A3,[1]CALCULO_VR!$D:$D,[1]CALCULO_VR!$P:$P) -> -63.021408
A4: 2595236 | B4: POSTO DE SAUDE ALDEIA CAJUI | C4: São Francisco do Guaporé | D4: 45505 | E4: 45505 | F4: 34042.861 | G4: 1 | H4: 1 | J4: 0 | Q4: 70.937531 | R4: 2 | S4: 2 | T4: 251 | U4: 5 | W4: =_xlfn.XLOOKUP(A4,[1]CALCULO_VR!$D:$D,[1]CALCULO_VR!$J:$J) -> 80 | X4: =_xlfn.XLOOKUP(A4,[1]CALCULO_VR!$D:$D,[1]CALCULO_VR!$O:$O) -> -12.407253 | Y4: =_xlfn.XLOOKUP(A4,[1]CALCULO_VR!$D:$D,[1]CALCULO_VR!$P:$P) -> -63.020755
A5: 2595237 | B5: EIEEFM KON KOATT TUPARI | C5: São Francisco do Guaporé | D5: 45505 | E5: 45505 | F5: 34042.861 | G5: 1 | H5: 1 | J5: 0 | Q5: 70.910302 | R5: 2 | S5: 2 | T5: 251 | U5: 5 | W5: =_xlfn.XLOOKUP(A5,[1]CALCULO_VR!$D:$D,[1]CALCULO_VR!$J:$J) -> 80 | X5: =_xlfn.XLOOKUP(A5,[1]CALCULO_VR!$D:$D,[1]CALCULO_VR!$O:$O) -> -12.40728 | Y5: =_xlfn.XLOOKUP(A5,[1]CALCULO_VR!$D:$D,[1]CALCULO_VR!$P:$P) -> -63.02107
A6: 2595249 | B6: ROSEANE TENHARIN | C6: São Francisco do Guaporé | D6: 45500 | E6: 45500 | F6: 52970.941 | G6: 1 | H6: 1 | J6: 0 | Q6: 90.038796 | R6: 3 | S6: 3 | T6: 223 | U6: 6 | W6: =_xlfn.XLOOKUP(A6,[1]CALCULO_VR!$D:$D,[1]CALCULO_VR!$J:$J) -> 160 | X6: =_xlfn.XLOOKUP(A6,[1]CALCULO_VR!$D:$D,[1]CALCULO_VR!$O:$O) -> -12.34808 | Y6: =_xlfn.XLOOKUP(A6,[1]CALCULO_VR!$D:$D,[1]CALCULO_VR!$P:$P) -> -62.795132
A7: 2595250 | B7: OSMAR MAINTAKA TUPARI | C7: São Francisco do Guaporé | D7: 45500 | E7: 45500 | F7: 52970.941 | G7: 1 | H7: 1 | J7: 0 | Q7: 89.873976 | R7: 3 | S7: 3 | T7: 223 | U7: 6 | W7: =_xlfn.XLOOKUP(A7,[1]CALCULO_VR!$D:$D,[1]CALCULO_VR!$J:$J) -> 160 | X7: =_xlfn.XLOOKUP(A7,[1]CALCULO_VR!$D:$D,[1]CALCULO_VR!$O:$O) -> -12.347225 | Y7: =_xlfn.XLOOKUP(A7,[1]CALCULO_VR!$D:$D,[1]CALCULO_VR!$P:$P) -> -62.796425
A8: 2595269 | B8: EIEEFM KON KOATT TUPARI | C8: São Francisco do Guaporé | D8: 45506 | E8: 45506 | F8: 34042.861 | G8: 1 | H8: 1 | J8: 0 | Q8: 70.974094 | R8: 2 | S8: 2 | T8: 251 | U8: 5 | W8: =_xlfn.XLOOKUP(A8,[1]CALCULO_VR!$D:$D,[1]CALCULO_VR!$J:$J) -> 80 | X8: =_xlfn.XLOOKUP(A8,[1]CALCULO_VR!$D:$D,[1]CALCULO_VR!$O:$O) -> -12.41203 | Y8: =_xlfn.XLOOKUP(A8,[1]CALCULO_VR!$D:$D,[1]CALCULO_VR!$P:$P) -> -63.023502
A9: 2595272 | B9: WALDIR FIRMINO VALE | C9: São Francisco do Guaporé | D9: 45502 | E9: 45502 | F9: 52970.941 | G9: 1 | H9: 1 | J9: 0 | Q9: 89.869751 | R9: 3 | S9: 3 | T9: 223 | U9: 6 | W9: =_xlfn.XLOOKUP(A9,[1]CALCULO_VR!$D:$D,[1]CALCULO_VR!$J:$J) -> 160 | X9: =_xlfn.XLOOKUP(A9,[1]CALCULO_VR!$D:$D,[1]CALCULO_VR!$O:$O) -> -12.347462 | Y9: =_xlfn.XLOOKUP(A9,[1]CALCULO_VR!$D:$D,[1]CALCULO_VR!$P:$P) -> -62.796557
A10: 2583661 | B10: DIVINO GOMES LIMA | C10: Guajará-Mirim | D10: 45459 | E10: 45459 | F10: 34042.861 | G10: 1 | H10: 1 | J10: 0 | Q10: 54.60863 | R10: 2 | S10: 2 | T10: 251 | U10: 5 | W10: =_xlfn.XLOOKUP(A10,[1]CALCULO_VR!$D:$D,[1]CALCULO_VR!$J:$J) -> 80 | X10: =_xlfn.XLOOKUP(A10,[1]CALCULO_VR!$D:$D,[1]CALCULO_VR!$O:$O) -> -10.681757 | Y10: =_xlfn.XLOOKUP(A10,[1]CALCULO_VR!$D:$D,[1]CALCULO_VR!$P:$P) -> -64.832982
A11: 2583662 | B11: JOSE PEREIRA ALVES | C11: Guajará-Mirim | D11: 45458 | E11: 45458 | F11: 34042.861 | G11: 1 | H11: 1 | J11: 0 | Q11: 56.302057 | R11: 2 | S11: 2 | T11: 251 | U11: 5 | W11: =_xlfn.XLOOKUP(A11,[1]CALCULO_VR!$D:$D,[1]CALCULO_VR!$J:$J) -> 80 | X11: =_xlfn.XLOOKUP(A11,[1]CALCULO_VR!$D:$D,[1]CALCULO_VR!$O:$O) -> -10.673628 | Y11: =_xlfn.XLOOKUP(A11,[1]CALCULO_VR!$D:$D,[1]CALCULO_VR!$P:$P) -> -64.818818
A12: 2583663 | B12: ELIETE BIRA MACIEL | C12: Guajará-Mirim | D12: 45459 | E12: 45459 | F12: 34042.861 | G12: 1 | H12: 1 | J12: 0 | Q12: 56.649232 | R12: 2 | S12: 2 | T12: 251 | U12: 5 | W12: =_xlfn.XLOOKUP(A12,[1]CALCULO_VR!$D:$D,[1]CALCULO_VR!$J:$J) -> 80 | X12: =_xlfn.XLOOKUP(A12,[1]CALCULO_VR!$D:$D,[1]CALCULO_VR!$O:$O) -> -10.669567 | Y12: =_xlfn.XLOOKUP(A12,[1]CALCULO_VR!$D:$D,[1]CALCULO_VR!$P:$P) -> -64.816427
A13: 2583664 | B13: JOSE ELEUTERIO FILHO | C13: Guajará-Mirim | D13: 45459 | E13: 45459 | F13: 34042.861 | G13: 1 | H13: 1 | J13: 0 | Q13: 57.074959 | R13: 2 | S13: 2 | T13: 251 | U13: 5 | W13: =_xlfn.XLOOKUP(A13,[1]CALCULO_VR!$D:$D,[1]CALCULO_VR!$J:$J) -> 80 | X13: =_xlfn.XLOOKUP(A13,[1]CALCULO_VR!$D:$D,[1]CALCULO_VR!$O:$O) -> -10.674992 | Y13: =_xlfn.XLOOKUP(A13,[1]CALCULO_VR!$D:$D,[1]CALCULO_VR!$P:$P) -> -64.811327
... A54: 2583787 | B54: FRANCIELE PAMOTO KARITIANA | C54: Porto Velho | D54: 45468 | E54: 45468 | F54: 34042.861 | G54: 1 | H54: 1 | J54: 0 | Q54: 48.789481 | R54: 2 | S54: 2 | T54: 251 | U54: 5 | W54: =_xlfn.XLOOKUP(A54,[1]CALCULO_VR!$D:$D,[1]CALCULO_VR!$J:$J) -> 80 | X54: =_xlfn.XLOOKUP(A54,[1]CALCULO_VR!$D:$D,[1]CALCULO_VR!$O:$O) -> -9.192407 | Y54: =_xlfn.XLOOKUP(A54,[1]CALCULO_VR!$D:$D,[1]CALCULO_VR!$P:$P) -> -63.947577
A55: 2583701 | B55: MARIA LILIA OLIVEIRA GONCALVES | C55: Guajará-Mirim | D55: 45467 | E55: 45467 | F55: 34042.861 | G55: 1 | H55: 1 | J55: 0 | Q55: 74.086101 | R55: 2 | S55: 2 | T55: 251 | U55: 5 | V55: Selecionado | W55: =_xlfn.XLOOKUP(A55,[1]CALCULO_VR!$D:$D,[1]CALCULO_VR!$J:$J) -> 80 | X55: =_xlfn.XLOOKUP(A55,[1]CALCULO_VR!$D:$D,[1]CALCULO_VR!$O:$O) -> -11.20843 | Y55: =_xlfn.XLOOKUP(A55,[1]CALCULO_VR!$D:$D,[1]CALCULO_VR!$P:$P) -> -64.80945
A56: 2583921 | B56: POSTO DE SAUDE ALDEIA SAO LUIZ | C56: Guajará-Mirim | D56: 45460 | E56: 45460 | F56: 34042.861 | G56: 1 | H56: 1 | J56: 0 | Q56: 140.19241 | R56: 4 | S56: 4 | T56: 163 | U56: 5 | W56: =_xlfn.XLOOKUP(A56,[1]CALCULO_VR!$D:$D,[1]CALCULO_VR!$J:$J) -> 80 | X56: =_xlfn.XLOOKUP(A56,[1]CALCULO_VR!$D:$D,[1]CALCULO_VR!$O:$O) -> -11.085762 | Y56: =_xlfn.XLOOKUP(A56,[1]CALCULO_VR!$D:$D,[1]CALCULO_VR!$P:$P) -> -64.079783
A57: 2583685 | B57: WALDEMIR LOPES DE AMORIM | C57: Guajará-Mirim | D57: 45464 | E57: 45464 | F57: 34042.861 | G57: 1 | H57: 1 | J57: 0 | Q57: 65.495643 | R57: 2 | S57: 2 | T57: 251 | U57: 5 | W57: =_xlfn.XLOOKUP(A57,[1]CALCULO_VR!$D:$D,[1]CALCULO_VR!$J:$J) -> 80 | X57: =_xlfn.XLOOKUP(A57,[1]CALCULO_VR!$D:$D,[1]CALCULO_VR!$O:$O) -> -11.200607 | Y57: =_xlfn.XLOOKUP(A57,[1]CALCULO_VR!$D:$D,[1]CALCULO_VR!$P:$P) -> -64.910355
A58: 2583686 | B58: JOSE MARIA DE SOUZA RUFINO | C58: Guajará-Mirim | D58: 45464 | E58: 45464 | F58: 34042.861 | G58: 1 | H58: 1 | J58: 0 | Q58: 65.745664 | R58: 2 | S58: 2 | T58: 251 | U58: 5 | W58: =_xlfn.XLOOKUP(A58,[1]CALCULO_VR!$D:$D,[1]CALCULO_VR!$J:$J) -> 80 | X58: =_xlfn.XLOOKUP(A58,[1]CALCULO_VR!$D:$D,[1]CALCULO_VR!$O:$O) -> -11.198337 | Y58: =_xlfn.XLOOKUP(A58,[1]CALCULO_VR!$D:$D,[1]CALCULO_VR!$P:$P) -> -64.904643
A59: 2583922 | B59: ESCOLA JOAO FARIAS DE BARROS | C59: Guajará-Mirim | D59: 45460 | E59: 45460 | F59: 34042.861 | G59: 1 | H59: 1 | J59: 0 | Q59: 140.12685 | R59: 4 | S59: 4 | T59: 163 | U59: 5 | W59: =_xlfn.XLOOKUP(A59,[1]CALCULO_VR!$D:$D,[1]CALCULO_VR!$J:$J) -> 80 | X59: =_xlfn.XLOOKUP(A59,[1]CALCULO_VR!$D:$D,[1]CALCULO_VR!$O:$O) -> -11.087058 | Y59: =_xlfn.XLOOKUP(A59,[1]CALCULO_VR!$D:$D,[1]CALCULO_VR!$P:$P) -> -64.080738
A60: 2583788 | B60: SILVANA KARITIANA | C60: Porto Velho | D60: 45468 | E60: 45468 | F60: 34042.861 | G60: 1 | H60: 1 | J60: 0 | Q60: 48.832983 | R60: 2 | S60: 2 | T60: 251 | U60: 5 | W60: =_xlfn.XLOOKUP(A60,[1]CALCULO_VR!$D:$D,[1]CALCULO_VR!$J:$J) -> 80 | X60: =_xlfn.XLOOKUP(A60,[1]CALCULO_VR!$D:$D,[1]CALCULO_VR!$O:$O) -> -9.192673 | Y60: =_xlfn.XLOOKUP(A60,[1]CALCULO_VR!$D:$D,[1]CALCULO_VR!$P:$P) -> -63.948097
A61: 2583789 | B61: GEICILENE ORO JOWIN | C61: Guajará-Mirim | D61: 45460 | E61: 45460 | F61: 34042.861 | G61: 1 | H61: 1 | J61: 0 | Q61: 140.19906 | R61: 4 | S61: 4 | T61: 163 | U61: 5 | W61: =_xlfn.XLOOKUP(A61,[1]CALCULO_VR!$D:$D,[1]CALCULO_VR!$J:$J) -> 80 | X61: =_xlfn.XLOOKUP(A61,[1]CALCULO_VR!$D:$D,[1]CALCULO_VR!$O:$O) -> -11.087127 | Y61: =_xlfn.XLOOKUP(A61,[1]CALCULO_VR!$D:$D,[1]CALCULO_VR!$P:$P) -> -64.080073
A62: 2583790 | B62: ROSENDA FERREIRA INUMA | C62: Guajará-Mirim | D62: 45469 | E62: 45469 | F62: 34042.861 | G62: 1 | H62: 1 | J62: 0 | Q62: 94.114195 | R62: 3 | S62: 3 | T62: 223 | U62: 6 | W62: =_xlfn.XLOOKUP(A62,[1]CALCULO_VR!$D:$D,[1]CALCULO_VR!$J:$J) -> 80 | X62: =_xlfn.XLOOKUP(A62,[1]CALCULO_VR!$D:$D,[1]CALCULO_VR!$O:$O) -> -11.380303 | Y62: =_xlfn.XLOOKUP(A62,[1]CALCULO_VR!$D:$D,[1]CALCULO_VR!$P:$P) -> -64.72229
A63: 2583791 | B63: NEIDE MORAIS KARITIANA LOPES | C63: Porto Velho | D63: 45469 | E63: 45469 | F63: 34042.861 | G63: 1 | H63: 1 | J63: 0 | Q63: 66.468637 | R63: 2 | S63: 2 | T63: 251 | U63: 5 | W63: =_xlfn.XLOOKUP(A63,[1]CALCULO_VR!$D:$D,[1]CALCULO_VR!$J:$J) -> 80 | X63: =_xlfn.XLOOKUP(A63,[1]CALCULO_VR!$D:$D,[1]CALCULO_VR!$O:$O) -> -9.320778 | Y63: =_xlfn.XLOOKUP(A63,[1]CALCULO_VR!$D:$D,[1]CALCULO_VR!$P:$P) -> -64.064005
A64: 2583792 | B64: JOAO FERREIRA LOPES | C64: Guajará-Mirim | D64: 45468 | E64: 45468 | F64: 34042.861 | G64: 1 | H64: 1 | J64: 0 | Q64: 86.782843 | R64: 3 | S64: 3 | T64: 223 | U64: 6 | W64: =_xlfn.XLOOKUP(A64,[1]CALCULO_VR!$D:$D,[1]CALCULO_VR!$J:$J) -> 80 | X64: =_xlfn.XLOOKUP(A64,[1]CALCULO_VR!$D:$D,[1]CALCULO_VR!$O:$O) -> -11.353395 | Y64: =_xlfn.XLOOKUP(A64,[1]CALCULO_VR!$D:$D,[1]CALCULO_VR!$P:$P) -> -64.791288
A65: 2583923 | B65: ESCOLA INDIGENA NYJNYJI | C65: Porto Velho | D65: 45469 | E65: 45469 | F65: 34042.861 | G65: 1 | H65: 1 | J65: 0 | Q65: 66.366 | R65: 2 | S65: 2 | T65: 251 | U65: 5 | W65: =_xlfn.XLOOKUP(A65,[1]CALCULO_VR!$D:$D,[1]CALCULO_VR!$J:$J) -> 80 | X65: =_xlfn.XLOOKUP(A65,[1]CALCULO_VR!$D:$D,[1]CALCULO_VR!$O:$O) -> -9.32021 | Y65: =_xlfn.XLOOKUP(A65,[1]CALCULO_VR!$D:$D,[1]CALCULO_VR!$P:$P) -> -64.062953
A66: 2583681 | B66: MIZAEL ORO NAO | C66: Guajará-Mirim | D66: 45467 | E66: 45467 | F66: 34042.861 | G66: 1 | H66: 1 | J66: 0 | Q66: 63.415301 | R66: 2 | S66: 2 | T66: 251 | U66: 5 | W66: =_xlfn.XLOOKUP(A66,[1]CALCULO_VR!$D:$D,[1]CALCULO_VR!$J:$J) -> 80 | X66: =_xlfn.XLOOKUP(A66,[1]CALCULO_VR!$D:$D,[1]CALCULO_VR!$O:$O) -> -11.219857 | Y66: =_xlfn.XLOOKUP(A66,[1]CALCULO_VR!$D:$D,[1]CALCULO_VR!$P:$P) -> -64.961832
A67: 2583793 | B67: CELIANE DA SILVA KARITIANA | C67: Porto Velho | D67: 45467 | E67: 45467 | F67: 34042.861 | G67: 1 | H67: 1 | J67: 0 | Q67: 48.79447 | R67: 2 | S67: 2 | T67: 251 | U67: 5 | W67: =_xlfn.XLOOKUP(A67,[1]CALCULO_VR!$D:$D,[1]CALCULO_VR!$J:$J) -> 80 | X67: =_xlfn.XLOOKUP(A67,[1]CALCULO_VR!$D:$D,[1]CALCULO_VR!$O:$O) -> -9.192733 | Y67: =_xlfn.XLOOKUP(A67,[1]CALCULO_VR!$D:$D,[1]CALCULO_VR!$P:$P) -> -63.946527
... A74: 2583801 | B74: GEANE MARIA GARCIA KARITIANA | C74: Porto Velho | D74: 45469 | E74: 45469 | F74: 34042.861 | G74: 1 | H74: 1 | J74: 0 | Q74: 66.471653 | R74: 2 | S74: 2 | T74: 251 | U74: 5 | W74: =_xlfn.XLOOKUP(A74,[1]CALCULO_VR!$D:$D,[1]CALCULO_VR!$J:$J) -> 80 | X74: =_xlfn.XLOOKUP(A74,[1]CALCULO_VR!$D:$D,[1]CALCULO_VR!$O:$O) -> -9.320793 | Y74: =_xlfn.XLOOKUP(A74,[1]CALCULO_VR!$D:$D,[1]CALCULO_VR!$P:$P) -> -64.06404
A75: 2583802 | B75: RAIMUNDO NONATO KARITIANA | C75: Porto Velho | D75: 45467 | E75: 45467 | F75: 34042.861 | G75: 1 | H75: 1 | J75: 0 | Q75: 48.715771 | R75: 2 | S75: 2 | T75: 251 | U75: 5 | V75: Selecionado | W75: =_xlfn.XLOOKUP(A75,[1]CALCULO_VR!$D:$D,[1]CALCULO_VR!$J:$J) -> 80 | X75: =_xlfn.XLOOKUP(A75,[1]CALCULO_VR!$D:$D,[1]CALCULO_VR!$O:$O) -> -9.191817 | Y75: =_xlfn.XLOOKUP(A75,[1]CALCULO_VR!$D:$D,[1]CALCULO_VR!$P:$P) -> -63.947215
A76: 2583682 | B76: CLEICIELE ORO NAO | C76: Guajará-Mirim | D76: 45467 | E76: 45467 | F76: 34042.861 | G76: 1 | H76: 1 | J76: 0 | Q76: 63.907334 | R76: 2 | S76: 2 | T76: 251 | U76: 5 | W76: =_xlfn.XLOOKUP(A76,[1]CALCULO_VR!$D:$D,[1]CALCULO_VR!$J:$J) -> 80 | X76: =_xlfn.XLOOKUP(A76,[1]CALCULO_VR!$D:$D,[1]CALCULO_VR!$O:$O) -> -11.222135 | Y76: =_xlfn.XLOOKUP(A76,[1]CALCULO_VR!$D:$D,[1]CALCULO_VR!$P:$P) -> -64.957515
A77: 2583804 | B77: FABIO SOARES LIMA | C77: Guajará-Mirim | D77: 45459 | E77: 45459 | F77: 34042.861 | G77: 1 | H77: 1 | J77: 0 | Q77: 140.16655 | R77: 4 | S77: 4 | T77: 163 | U77: 5 | W77: =_xlfn.XLOOKUP(A77,[1]CALCULO_VR!$D:$D,[1]CALCULO_VR!$J:$J) -> 80 | X77: =_xlfn.XLOOKUP(A77,[1]CALCULO_VR!$D:$D,[1]CALCULO_VR!$O:$O) -> -11.086225 | Y77: =_xlfn.XLOOKUP(A77,[1]CALCULO_VR!$D:$D,[1]CALCULO_VR!$P:$P) -> -64.080147
A78: 2583805 | B78: JOABE ORO WIN | C78: Guajará-Mirim | D78: 45465 | E78: 45465 | F78: 34042.861 | G78: 1 | H78: 1 | J78: 0 | Q78: 140.30324 | R78: 4 | S78: 4 | T78: 163 | U78: 5 | W78: =_xlfn.XLOOKUP(A78,[1]CALCULO_VR!$D:$D,[1]CALCULO_VR!$J:$J) -> 80 | X78: =_xlfn.XLOOKUP(A78,[1]CALCULO_VR!$D:$D,[1]CALCULO_VR!$O:$O) -> -11.085935 | Y78: =_xlfn.XLOOKUP(A78,[1]CALCULO_VR!$D:$D,[1]CALCULO_VR!$P:$P) -> -64.07878
A79: 2583807 | B79: JOSEMAR JACOME LOPES | C79: Guajará-Mirim | D79: 45468 | E79: 45468 | F79: 34042.861 | G79: 1 | H79: 1 | J79: 0 | Q79: 86.804844 | R79: 3 | S79: 3 | T79: 223 | U79: 6 | W79: =_xlfn.XLOOKUP(A79,[1]CALCULO_VR!$D:$D,[1]CALCULO_VR!$J:$J) -> 80 | X79: =_xlfn.XLOOKUP(A79,[1]CALCULO_VR!$D:$D,[1]CALCULO_VR!$O:$O) -> -11.353457 | Y79: =_xlfn.XLOOKUP(A79,[1]CALCULO_VR!$D:$D,[1]CALCULO_VR!$P:$P) -> -64.791057
A80: 2583808 | B80: DANIEL NONATO KARITIANA | C80: Porto Velho | D80: 45468 | E80: 45468 | F80: 34042.861 | G80: 1 | H80: 1 | J80: 0 | Q80: 48.735626 | R80: 2 | S80: 2 | T80: 251 | U80: 5 | W80: =_xlfn.XLOOKUP(A80,[1]CALCULO_VR!$D:$D,[1]CALCULO_VR!$J:$J) -> 80 | X80: =_xlfn.XLOOKUP(A80,[1]CALCULO_VR!$D:$D,[1]CALCULO_VR!$O:$O) -> -9.191895 | Y80: =_xlfn.XLOOKUP(A80,[1]CALCULO_VR!$D:$D,[1]CALCULO_VR!$P:$P) -> -63.947615
A81: 2583809 | B81: MARCIO KARINTIANA | C81: Porto Velho | D81: 45469 | E81: 45469 | F81: 34042.861 | G81: 1 | H81: 1 | J81: 0 | Q81: 66.470852 | R81: 2 | S81: 2 | T81: 251 | U81: 5 | W81: =_xlfn.XLOOKUP(A81,[1]CALCULO_VR!$D:$D,[1]CALCULO_VR!$J:$J) -> 80 | X81: =_xlfn.XLOOKUP(A81,[1]CALCULO_VR!$D:$D,[1]CALCULO_VR!$O:$O) -> -9.320473 | Y81: =_xlfn.XLOOKUP(A81,[1]CALCULO_VR!$D:$D,[1]CALCULO_VR!$P:$P) -> -64.064798
A82: 2583680 | B82: REGIANE ORO EO | C82: Guajará-Mirim | D82: 45469 | E82: 45469 | F82: 34042.861 | G82: 1 | H82: 1 | J82: 0 | Q82: 78.373186 | R82: 3 | S82: 3 | T82: 223 | U82: 6 | W82: =_xlfn.XLOOKUP(A82,[1]CALCULO_VR!$D:$D,[1]CALCULO_VR!$J:$J) -> 80 | X82: =_xlfn.XLOOKUP(A82,[1]CALCULO_VR!$D:$D,[1]CALCULO_VR!$O:$O) -> -11.187977 | Y82: =_xlfn.XLOOKUP(A82,[1]CALCULO_VR!$D:$D,[1]CALCULO_VR!$P:$P) -> -64.742955
A83: 2583810 | B83: JEAN ORO WARAM | C83: Guajará-Mirim | D83: 45460 | E83: 45460 | F83: 34042.861 | G83: 1 | H83: 1 | J83: 0 | Q83: 140.24523 | R83: 4 | S83: 4 | T83: 163 | U83: 5 | V83: Selecionado | W83: =_xlfn.XLOOKUP(A83,[1]CALCULO_VR!$D:$D,[1]CALCULO_VR!$J:$J) -> 80 | X83: =_xlfn.XLOOKUP(A83,[1]CALCULO_VR!$D:$D,[1]CALCULO_VR!$O:$O) -> -11.087268 | Y83: =_xlfn.XLOOKUP(A83,[1]CALCULO_VR!$D:$D,[1]CALCULO_VR!$P:$P) -> -64.079673
A84: 2583926 | B84: IGREJA PENTECOSTAL MISTERIO MOVER DO | C84: Porto Velho | D84: 45469 | E84: 45469 | F84: 34042.861 | G84: 1 | H84: 1 | J84: 0 | Q84: 66.470358 | R84: 2 | S84: 2 | T84: 251 | U84: 5 | W84: =_xlfn.XLOOKUP(A84,[1]CALCULO_VR!$D:$D,[1]CALCULO_VR!$J:$J) -> 80 | X84: =_xlfn.XLOOKUP(A84,[1]CALCULO_VR!$D:$D,[1]CALCULO_VR!$O:$O) -> -9.320872 | Y84: =_xlfn.XLOOKUP(A84,[1]CALCULO_VR!$D:$D,[1]CALCULO_VR!$P:$P) -> -64.063817
A85: 2585871 | B85: KATIA ORO MON | C85: Nova Mamoré | D85: 45464 | E85: 45464 | F85: 34042.861 | G85: 1 | H85: 1 | J85: 0 | Q85: 26.543438 | R85: 1 | S85: 1 | T85: 225 | U85: 6 | W85: =_xlfn.XLOOKUP(A85,[1]CALCULO_VR!$D:$D,[1]CALCULO_VR!$J:$J) -> 80 | X85: =_xlfn.XLOOKUP(A85,[1]CALCULO_VR!$D:$D,[1]CALCULO_VR!$O:$O) -> -10.326277 | Y85: =_xlfn.XLOOKUP(A85,[1]CALCULO_VR!$D:$D,[1]CALCULO_VR!$P:$P) -> -65.102573
A86: 2583811 | B86: ROBERTO ORO WIN | C86: Guajará-Mirim | D86: 45460 | E86: 45460 | F86: 34042.861 | G86: 1 | H86: 1 | J86: 0 | Q86: 139.74196 | R86: 4 | S86: 4 | T86: 163 | U86: 5 | W86: =_xlfn.XLOOKUP(A86,[1]CALCULO_VR!$D:$D,[1]CALCULO_VR!$J:$J) -> 80 | X86: =_xlfn.XLOOKUP(A86,[1]CALCULO_VR!$D:$D,[1]CALCULO_VR!$O:$O) -> -11.093202 | Y86: =_xlfn.XLOOKUP(A86,[1]CALCULO_VR!$D:$D,[1]CALCULO_VR!$P:$P) -> -64.085992
...

Sheet Amostra 1_5_extrato_erro_5%
A1: UC | B1: Projeto | C1: Município | D1: Data Inicio | E1: Data Fim | F1: Custo(R$) | G1: Cons. | H1: Kit | I1: Regional | J1: Grupo | K1: Poste | L1: Rede AT km | M1: Rede BT km | N1: Medidor | O1: Trafo | P1: Equip. | Q1: VR | R1: Estrato | S1: regionale | T1: NGH | U1: NPH | V1: STATUS | W1: SIGFI | X1: Latitude_UC | Y1: Longitude_UC
A2: 2595147 | B2: POSTO DE SAUDE ALDEIA PALHAL | C2: Vilhena | D2: 45500 | E2: 45500 | F2: 34042.861 | G2: 1 | H2: 1 | J2: 0 | Q2: 144.5618 | R2: 5 | S2: 5 | T2: 118 | U2: 2 | W2: =_xlfn.XLOOKUP(A2,[1]CALCULO_VR!$D:$D,[1]CALCULO_VR!$J:$J) -> 80 | X2: =_xlfn.XLOOKUP(A2,[1]CALCULO_VR!$D:$D,[1]CALCULO_VR!$O:$O) -> -11.479878 | Y2: =_xlfn.XLOOKUP(A2,[1]CALCULO_VR!$D:$D,[1]CALCULO_VR!$P:$P) -> -60.460112
A3: 2595177 | B3: GERSON CINTA LARGA | C3: São Francisco do Guaporé | D3: 45504 | E3: 45504 | F3: 52970.941 | G3: 1 | H3: 1 | J3: 0 | Q3: 70.928033 | R3: 2 | S3: 2 | T3: 247 | U3: 4 | W3: =_xlfn.XLOOKUP(A3,[1]CALCULO_VR!$D:$D,[1]CALCULO_VR!$J:$J) -> 160 | X3: =_xlfn.XLOOKUP(A3,[1]CALCULO_VR!$D:$D,[1]CALCULO_VR!$O:$O) -> -12.408093 | Y3: =_xlfn.XLOOKUP(A3,[1]CALCULO_VR!$D:$D,[1]CALCULO_VR!$P:$P) -> -63.021408
A4: 2595236 | B4: POSTO DE SAUDE ALDEIA CAJUI | C4: São Francisco do Guaporé | D4: 45505 | E4: 45505 | F4: 34042.861 | G4: 1 | H4: 1 | J4: 0 | Q4: 70.937531 | R4: 2 | S4: 2 | T4: 247 | U4: 4 | W4: =_xlfn.XLOOKUP(A4,[1]CALCULO_VR!$D:$D,[1]CALCULO_VR!$J:$J) -> 80 | X4: =_xlfn.XLOOKUP(A4,[1]CALCULO_VR!$D:$D,[1]CALCULO_VR!$O:$O) -> -12.407253 | Y4: =_xlfn.XLOOKUP(A4,[1]CALCULO_VR!$D:$D,[1]CALCULO_VR!$P:$P) -> -63.020755
A5: 2595237 | B5: EIEEFM KON KOATT TUPARI | C5: São Francisco do Guaporé | D5: 45505 | E5: 45505 | F5: 34042.861 | G5: 1 | H5: 1 | J5: 0 | Q5: 70.910302 | R5: 2 | S5: 2 | T5: 247 | U5: 4 | W5: =_xlfn.XLOOKUP(A5,[1]CALCULO_VR!$D:$D,[1]CALCULO_VR!$J:$J) -> 80 | X5: =_xlfn.XLOOKUP(A5,[1]CALCULO_VR!$D:$D,[1]CALCULO_VR!$O:$O) -> -12.40728 | Y5: =_xlfn.XLOOKUP(A5,[1]CALCULO_VR!$D:$D,[1]CALCULO_VR!$P:$P) -> -63.02107
A6: 2595249 | B6: ROSEANE TENHARIN | C6: São Francisco do Guaporé | D6: 45500 | E6: 45500 | F6: 52970.941 | G6: 1 | H6: 1 | J6: 0 | Q6: 90.038796 | R6: 3 | S6: 3 | T6: 161 | U6: 2 | W6: =_xlfn.XLOOKUP(A6,[1]CALCULO_VR!$D:$D,[1]CALCULO_VR!$J:$J) -> 160 | X6: =_xlfn.XLOOKUP(A6,[1]CALCULO_VR!$D:$D,[1]CALCULO_VR!$O:$O) -> -12.34808 | Y6: =_xlfn.XLOOKUP(A6,[1]CALCULO_VR!$D:$D,[1]CALCULO_VR!$P:$P) -> -62.795132
A7: 2595250 | B7: OSMAR MAINTAKA TUPARI | C7: São Francisco do Guaporé | D7: 45500 | E7: 45500 | F7: 52970.941 | G7: 1 | H7: 1 | J7: 0 | Q7: 89.873976 | R7: 3 | S7: 3 | T7: 161 | U7: 2 | W7: =_xlfn.XLOOKUP(A7,[1]CALCULO_VR!$D:$D,[1]CALCULO_VR!$J:$J) -> 160 | X7: =_xlfn.XLOOKUP(A7,[1]CALCULO_VR!$D:$D,[1]CALCULO_VR!$O:$O) -> -12.347225 | Y7: =_xlfn.XLOOKUP(A7,[1]CALCULO_VR!$D:$D,[1]CALCULO_VR!$P:$P) -> -62.796425
A8: 2595269 | B8: EIEEFM KON KOATT TUPARI | C8: São Francisco do Guaporé | D8: 45506 | E8: 45506 | F8: 34042.861 | G8: 1 | H8: 1 | J8: 0 | Q8: 70.974094 | R8: 2 | S8: 2 | T8: 247 | U8: 4 | W8: =_xlfn.XLOOKUP(A8,[1]CALCULO_VR!$D:$D,[1]CALCULO_VR!$J:$J) -> 80 | X8: =_xlfn.XLOOKUP(A8,[1]CALCULO_VR!$D:$D,[1]CALCULO_VR!$O:$O) -> -12.41203 | Y8: =_xlfn.XLOOKUP(A8,[1]CALCULO_VR!$D:$D,[1]CALCULO_VR!$P:$P) -> -63.023502
A9: 2595272 | B9: WALDIR FIRMINO VALE | C9: São Francisco do Guaporé | D9: 45502 | E9: 45502 | F9: 52970.941 | G9: 1 | H9: 1 | J9: 0 | Q9: 89.869751 | R9: 3 | S9: 3 | T9: 161 | U9: 2 | W9: =_xlfn.XLOOKUP(A9,[1]CALCULO_VR!$D:$D,[1]CALCULO_VR!$J:$J) -> 160 | X9: =_xlfn.XLOOKUP(A9,[1]CALCULO_VR!$D:$D,[1]CALCULO_VR!$O:$O) -> -12.347462 | Y9: =_xlfn.XLOOKUP(A9,[1]CALCULO_VR!$D:$D,[1]CALCULO_VR!$P:$P) -> -62.796557
A10: 2583661 | B10: DIVINO GOMES LIMA | C10: Guajará-Mirim | D10: 45459 | E10: 45459 | F10: 34042.861 | G10: 1 | H10: 1 | J10: 0 | Q10: 54.60863 | R10: 2 | S10: 2 | T10: 247 | U10: 4 | W10: =_xlfn.XLOOKUP(A10,[1]CALCULO_VR!$D:$D,[1]CALCULO_VR!$J:$J) -> 80 | X10: =_xlfn.XLOOKUP(A10,[1]CALCULO_VR!$D:$D,[1]CALCULO_VR!$O:$O) -> -10.681757 | Y10: =_xlfn.XLOOKUP(A10,[1]CALCULO_VR!$D:$D,[1]CALCULO_VR!$P:$P) -> -64.832982
A11: 2583662 | B11: JOSE PEREIRA ALVES | C11: Guajará-Mirim | D11: 45458 | E11: 45458 | F11: 34042.861 | G11: 1 | H11: 1 | J11: 0 | Q11: 56.302057 | R11: 2 | S11: 2 | T11: 247 | U11: 4 | W11: =_xlfn.XLOOKUP(A11,[1]CALCULO_VR!$D:$D,[1]CALCULO_VR!$J:$J) -> 80 | X11: =_xlfn.XLOOKUP(A11,[1]CALCULO_VR!$D:$D,[1]CALCULO_VR!$O:$O) -> -10.673628 | Y11: =_xlfn.XLOOKUP(A11,[1]CALCULO_VR!$D:$D,[1]CALCULO_VR!$P:$P) -> -64.818818
A12: 2583663 | B12: ELIETE BIRA MACIEL | C12: Guajará-Mirim | D12: 45459 | E12: 45459 | F12: 34042.861 | G12: 1 | H12: 1 | J12: 0 | Q12: 56.649232 | R12: 2 | S12: 2 | T12: 247 | U12: 4 | W12: =_xlfn.XLOOKUP(A12,[1]CALCULO_VR!$D:$D,[1]CALCULO_VR!$J:$J) -> 80 | X12: =_xlfn.XLOOKUP(A12,[1]CALCULO_VR!$D:$D,[1]CALCULO_VR!$O:$O) -> -10.669567 | Y12: =_xlfn.XLOOKUP(A12,[1]CALCULO_VR!$D:$D,[1]CALCULO_VR!$P:$P) -> -64.816427
A13: 2583664 | B13: JOSE ELEUTERIO FILHO | C13: Guajará-Mirim | D13: 45459 | E13: 45459 | F13: 34042.861 | G13: 1 | H13: 1 | J13: 0 | Q13: 57.074959 | R13: 2 | S13: 2 | T13: 247 | U13: 4 | W13: =_xlfn.XLOOKUP(A13,[1]CALCULO_VR!$D:$D,[1]CALCULO_VR!$J:$J) -> 80 | X13: =_xlfn.XLOOKUP(A13,[1]CALCULO_VR!$D:$D,[1]CALCULO_VR!$O:$O) -> -10.674992 | Y13: =_xlfn.XLOOKUP(A13,[1]CALCULO_VR!$D:$D,[1]CALCULO_VR!$P:$P) -> -64.811327
... A52: 2583785 | B52: SAMUEL ORO WIN | C52: Guajará-Mirim | D52: 45461 | E52: 45461 | F52: 34042.861 | G52: 1 | H52: 1 | J52: 0 | Q52: 134.37134 | R52: 5 | S52: 5 | T52: 118 | U52: 2 | W52: =_xlfn.XLOOKUP(A52,[1]CALCULO_VR!$D:$D,[1]CALCULO_VR!$J:$J) -> 80 | X52: =_xlfn.XLOOKUP(A52,[1]CALCULO_VR!$D:$D,[1]CALCULO_VR!$O:$O) -> -11.121525 | Y52: =_xlfn.XLOOKUP(A52,[1]CALCULO_VR!$D:$D,[1]CALCULO_VR!$P:$P) -> -64.14515
A53: 2583786 | B53: MARINA ORO WIN | C53: Guajará-Mirim | D53: 45461 | E53: 45461 | F53: 34042.861 | G53: 1 | H53: 1 | J53: 0 | Q53: 134.2749 | R53: 5 | S53: 5 | T53: 118 | U53: 2 | V53: Selecionado | W53: =_xlfn.XLOOKUP(A53,[1]CALCULO_VR!$D:$D,[1]CALCULO_VR!$J:$J) -> 80 | X53: =_xlfn.XLOOKUP(A53,[1]CALCULO_VR!$D:$D,[1]CALCULO_VR!$O:$O) -> -11.121458 | Y53: =_xlfn.XLOOKUP(A53,[1]CALCULO_VR!$D:$D,[1]CALCULO_VR!$P:$P) -> -64.146052
A54: 2583787 | B54: FRANCIELE PAMOTO KARITIANA | C54: Porto Velho | D54: 45468 | E54: 45468 | F54: 34042.861 | G54: 1 | H54: 1 | J54: 0 | Q54: 48.789481 | R54: 2 | S54: 2 | T54: 247 | U54: 4 | W54: =_xlfn.XLOOKUP(A54,[1]CALCULO_VR!$D:$D,[1]CALCULO_VR!$J:$J) -> 80 | X54: =_xlfn.XLOOKUP(A54,[1]CALCULO_VR!$D:$D,[1]CALCULO_VR!$O:$O) -> -9.192407 | Y54: =_xlfn.XLOOKUP(A54,[1]CALCULO_VR!$D:$D,[1]CALCULO_VR!$P:$P) -> -63.947577
A55: 2583701 | B55: MARIA LILIA OLIVEIRA GONCALVES | C55: Guajará-Mirim | D55: 45467 | E55: 45467 | F55: 34042.861 | G55: 1 | H55: 1 | J55: 0 | Q55: 74.086101 | R55: 3 | S55: 3 | T55: 161 | U55: 2 | W55: =_xlfn.XLOOKUP(A55,[1]CALCULO_VR!$D:$D,[1]CALCULO_VR!$J:$J) -> 80 | X55: =_xlfn.XLOOKUP(A55,[1]CALCULO_VR!$D:$D,[1]CALCULO_VR!$O:$O) -> -11.20843 | Y55: =_xlfn.XLOOKUP(A55,[1]CALCULO_VR!$D:$D,[1]CALCULO_VR!$P:$P) -> -64.80945
A56: 2583921 | B56: POSTO DE SAUDE ALDEIA SAO LUIZ | C56: Guajará-Mirim | D56: 45460 | E56: 45460 | F56: 34042.861 | G56: 1 | H56: 1 | J56: 0 | Q56: 140.19241 | R56: 5 | S56: 5 | T56: 118 | U56: 2 | W56: =_xlfn.XLOOKUP(A56,[1]CALCULO_VR!$D:$D,[1]CALCULO_VR!$J:$J) -> 80 | X56: =_xlfn.XLOOKUP(A56,[1]CALCULO_VR!$D:$D,[1]CALCULO_VR!$O:$O) -> -11.085762 | Y56: =_xlfn.XLOOKUP(A56,[1]CALCULO_VR!$D:$D,[1]CALCULO_VR!$P:$P) -> -64.079783
A57: 2583685 | B57: WALDEMIR LOPES DE AMORIM | C57: Guajará-Mirim | D57: 45464 | E57: 45464 | F57: 34042.861 | G57: 1 | H57: 1 | J57: 0 | Q57: 65.495643 | R57: 2 | S57: 2 | T57: 247 | U57: 4 | W57: =_xlfn.XLOOKUP(A57,[1]CALCULO_VR!$D:$D,[1]CALCULO_VR!$J:$J) -> 80 | X57: =_xlfn.XLOOKUP(A57,[1]CALCULO_VR!$D:$D,[1]CALCULO_VR!$O:$O) -> -11.200607 | Y57: =_xlfn.XLOOKUP(A57,[1]CALCULO_VR!$D:$D,[1]CALCULO_VR!$P:$P) -> -64.910355
A58: 2583686 | B58: JOSE MARIA DE SOUZA RUFINO | C58: Guajará-Mirim | D58: 45464 | E58: 45464 | F58: 34042.861 | G58: 1 | H58: 1 | J58: 0 | Q58: 65.745664 | R58: 2 | S58: 2 | T58: 247 | U58: 4 | W58: =_xlfn.XLOOKUP(A58,[1]CALCULO_VR!$D:$D,[1]CALCULO_VR!$J:$J) -> 80 | X58: =_xlfn.XLOOKUP(A58,[1]CALCULO_VR!$D:$D,[1]CALCULO_VR!$O:$O) -> -11.198337 | Y58: =_xlfn.XLOOKUP(A58,[1]CALCULO_VR!$D:$D,[1]CALCULO_VR!$P:$P) -> -64.904643
A59: 2583922 | B59: ESCOLA JOAO FARIAS DE BARROS | C59: Guajará-Mirim | D59: 45460 | E59: 45460 | F59: 34042.861 | G59: 1 | H59: 1 | J59: 0 | Q59: 140.12685 | R59: 5 | S59: 5 | T59: 118 | U59: 2 | W59: =_xlfn.XLOOKUP(A59,[1]CALCULO_VR!$D:$D,[1]CALCULO_VR!$J:$J) -> 80 | X59: =_xlfn.XLOOKUP(A59,[1]CALCULO_VR!$D:$D,[1]CALCULO_VR!$O:$O) -> -11.087058 | Y59: =_xlfn.XLOOKUP(A59,[1]CALCULO_VR!$D:$D,[1]CALCULO_VR!$P:$P) -> -64.080738
A60: 2583788 | B60: SILVANA KARITIANA | C60: Porto Velho | D60: 45468 | E60: 45468 | F60: 34042.861 | G60: 1 | H60: 1 | J60: 0 | Q60: 48.832983 | R60: 2 | S60: 2 | T60: 247 | U60: 4 | W60: =_xlfn.XLOOKUP(A60,[1]CALCULO_VR!$D:$D,[1]CALCULO_VR!$J:$J) -> 80 | X60: =_xlfn.XLOOKUP(A60,[1]CALCULO_VR!$D:$D,[1]CALCULO_VR!$O:$O) -> -9.192673 | Y60: =_xlfn.XLOOKUP(A60,[1]CALCULO_VR!$D:$D,[1]CALCULO_VR!$P:$P) -> -63.948097
A61: 2583789 | B61: GEICILENE ORO JOWIN | C61: Guajará-Mirim | D61: 45460 | E61: 45460 | F61: 34042.861 | G61: 1 | H61: 1 | J61: 0 | Q61: 140.19906 | R61: 5 | S61: 5 | T61: 118 | U61: 2 | W61: =_xlfn.XLOOKUP(A61,[1]CALCULO_VR!$D:$D,[1]CALCULO_VR!$J:$J) -> 80 | X61: =_xlfn.XLOOKUP(A61,[1]CALCULO_VR!$D:$D,[1]CALCULO_VR!$O:$O) -> -11.087127 | Y61: =_xlfn.XLOOKUP(A61,[1]CALCULO_VR!$D:$D,[1]CALCULO_VR!$P:$P) -> -64.080073
A62: 2583790 | B62: ROSENDA FERREIRA INUMA | C62: Guajará-Mirim | D62: 45469 | E62: 45469 | F62: 34042.861 | G62: 1 | H62: 1 | J62: 0 | Q62: 94.114195 | R62: 3 | S62: 3 | T62: 161 | U62: 2 | W62: =_xlfn.XLOOKUP(A62,[1]CALCULO_VR!$D:$D,[1]CALCULO_VR!$J:$J) -> 80 | X62: =_xlfn.XLOOKUP(A62,[1]CALCULO_VR!$D:$D,[1]CALCULO_VR!$O:$O) -> -11.380303 | Y62: =_xlfn.XLOOKUP(A62,[1]CALCULO_VR!$D:$D,[1]CALCULO_VR!$P:$P) -> -64.72229
A63: 2583791 | B63: NEIDE MORAIS KARITIANA LOPES | C63: Porto Velho | D63: 45469 | E63: 45469 | F63: 34042.861 | G63: 1 | H63: 1 | J63: 0 | Q63: 66.468637 | R63: 2 | S63: 2 | T63: 247 | U63: 4 | W63: =_xlfn.XLOOKUP(A63,[1]CALCULO_VR!$D:$D,[1]CALCULO_VR!$J:$J) -> 80 | X63: =_xlfn.XLOOKUP(A63,[1]CALCULO_VR!$D:$D,[1]CALCULO_VR!$O:$O) -> -9.320778 | Y63: =_xlfn.XLOOKUP(A63,[1]CALCULO_VR!$D:$D,[1]CALCULO_VR!$P:$P) -> -64.064005
A64: 2583792 | B64: JOAO FERREIRA LOPES | C64: Guajará-Mirim | D64: 45468 | E64: 45468 | F64: 34042.861 | G64: 1 | H64: 1 | J64: 0 | Q64: 86.782843 | R64: 3 | S64: 3 | T64: 161 | U64: 2 | W64: =_xlfn.XLOOKUP(A64,[1]CALCULO_VR!$D:$D,[1]CALCULO_VR!$J:$J) -> 80 | X64: =_xlfn.XLOOKUP(A64,[1]CALCULO_VR!$D:$D,[1]CALCULO_VR!$O:$O) -> -11.353395 | Y64: =_xlfn.XLOOKUP(A64,[1]CALCULO_VR!$D:$D,[1]CALCULO_VR!$P:$P) -> -64.791288
A65: 2583923 | B65: ESCOLA INDIGENA NYJNYJI | C65: Porto Velho | D65: 45469 | E65: 45469 | F65: 34042.861 | G65: 1 | H65: 1 | J65: 0 | Q65: 66.366 | R65: 2 | S65: 2 | T65: 247 | U65: 4 | W65: =_xlfn.XLOOKUP(A65,[1]CALCULO_VR!$D:$D,[1]CALCULO_VR!$J:$J) -> 80 | X65: =_xlfn.XLOOKUP(A65,[1]CALCULO_VR!$D:$D,[1]CALCULO_VR!$O:$O) -> -9.32021 | Y65: =_xlfn.XLOOKUP(A65,[1]CALCULO_VR!$D:$D,[1]CALCULO_VR!$P:$P) -> -64.062953
... A80: 2583808 | B80: DANIEL NONATO KARITIANA | C80: Porto Velho | D80: 45468 | E80: 45468 | F80: 34042.861 | G80: 1 | H80: 1 | J80: 0 | Q80: 48.735626 | R80: 2 | S80: 2 | T80: 247 | U80: 4 | W80: =_xlfn.XLOOKUP(A80,[1]CALCULO_VR!$D:$D,[1]CALCULO_VR!$J:$J) -> 80 | X80: =_xlfn.XLOOKUP(A80,[1]CALCULO_VR!$D:$D,[1]CALCULO_VR!$O:$O) -> -9.191895 | Y80: =_xlfn.XLOOKUP(A80,[1]CALCULO_VR!$D:$D,[1]CALCULO_VR!$P:$P) -> -63.947615
A81: 2583809 | B81: MARCIO KARINTIANA | C81: Porto Velho | D81: 45469 | E81: 45469 | F81: 34042.861 | G81: 1 | H81: 1 | J81: 0 | Q81: 66.470852 | R81: 2 | S81: 2 | T81: 247 | U81: 4 | V81: Selecionado | W81: =_xlfn.XLOOKUP(A81,[1]CALCULO_VR!$D:$D,[1]CALCULO_VR!$J:$J) -> 80 | X81: =_xlfn.XLOOKUP(A81,[1]CALCULO_VR!$D:$D,[1]CALCULO_VR!$O:$O) -> -9.320473 | Y81: =_xlfn.XLOOKUP(A81,[1]CALCULO_VR!$D:$D,[1]CALCULO_VR!$P:$P) -> -64.064798
A82: 2583680 | B82: REGIANE ORO EO | C82: Guajará-Mirim | D82: 45469 | E82: 45469 | F82: 34042.861 | G82: 1 | H82: 1 | J82: 0 | Q82: 78.373186 | R82: 3 | S82: 3 | T82: 161 | U82: 2 | W82: =_xlfn.XLOOKUP(A82,[1]CALCULO_VR!$D:$D,[1]CALCULO_VR!$J:$J) -> 80 | X82: =_xlfn.XLOOKUP(A82,[1]CALCULO_VR!$D:$D,[1]CALCULO_VR!$O:$O) -> -11.187977 | Y82: =_xlfn.XLOOKUP(A82,[1]CALCULO_VR!$D:$D,[1]CALCULO_VR!$P:$P) -> -64.742955
A83: 2583810 | B83: JEAN ORO WARAM | C83: Guajará-Mirim | D83: 45460 | E83: 45460 | F83: 34042.861 | G83: 1 | H83: 1 | J83: 0 | Q83: 140.24523 | R83: 5 | S83: 5 | T83: 118 | U83: 2 | W83: =_xlfn.XLOOKUP(A83,[1]CALCULO_VR!$D:$D,[1]CALCULO_VR!$J:$J) -> 80 | X83: =_xlfn.XLOOKUP(A83,[1]CALCULO_VR!$D:$D,[1]CALCULO_VR!$O:$O) -> -11.087268 | Y83: =_xlfn.XLOOKUP(A83,[1]CALCULO_VR!$D:$D,[1]CALCULO_VR!$P:$P) -> -64.079673
A84: 2583926 | B84: IGREJA PENTECOSTAL MISTERIO MOVER DO | C84: Porto Velho | D84: 45469 | E84: 45469 | F84: 34042.861 | G84: 1 | H84: 1 | J84: 0 | Q84: 66.470358 | R84: 2 | S84: 2 | T84: 247 | U84: 4 | W84: =_xlfn.XLOOKUP(A84,[1]CALCULO_VR!$D:$D,[1]CALCULO_VR!$J:$J) -> 80 | X84: =_xlfn.XLOOKUP(A84,[1]CALCULO_VR!$D:$D,[1]CALCULO_VR!$O:$O) -> -9.320872 | Y84: =_xlfn.XLOOKUP(A84,[1]CALCULO_VR!$D:$D,[1]CALCULO_VR!$P:$P) -> -64.063817
A85: 2585871 | B85: KATIA ORO MON | C85: Nova Mamoré | D85: 45464 | E85: 45464 | F85: 34042.861 | G85: 1 | H85: 1 | J85: 0 | Q85: 26.543438 | R85: 1 | S85: 1 | T85: 225 | U85: 5 | W85: =_xlfn.XLOOKUP(A85,[1]CALCULO_VR!$D:$D,[1]CALCULO_VR!$J:$J) -> 80 | X85: =_xlfn.XLOOKUP(A85,[1]CALCULO_VR!$D:$D,[1]CALCULO_VR!$O:$O) -> -10.326277 | Y85: =_xlfn.XLOOKUP(A85,[1]CALCULO_VR!$D:$D,[1]CALCULO_VR!$P:$P) -> -65.102573
A86: 2583811 | B86: ROBERTO ORO WIN | C86: Guajará-Mirim | D86: 45460 | E86: 45460 | F86: 34042.861 | G86: 1 | H86: 1 | J86: 0 | Q86: 139.74196 | R86: 5 | S86: 5 | T86: 118 | U86: 2 | W86: =_xlfn.XLOOKUP(A86,[1]CALCULO_VR!$D:$D,[1]CALCULO_VR!$J:$J) -> 80 | X86: =_xlfn.XLOOKUP(A86,[1]CALCULO_VR!$D:$D,[1]CALCULO_VR!$O:$O) -> -11.093202 | Y86: =_xlfn.XLOOKUP(A86,[1]CALCULO_VR!$D:$D,[1]CALCULO_VR!$P:$P) -> -64.085992
A87: 2583812 | B87: VITOR GARCIA POROGNGA KARITIANA | C87: Porto Velho | D87: 45469 | E87: 45469 | F87: 34042.861 | G87: 1 | H87: 1 | J87: 0 | Q87: 66.490199 | R87: 2 | S87: 2 | T87: 247 | U87: 4 | W87: =_xlfn.XLOOKUP(A87,[1]CALCULO_VR!$D:$D,[1]CALCULO_VR!$J:$J) -> 80 | X87: =_xlfn.XLOOKUP(A87,[1]CALCULO_VR!$D:$D,[1]CALCULO_VR!$O:$O) -> -9.321055 | Y87: =_xlfn.XLOOKUP(A87,[1]CALCULO_VR!$D:$D,[1]CALCULO_VR!$P:$P) -> -64.063842
